[2025-04-24T00:17:38.021+0000] {local_task_job_runner.py:123} INFO - ::group::Pre task execution logs
[2025-04-24T00:17:38.045+0000] {taskinstance.py:2612} INFO - Dependencies all met for dep_context=non-requeueable deps ti=<TaskInstance: dbt_stock_project.dbt_run manual__2025-04-24T00:17:37.452765+00:00 [queued]>
[2025-04-24T00:17:38.055+0000] {taskinstance.py:2612} INFO - Dependencies all met for dep_context=requeueable deps ti=<TaskInstance: dbt_stock_project.dbt_run manual__2025-04-24T00:17:37.452765+00:00 [queued]>
[2025-04-24T00:17:38.059+0000] {taskinstance.py:2865} INFO - Starting attempt 1 of 1
[2025-04-24T00:17:38.075+0000] {taskinstance.py:2888} INFO - Executing <Task(BashOperator): dbt_run> on 2025-04-24 00:17:37.452765+00:00
[2025-04-24T00:17:38.087+0000] {logging_mixin.py:190} WARNING - /home/***/.local/lib/python3.12/site-packages/***/task/task_runner/standard_task_runner.py:70 DeprecationWarning: This process (pid=6709) is multi-threaded, use of fork() may lead to deadlocks in the child.
[2025-04-24T00:17:38.085+0000] {standard_task_runner.py:104} INFO - Running: ['***', 'tasks', 'run', 'dbt_stock_project', 'dbt_run', 'manual__2025-04-24T00:17:37.452765+00:00', '--job-id', '329', '--raw', '--subdir', 'DAGS_FOLDER/226_lab2_elt.py', '--cfg-path', '/tmp/tmprhv50_0g']
[2025-04-24T00:17:38.089+0000] {standard_task_runner.py:72} INFO - Started process 6710 to run task
[2025-04-24T00:17:38.090+0000] {standard_task_runner.py:105} INFO - Job 329: Subtask dbt_run
[2025-04-24T00:17:38.145+0000] {task_command.py:467} INFO - Running <TaskInstance: dbt_stock_project.dbt_run manual__2025-04-24T00:17:37.452765+00:00 [running]> on host d01273b1fd04
[2025-04-24T00:17:38.226+0000] {taskinstance.py:3131} INFO - Exporting env vars: AIRFLOW_CTX_DAG_OWNER='***' AIRFLOW_CTX_DAG_ID='dbt_stock_project' AIRFLOW_CTX_TASK_ID='dbt_run' AIRFLOW_CTX_EXECUTION_DATE='2025-04-24T00:17:37.452765+00:00' AIRFLOW_CTX_TRY_NUMBER='1' AIRFLOW_CTX_DAG_RUN_ID='manual__2025-04-24T00:17:37.452765+00:00'
[2025-04-24T00:17:38.227+0000] {taskinstance.py:731} INFO - ::endgroup::
[2025-04-24T00:17:38.240+0000] {subprocess.py:63} INFO - Tmp dir root location: /tmp
[2025-04-24T00:17:38.243+0000] {subprocess.py:75} INFO - Running command: ['/usr/bin/bash', '-c', '/home/***/.local/bin/dbt run --profiles-dir /home/***/.dbt --project-dir /opt/***/dbt']
[2025-04-24T00:17:38.251+0000] {subprocess.py:86} INFO - Output:
[2025-04-24T00:17:40.046+0000] {subprocess.py:93} INFO - [0m00:17:40  Running with dbt=1.8.7
[2025-04-24T00:17:40.920+0000] {subprocess.py:93} INFO - [0m00:17:40  Registered adapter: snowflake=1.8.1
[2025-04-24T00:17:41.714+0000] {subprocess.py:93} INFO - [0m00:17:41  [[33mWARNING[0m]: Deprecated functionality
[2025-04-24T00:17:41.715+0000] {subprocess.py:93} INFO - The `tests` config has been renamed to `data_tests`. Please see
[2025-04-24T00:17:41.716+0000] {subprocess.py:93} INFO - https://docs.getdbt.com/docs/build/data-tests#new-data_tests-syntax for more
[2025-04-24T00:17:41.717+0000] {subprocess.py:93} INFO - information.
[2025-04-24T00:17:42.129+0000] {subprocess.py:93} INFO - [0m00:17:42  Found 6 models, 18 data tests, 3 sources, 459 macros
[2025-04-24T00:17:42.134+0000] {subprocess.py:93} INFO - [0m00:17:42
[2025-04-24T00:17:43.238+0000] {subprocess.py:93} INFO - [0m00:17:43  Concurrency: 1 threads (target='dev')
[2025-04-24T00:17:43.239+0000] {subprocess.py:93} INFO - [0m00:17:43
[2025-04-24T00:17:43.250+0000] {subprocess.py:93} INFO - [0m00:17:43  1 of 4 START sql table model analytics.moving_averages ......................... [RUN]
[2025-04-24T00:17:44.691+0000] {subprocess.py:93} INFO - [0m00:17:44  1 of 4 OK created sql table model analytics.moving_averages .................... [[32mSUCCESS 1[0m in 1.44s]
[2025-04-24T00:17:44.735+0000] {subprocess.py:93} INFO - [0m00:17:44  2 of 4 START sql table model analytics.stock_indicators ........................ [RUN]
[2025-04-24T00:17:45.711+0000] {subprocess.py:93} INFO - [0m00:17:45  2 of 4 OK created sql table model analytics.stock_indicators ................... [[32mSUCCESS 1[0m in 0.97s]
[2025-04-24T00:17:45.715+0000] {subprocess.py:93} INFO - [0m00:17:45  3 of 4 START sql table model analytics.volume_summary .......................... [RUN]
[2025-04-24T00:17:46.663+0000] {subprocess.py:93} INFO - [0m00:17:46  3 of 4 OK created sql table model analytics.volume_summary ..................... [[32mSUCCESS 1[0m in 0.94s]
[2025-04-24T00:17:46.667+0000] {subprocess.py:93} INFO - [0m00:17:46  4 of 4 START sql table model analytics.rsi ..................................... [RUN]
[2025-04-24T00:17:47.188+0000] {subprocess.py:93} INFO - [0m00:17:47  4 of 4 ERROR creating sql table model analytics.rsi ............................ [[31mERROR[0m in 0.52s]
[2025-04-24T00:17:47.195+0000] {subprocess.py:93} INFO - [0m00:17:47
[2025-04-24T00:17:47.197+0000] {subprocess.py:93} INFO - [0m00:17:47  Finished running 4 table models in 0 hours 0 minutes and 5.06 seconds (5.06s).
[2025-04-24T00:17:47.410+0000] {subprocess.py:93} INFO - [0m00:17:47
[2025-04-24T00:17:47.411+0000] {subprocess.py:93} INFO - [0m00:17:47  [31mCompleted with 1 error and 0 warnings:[0m
[2025-04-24T00:17:47.412+0000] {subprocess.py:93} INFO - [0m00:17:47
[2025-04-24T00:17:47.414+0000] {subprocess.py:93} INFO - [0m00:17:47    Database Error in model rsi (models/output/rsi.sql)
[2025-04-24T00:17:47.415+0000] {subprocess.py:93} INFO -   001003 (42000): SQL compilation error:
[2025-04-24T00:17:47.416+0000] {subprocess.py:93} INFO -   syntax error line 47 at position 27 unexpected ';'.
[2025-04-24T00:17:47.417+0000] {subprocess.py:93} INFO -   compiled code at target/run/dbt_stock_project/models/output/rsi.sql
[2025-04-24T00:17:47.418+0000] {subprocess.py:93} INFO - [0m00:17:47
[2025-04-24T00:17:47.419+0000] {subprocess.py:93} INFO - [0m00:17:47  Done. PASS=3 WARN=0 ERROR=1 SKIP=0 TOTAL=4
[2025-04-24T00:17:48.240+0000] {subprocess.py:97} INFO - Command exited with return code 1
[2025-04-24T00:17:48.252+0000] {taskinstance.py:3310} ERROR - Task failed with exception
Traceback (most recent call last):
  File "/home/airflow/.local/lib/python3.12/site-packages/airflow/models/taskinstance.py", line 767, in _execute_task
    result = _execute_callable(context=context, **execute_callable_kwargs)
             ^^^^^^^^^^^^^^^^^^^^^^^^^^^^^^^^^^^^^^^^^^^^^^^^^^^^^^^^^^^^^
  File "/home/airflow/.local/lib/python3.12/site-packages/airflow/models/taskinstance.py", line 733, in _execute_callable
    return ExecutionCallableRunner(
           ^^^^^^^^^^^^^^^^^^^^^^^^
  File "/home/airflow/.local/lib/python3.12/site-packages/airflow/utils/operator_helpers.py", line 252, in run
    return self.func(*args, **kwargs)
           ^^^^^^^^^^^^^^^^^^^^^^^^^^
  File "/home/airflow/.local/lib/python3.12/site-packages/airflow/models/baseoperator.py", line 406, in wrapper
    return func(self, *args, **kwargs)
           ^^^^^^^^^^^^^^^^^^^^^^^^^^^
  File "/home/airflow/.local/lib/python3.12/site-packages/airflow/operators/bash.py", line 249, in execute
    raise AirflowException(
airflow.exceptions.AirflowException: Bash command failed. The command returned a non-zero exit code 1.
[2025-04-24T00:17:48.256+0000] {taskinstance.py:1225} INFO - Marking task as FAILED. dag_id=dbt_stock_project, task_id=dbt_run, run_id=manual__2025-04-24T00:17:37.452765+00:00, execution_date=20250424T001737, start_date=20250424T001738, end_date=20250424T001748
[2025-04-24T00:17:48.269+0000] {taskinstance.py:340} INFO - ::group::Post task execution logs
[2025-04-24T00:17:48.270+0000] {standard_task_runner.py:124} ERROR - Failed to execute job 329 for task dbt_run (Bash command failed. The command returned a non-zero exit code 1.; 6710)
Traceback (most recent call last):
  File "/home/airflow/.local/lib/python3.12/site-packages/airflow/task/task_runner/standard_task_runner.py", line 117, in _start_by_fork
    ret = args.func(args, dag=self.dag)
          ^^^^^^^^^^^^^^^^^^^^^^^^^^^^^
  File "/home/airflow/.local/lib/python3.12/site-packages/airflow/cli/cli_config.py", line 49, in command
    return func(*args, **kwargs)
           ^^^^^^^^^^^^^^^^^^^^^
  File "/home/airflow/.local/lib/python3.12/site-packages/airflow/utils/cli.py", line 115, in wrapper
    return f(*args, **kwargs)
           ^^^^^^^^^^^^^^^^^^
  File "/home/airflow/.local/lib/python3.12/site-packages/airflow/cli/commands/task_command.py", line 483, in task_run
    task_return_code = _run_task_by_selected_method(args, _dag, ti)
                       ^^^^^^^^^^^^^^^^^^^^^^^^^^^^^^^^^^^^^^^^^^^^
  File "/home/airflow/.local/lib/python3.12/site-packages/airflow/cli/commands/task_command.py", line 256, in _run_task_by_selected_method
    return _run_raw_task(args, ti)
           ^^^^^^^^^^^^^^^^^^^^^^^
  File "/home/airflow/.local/lib/python3.12/site-packages/airflow/cli/commands/task_command.py", line 341, in _run_raw_task
    return ti._run_raw_task(
           ^^^^^^^^^^^^^^^^^
  File "/home/airflow/.local/lib/python3.12/site-packages/airflow/utils/session.py", line 97, in wrapper
    return func(*args, session=session, **kwargs)
           ^^^^^^^^^^^^^^^^^^^^^^^^^^^^^^^^^^^^^^
  File "/home/airflow/.local/lib/python3.12/site-packages/airflow/models/taskinstance.py", line 3004, in _run_raw_task
    return _run_raw_task(
           ^^^^^^^^^^^^^^
  File "/home/airflow/.local/lib/python3.12/site-packages/airflow/models/taskinstance.py", line 273, in _run_raw_task
    TaskInstance._execute_task_with_callbacks(
  File "/home/airflow/.local/lib/python3.12/site-packages/airflow/models/taskinstance.py", line 3158, in _execute_task_with_callbacks
    result = self._execute_task(context, task_orig)
             ^^^^^^^^^^^^^^^^^^^^^^^^^^^^^^^^^^^^^^
  File "/home/airflow/.local/lib/python3.12/site-packages/airflow/models/taskinstance.py", line 3182, in _execute_task
    return _execute_task(self, context, task_orig)
           ^^^^^^^^^^^^^^^^^^^^^^^^^^^^^^^^^^^^^^^
  File "/home/airflow/.local/lib/python3.12/site-packages/airflow/models/taskinstance.py", line 767, in _execute_task
    result = _execute_callable(context=context, **execute_callable_kwargs)
             ^^^^^^^^^^^^^^^^^^^^^^^^^^^^^^^^^^^^^^^^^^^^^^^^^^^^^^^^^^^^^
  File "/home/airflow/.local/lib/python3.12/site-packages/airflow/models/taskinstance.py", line 733, in _execute_callable
    return ExecutionCallableRunner(
           ^^^^^^^^^^^^^^^^^^^^^^^^
  File "/home/airflow/.local/lib/python3.12/site-packages/airflow/utils/operator_helpers.py", line 252, in run
    return self.func(*args, **kwargs)
           ^^^^^^^^^^^^^^^^^^^^^^^^^^
  File "/home/airflow/.local/lib/python3.12/site-packages/airflow/models/baseoperator.py", line 406, in wrapper
    return func(self, *args, **kwargs)
           ^^^^^^^^^^^^^^^^^^^^^^^^^^^
  File "/home/airflow/.local/lib/python3.12/site-packages/airflow/operators/bash.py", line 249, in execute
    raise AirflowException(
airflow.exceptions.AirflowException: Bash command failed. The command returned a non-zero exit code 1.
[2025-04-24T00:17:48.279+0000] {local_task_job_runner.py:266} INFO - Task exited with return code 1
[2025-04-24T00:17:48.300+0000] {taskinstance.py:3900} INFO - 0 downstream tasks scheduled from follow-on schedule check
[2025-04-24T00:17:48.305+0000] {local_task_job_runner.py:245} INFO - ::endgroup::
