[2025-04-23T23:26:21.423+0000] {local_task_job_runner.py:123} INFO - ::group::Pre task execution logs
[2025-04-23T23:26:21.442+0000] {taskinstance.py:2612} INFO - Dependencies all met for dep_context=non-requeueable deps ti=<TaskInstance: dbt_stock_project.dbt_run manual__2025-04-23T23:26:20.882777+00:00 [queued]>
[2025-04-23T23:26:21.450+0000] {taskinstance.py:2612} INFO - Dependencies all met for dep_context=requeueable deps ti=<TaskInstance: dbt_stock_project.dbt_run manual__2025-04-23T23:26:20.882777+00:00 [queued]>
[2025-04-23T23:26:21.452+0000] {taskinstance.py:2865} INFO - Starting attempt 1 of 1
[2025-04-23T23:26:21.466+0000] {taskinstance.py:2888} INFO - Executing <Task(BashOperator): dbt_run> on 2025-04-23 23:26:20.882777+00:00
[2025-04-23T23:26:21.474+0000] {standard_task_runner.py:104} INFO - Running: ['***', 'tasks', 'run', 'dbt_stock_project', 'dbt_run', 'manual__2025-04-23T23:26:20.882777+00:00', '--job-id', '309', '--raw', '--subdir', 'DAGS_FOLDER/226_lab2_elt.py', '--cfg-path', '/tmp/tmpeihv_73i']
[2025-04-23T23:26:21.477+0000] {logging_mixin.py:190} WARNING - /home/***/.local/lib/python3.12/site-packages/***/task/task_runner/standard_task_runner.py:70 DeprecationWarning: This process (pid=4019) is multi-threaded, use of fork() may lead to deadlocks in the child.
[2025-04-23T23:26:21.477+0000] {standard_task_runner.py:105} INFO - Job 309: Subtask dbt_run
[2025-04-23T23:26:21.478+0000] {standard_task_runner.py:72} INFO - Started process 4020 to run task
[2025-04-23T23:26:21.531+0000] {task_command.py:467} INFO - Running <TaskInstance: dbt_stock_project.dbt_run manual__2025-04-23T23:26:20.882777+00:00 [running]> on host d01273b1fd04
[2025-04-23T23:26:21.632+0000] {taskinstance.py:3131} INFO - Exporting env vars: AIRFLOW_CTX_DAG_OWNER='***' AIRFLOW_CTX_DAG_ID='dbt_stock_project' AIRFLOW_CTX_TASK_ID='dbt_run' AIRFLOW_CTX_EXECUTION_DATE='2025-04-23T23:26:20.882777+00:00' AIRFLOW_CTX_TRY_NUMBER='1' AIRFLOW_CTX_DAG_RUN_ID='manual__2025-04-23T23:26:20.882777+00:00'
[2025-04-23T23:26:21.634+0000] {taskinstance.py:731} INFO - ::endgroup::
[2025-04-23T23:26:21.652+0000] {subprocess.py:63} INFO - Tmp dir root location: /tmp
[2025-04-23T23:26:21.654+0000] {subprocess.py:75} INFO - Running command: ['/usr/bin/bash', '-c', '/home/***/.local/bin/dbt run --profiles-dir /home/***/.dbt --project-dir /opt/***/dbt']
[2025-04-23T23:26:21.665+0000] {subprocess.py:86} INFO - Output:
[2025-04-23T23:26:23.515+0000] {subprocess.py:93} INFO - [0m23:26:23  Running with dbt=1.8.7
[2025-04-23T23:26:24.450+0000] {subprocess.py:93} INFO - [0m23:26:24  Registered adapter: snowflake=1.8.1
[2025-04-23T23:26:24.780+0000] {subprocess.py:93} INFO - [0m23:26:24  Encountered an error:
[2025-04-23T23:26:24.780+0000] {subprocess.py:93} INFO - Parsing Error
[2025-04-23T23:26:24.781+0000] {subprocess.py:93} INFO -   Error reading dbt_stock_project: output/schema.yml - Runtime Error
[2025-04-23T23:26:24.781+0000] {subprocess.py:93} INFO -     Syntax error near line 39
[2025-04-23T23:26:24.782+0000] {subprocess.py:93} INFO -     ------------------------------
[2025-04-23T23:26:24.782+0000] {subprocess.py:93} INFO -     36 |           - not_null
[2025-04-23T23:26:24.783+0000] {subprocess.py:93} INFO -     37 |           -positive_values
[2025-04-23T23:26:24.783+0000] {subprocess.py:93} INFO -     38 |
[2025-04-23T23:26:24.783+0000] {subprocess.py:93} INFO -     39 |   - name: rsi
[2025-04-23T23:26:24.784+0000] {subprocess.py:93} INFO -     40 |     description: "Relative Strength Index (RSI) calculated from stock prices"
[2025-04-23T23:26:24.784+0000] {subprocess.py:93} INFO -     41 |     columns:
[2025-04-23T23:26:24.784+0000] {subprocess.py:93} INFO -     42 |       - name: trade_date
[2025-04-23T23:26:24.785+0000] {subprocess.py:93} INFO - 
[2025-04-23T23:26:24.785+0000] {subprocess.py:93} INFO -     Raw Error:
[2025-04-23T23:26:24.786+0000] {subprocess.py:93} INFO -     ------------------------------
[2025-04-23T23:26:24.786+0000] {subprocess.py:93} INFO -     while scanning a simple key
[2025-04-23T23:26:24.787+0000] {subprocess.py:93} INFO -       in "<unicode string>", line 37, column 11
[2025-04-23T23:26:24.787+0000] {subprocess.py:93} INFO -     could not find expected ':'
[2025-04-23T23:26:24.788+0000] {subprocess.py:93} INFO -       in "<unicode string>", line 39, column 3
[2025-04-23T23:26:25.480+0000] {subprocess.py:97} INFO - Command exited with return code 2
[2025-04-23T23:26:25.491+0000] {taskinstance.py:3310} ERROR - Task failed with exception
Traceback (most recent call last):
  File "/home/airflow/.local/lib/python3.12/site-packages/airflow/models/taskinstance.py", line 767, in _execute_task
    result = _execute_callable(context=context, **execute_callable_kwargs)
             ^^^^^^^^^^^^^^^^^^^^^^^^^^^^^^^^^^^^^^^^^^^^^^^^^^^^^^^^^^^^^
  File "/home/airflow/.local/lib/python3.12/site-packages/airflow/models/taskinstance.py", line 733, in _execute_callable
    return ExecutionCallableRunner(
           ^^^^^^^^^^^^^^^^^^^^^^^^
  File "/home/airflow/.local/lib/python3.12/site-packages/airflow/utils/operator_helpers.py", line 252, in run
    return self.func(*args, **kwargs)
           ^^^^^^^^^^^^^^^^^^^^^^^^^^
  File "/home/airflow/.local/lib/python3.12/site-packages/airflow/models/baseoperator.py", line 406, in wrapper
    return func(self, *args, **kwargs)
           ^^^^^^^^^^^^^^^^^^^^^^^^^^^
  File "/home/airflow/.local/lib/python3.12/site-packages/airflow/operators/bash.py", line 249, in execute
    raise AirflowException(
airflow.exceptions.AirflowException: Bash command failed. The command returned a non-zero exit code 2.
[2025-04-23T23:26:25.495+0000] {taskinstance.py:1225} INFO - Marking task as FAILED. dag_id=dbt_stock_project, task_id=dbt_run, run_id=manual__2025-04-23T23:26:20.882777+00:00, execution_date=20250423T232620, start_date=20250423T232621, end_date=20250423T232625
[2025-04-23T23:26:25.510+0000] {taskinstance.py:340} INFO - ::group::Post task execution logs
[2025-04-23T23:26:25.511+0000] {standard_task_runner.py:124} ERROR - Failed to execute job 309 for task dbt_run (Bash command failed. The command returned a non-zero exit code 2.; 4020)
Traceback (most recent call last):
  File "/home/airflow/.local/lib/python3.12/site-packages/airflow/task/task_runner/standard_task_runner.py", line 117, in _start_by_fork
    ret = args.func(args, dag=self.dag)
          ^^^^^^^^^^^^^^^^^^^^^^^^^^^^^
  File "/home/airflow/.local/lib/python3.12/site-packages/airflow/cli/cli_config.py", line 49, in command
    return func(*args, **kwargs)
           ^^^^^^^^^^^^^^^^^^^^^
  File "/home/airflow/.local/lib/python3.12/site-packages/airflow/utils/cli.py", line 115, in wrapper
    return f(*args, **kwargs)
           ^^^^^^^^^^^^^^^^^^
  File "/home/airflow/.local/lib/python3.12/site-packages/airflow/cli/commands/task_command.py", line 483, in task_run
    task_return_code = _run_task_by_selected_method(args, _dag, ti)
                       ^^^^^^^^^^^^^^^^^^^^^^^^^^^^^^^^^^^^^^^^^^^^
  File "/home/airflow/.local/lib/python3.12/site-packages/airflow/cli/commands/task_command.py", line 256, in _run_task_by_selected_method
    return _run_raw_task(args, ti)
           ^^^^^^^^^^^^^^^^^^^^^^^
  File "/home/airflow/.local/lib/python3.12/site-packages/airflow/cli/commands/task_command.py", line 341, in _run_raw_task
    return ti._run_raw_task(
           ^^^^^^^^^^^^^^^^^
  File "/home/airflow/.local/lib/python3.12/site-packages/airflow/utils/session.py", line 97, in wrapper
    return func(*args, session=session, **kwargs)
           ^^^^^^^^^^^^^^^^^^^^^^^^^^^^^^^^^^^^^^
  File "/home/airflow/.local/lib/python3.12/site-packages/airflow/models/taskinstance.py", line 3004, in _run_raw_task
    return _run_raw_task(
           ^^^^^^^^^^^^^^
  File "/home/airflow/.local/lib/python3.12/site-packages/airflow/models/taskinstance.py", line 273, in _run_raw_task
    TaskInstance._execute_task_with_callbacks(
  File "/home/airflow/.local/lib/python3.12/site-packages/airflow/models/taskinstance.py", line 3158, in _execute_task_with_callbacks
    result = self._execute_task(context, task_orig)
             ^^^^^^^^^^^^^^^^^^^^^^^^^^^^^^^^^^^^^^
  File "/home/airflow/.local/lib/python3.12/site-packages/airflow/models/taskinstance.py", line 3182, in _execute_task
    return _execute_task(self, context, task_orig)
           ^^^^^^^^^^^^^^^^^^^^^^^^^^^^^^^^^^^^^^^
  File "/home/airflow/.local/lib/python3.12/site-packages/airflow/models/taskinstance.py", line 767, in _execute_task
    result = _execute_callable(context=context, **execute_callable_kwargs)
             ^^^^^^^^^^^^^^^^^^^^^^^^^^^^^^^^^^^^^^^^^^^^^^^^^^^^^^^^^^^^^
  File "/home/airflow/.local/lib/python3.12/site-packages/airflow/models/taskinstance.py", line 733, in _execute_callable
    return ExecutionCallableRunner(
           ^^^^^^^^^^^^^^^^^^^^^^^^
  File "/home/airflow/.local/lib/python3.12/site-packages/airflow/utils/operator_helpers.py", line 252, in run
    return self.func(*args, **kwargs)
           ^^^^^^^^^^^^^^^^^^^^^^^^^^
  File "/home/airflow/.local/lib/python3.12/site-packages/airflow/models/baseoperator.py", line 406, in wrapper
    return func(self, *args, **kwargs)
           ^^^^^^^^^^^^^^^^^^^^^^^^^^^
  File "/home/airflow/.local/lib/python3.12/site-packages/airflow/operators/bash.py", line 249, in execute
    raise AirflowException(
airflow.exceptions.AirflowException: Bash command failed. The command returned a non-zero exit code 2.
[2025-04-23T23:26:25.519+0000] {local_task_job_runner.py:266} INFO - Task exited with return code 1
[2025-04-23T23:26:25.538+0000] {taskinstance.py:3900} INFO - 0 downstream tasks scheduled from follow-on schedule check
[2025-04-23T23:26:25.543+0000] {local_task_job_runner.py:245} INFO - ::endgroup::
