[2025-04-22T15:46:23.760+0000] {local_task_job_runner.py:123} INFO - ::group::Pre task execution logs
[2025-04-22T15:46:23.779+0000] {taskinstance.py:2612} INFO - Dependencies all met for dep_context=non-requeueable deps ti=<TaskInstance: dbt_stock_project.dbt_run manual__2025-04-22T15:46:22.714546+00:00 [queued]>
[2025-04-22T15:46:23.788+0000] {taskinstance.py:2612} INFO - Dependencies all met for dep_context=requeueable deps ti=<TaskInstance: dbt_stock_project.dbt_run manual__2025-04-22T15:46:22.714546+00:00 [queued]>
[2025-04-22T15:46:23.790+0000] {taskinstance.py:2865} INFO - Starting attempt 1 of 1
[2025-04-22T15:46:23.804+0000] {taskinstance.py:2888} INFO - Executing <Task(BashOperator): dbt_run> on 2025-04-22 15:46:22.714546+00:00
[2025-04-22T15:46:23.813+0000] {standard_task_runner.py:104} INFO - Running: ['***', 'tasks', 'run', 'dbt_stock_project', 'dbt_run', 'manual__2025-04-22T15:46:22.714546+00:00', '--job-id', '285', '--raw', '--subdir', 'DAGS_FOLDER/226_lab2_elt.py', '--cfg-path', '/tmp/tmpmanxl8gf']
[2025-04-22T15:46:23.817+0000] {standard_task_runner.py:105} INFO - Job 285: Subtask dbt_run
[2025-04-22T15:46:23.817+0000] {logging_mixin.py:190} WARNING - /home/***/.local/lib/python3.12/site-packages/***/task/task_runner/standard_task_runner.py:70 DeprecationWarning: This process (pid=1541) is multi-threaded, use of fork() may lead to deadlocks in the child.
[2025-04-22T15:46:23.818+0000] {standard_task_runner.py:72} INFO - Started process 1542 to run task
[2025-04-22T15:46:23.874+0000] {task_command.py:467} INFO - Running <TaskInstance: dbt_stock_project.dbt_run manual__2025-04-22T15:46:22.714546+00:00 [running]> on host 9d71c5fa265e
[2025-04-22T15:46:23.964+0000] {taskinstance.py:3131} INFO - Exporting env vars: AIRFLOW_CTX_DAG_OWNER='***' AIRFLOW_CTX_DAG_ID='dbt_stock_project' AIRFLOW_CTX_TASK_ID='dbt_run' AIRFLOW_CTX_EXECUTION_DATE='2025-04-22T15:46:22.714546+00:00' AIRFLOW_CTX_TRY_NUMBER='1' AIRFLOW_CTX_DAG_RUN_ID='manual__2025-04-22T15:46:22.714546+00:00'
[2025-04-22T15:46:23.966+0000] {taskinstance.py:731} INFO - ::endgroup::
[2025-04-22T15:46:23.995+0000] {subprocess.py:63} INFO - Tmp dir root location: /tmp
[2025-04-22T15:46:23.997+0000] {subprocess.py:75} INFO - Running command: ['/usr/bin/bash', '-c', '/home/***/.local/bin/dbt run --profiles-dir /home/***/.dbt --project-dir /opt/***/dbt']
[2025-04-22T15:46:24.005+0000] {subprocess.py:86} INFO - Output:
[2025-04-22T15:46:27.053+0000] {subprocess.py:93} INFO - [0m15:46:27  Running with dbt=1.8.7
[2025-04-22T15:46:28.952+0000] {subprocess.py:93} INFO - [0m15:46:28  Registered adapter: snowflake=1.8.1
[2025-04-22T15:46:29.803+0000] {subprocess.py:93} INFO - [0m15:46:29  [[33mWARNING[0m]: Deprecated functionality
[2025-04-22T15:46:29.805+0000] {subprocess.py:93} INFO - The `tests` config has been renamed to `data_tests`. Please see
[2025-04-22T15:46:29.806+0000] {subprocess.py:93} INFO - https://docs.getdbt.com/docs/build/data-tests#new-data_tests-syntax for more
[2025-04-22T15:46:29.807+0000] {subprocess.py:93} INFO - information.
[2025-04-22T15:46:30.414+0000] {subprocess.py:93} INFO - [0m15:46:30  Found 7 models, 9 data tests, 3 sources, 459 macros
[2025-04-22T15:46:30.419+0000] {subprocess.py:93} INFO - [0m15:46:30
[2025-04-22T15:46:31.837+0000] {subprocess.py:93} INFO - [0m15:46:31  Concurrency: 1 threads (target='dev')
[2025-04-22T15:46:31.838+0000] {subprocess.py:93} INFO - [0m15:46:31
[2025-04-22T15:46:31.852+0000] {subprocess.py:93} INFO - [0m15:46:31  1 of 5 START sql table model analytics.actual_vs_forecast ...................... [RUN]
[2025-04-22T15:46:34.168+0000] {subprocess.py:93} INFO - [0m15:46:34  1 of 5 OK created sql table model analytics.actual_vs_forecast ................. [[32mSUCCESS 1[0m in 2.31s]
[2025-04-22T15:46:34.239+0000] {subprocess.py:93} INFO - [0m15:46:34  2 of 5 START sql table model analytics.stock_indicators ........................ [RUN]
[2025-04-22T15:46:35.810+0000] {subprocess.py:93} INFO - [0m15:46:35  2 of 5 OK created sql table model analytics.stock_indicators ................... [[32mSUCCESS 1[0m in 1.57s]
[2025-04-22T15:46:35.815+0000] {subprocess.py:93} INFO - [0m15:46:35  3 of 5 START sql table model analytics.volume_summary .......................... [RUN]
[2025-04-22T15:46:37.329+0000] {subprocess.py:93} INFO - [0m15:46:37  3 of 5 OK created sql table model analytics.volume_summary ..................... [[32mSUCCESS 1[0m in 1.51s]
[2025-04-22T15:46:37.333+0000] {subprocess.py:93} INFO - [0m15:46:37  4 of 5 START sql table model analytics.moving_averages ......................... [RUN]
[2025-04-22T15:46:38.010+0000] {subprocess.py:93} INFO - [0m15:46:38  4 of 5 ERROR creating sql table model analytics.moving_averages ................ [[31mERROR[0m in 0.68s]
[2025-04-22T15:46:38.014+0000] {subprocess.py:93} INFO - [0m15:46:38  5 of 5 START sql table model analytics.rsi ..................................... [RUN]
[2025-04-22T15:46:38.790+0000] {subprocess.py:93} INFO - [0m15:46:38  5 of 5 ERROR creating sql table model analytics.rsi ............................ [[31mERROR[0m in 0.77s]
[2025-04-22T15:46:38.797+0000] {subprocess.py:93} INFO - [0m15:46:38
[2025-04-22T15:46:38.798+0000] {subprocess.py:93} INFO - [0m15:46:38  Finished running 5 table models in 0 hours 0 minutes and 8.38 seconds (8.38s).
[2025-04-22T15:46:38.895+0000] {subprocess.py:93} INFO - [0m15:46:38
[2025-04-22T15:46:38.896+0000] {subprocess.py:93} INFO - [0m15:46:38  [31mCompleted with 2 errors and 0 warnings:[0m
[2025-04-22T15:46:38.896+0000] {subprocess.py:93} INFO - [0m15:46:38
[2025-04-22T15:46:38.897+0000] {subprocess.py:93} INFO - [0m15:46:38    Database Error in model moving_averages (models/output/moving_averages.sql)
[2025-04-22T15:46:38.898+0000] {subprocess.py:93} INFO -   000904 (42000): SQL compilation error: error line 23 at position 4
[2025-04-22T15:46:38.899+0000] {subprocess.py:93} INFO -   invalid identifier 'CLOSE_PRICE'
[2025-04-22T15:46:38.899+0000] {subprocess.py:93} INFO -   compiled code at target/run/dbt_stock_project/models/output/moving_averages.sql
[2025-04-22T15:46:38.900+0000] {subprocess.py:93} INFO - [0m15:46:38
[2025-04-22T15:46:38.901+0000] {subprocess.py:93} INFO - [0m15:46:38    Database Error in model rsi (models/output/rsi.sql)
[2025-04-22T15:46:38.901+0000] {subprocess.py:93} INFO -   000904 (42000): SQL compilation error: error line 21 at position 4
[2025-04-22T15:46:38.902+0000] {subprocess.py:93} INFO -   invalid identifier 'CLOSE_PRICE'
[2025-04-22T15:46:38.903+0000] {subprocess.py:93} INFO -   compiled code at target/run/dbt_stock_project/models/output/rsi.sql
[2025-04-22T15:46:38.904+0000] {subprocess.py:93} INFO - [0m15:46:38
[2025-04-22T15:46:38.906+0000] {subprocess.py:93} INFO - [0m15:46:38  Done. PASS=3 WARN=0 ERROR=2 SKIP=0 TOTAL=5
[2025-04-22T15:46:39.936+0000] {subprocess.py:97} INFO - Command exited with return code 1
[2025-04-22T15:46:39.947+0000] {taskinstance.py:3310} ERROR - Task failed with exception
Traceback (most recent call last):
  File "/home/airflow/.local/lib/python3.12/site-packages/airflow/models/taskinstance.py", line 767, in _execute_task
    result = _execute_callable(context=context, **execute_callable_kwargs)
             ^^^^^^^^^^^^^^^^^^^^^^^^^^^^^^^^^^^^^^^^^^^^^^^^^^^^^^^^^^^^^
  File "/home/airflow/.local/lib/python3.12/site-packages/airflow/models/taskinstance.py", line 733, in _execute_callable
    return ExecutionCallableRunner(
           ^^^^^^^^^^^^^^^^^^^^^^^^
  File "/home/airflow/.local/lib/python3.12/site-packages/airflow/utils/operator_helpers.py", line 252, in run
    return self.func(*args, **kwargs)
           ^^^^^^^^^^^^^^^^^^^^^^^^^^
  File "/home/airflow/.local/lib/python3.12/site-packages/airflow/models/baseoperator.py", line 406, in wrapper
    return func(self, *args, **kwargs)
           ^^^^^^^^^^^^^^^^^^^^^^^^^^^
  File "/home/airflow/.local/lib/python3.12/site-packages/airflow/operators/bash.py", line 249, in execute
    raise AirflowException(
airflow.exceptions.AirflowException: Bash command failed. The command returned a non-zero exit code 1.
[2025-04-22T15:46:39.954+0000] {taskinstance.py:1225} INFO - Marking task as FAILED. dag_id=dbt_stock_project, task_id=dbt_run, run_id=manual__2025-04-22T15:46:22.714546+00:00, execution_date=20250422T154622, start_date=20250422T154623, end_date=20250422T154639
[2025-04-22T15:46:39.966+0000] {taskinstance.py:340} INFO - ::group::Post task execution logs
[2025-04-22T15:46:39.967+0000] {standard_task_runner.py:124} ERROR - Failed to execute job 285 for task dbt_run (Bash command failed. The command returned a non-zero exit code 1.; 1542)
Traceback (most recent call last):
  File "/home/airflow/.local/lib/python3.12/site-packages/airflow/task/task_runner/standard_task_runner.py", line 117, in _start_by_fork
    ret = args.func(args, dag=self.dag)
          ^^^^^^^^^^^^^^^^^^^^^^^^^^^^^
  File "/home/airflow/.local/lib/python3.12/site-packages/airflow/cli/cli_config.py", line 49, in command
    return func(*args, **kwargs)
           ^^^^^^^^^^^^^^^^^^^^^
  File "/home/airflow/.local/lib/python3.12/site-packages/airflow/utils/cli.py", line 115, in wrapper
    return f(*args, **kwargs)
           ^^^^^^^^^^^^^^^^^^
  File "/home/airflow/.local/lib/python3.12/site-packages/airflow/cli/commands/task_command.py", line 483, in task_run
    task_return_code = _run_task_by_selected_method(args, _dag, ti)
                       ^^^^^^^^^^^^^^^^^^^^^^^^^^^^^^^^^^^^^^^^^^^^
  File "/home/airflow/.local/lib/python3.12/site-packages/airflow/cli/commands/task_command.py", line 256, in _run_task_by_selected_method
    return _run_raw_task(args, ti)
           ^^^^^^^^^^^^^^^^^^^^^^^
  File "/home/airflow/.local/lib/python3.12/site-packages/airflow/cli/commands/task_command.py", line 341, in _run_raw_task
    return ti._run_raw_task(
           ^^^^^^^^^^^^^^^^^
  File "/home/airflow/.local/lib/python3.12/site-packages/airflow/utils/session.py", line 97, in wrapper
    return func(*args, session=session, **kwargs)
           ^^^^^^^^^^^^^^^^^^^^^^^^^^^^^^^^^^^^^^
  File "/home/airflow/.local/lib/python3.12/site-packages/airflow/models/taskinstance.py", line 3004, in _run_raw_task
    return _run_raw_task(
           ^^^^^^^^^^^^^^
  File "/home/airflow/.local/lib/python3.12/site-packages/airflow/models/taskinstance.py", line 273, in _run_raw_task
    TaskInstance._execute_task_with_callbacks(
  File "/home/airflow/.local/lib/python3.12/site-packages/airflow/models/taskinstance.py", line 3158, in _execute_task_with_callbacks
    result = self._execute_task(context, task_orig)
             ^^^^^^^^^^^^^^^^^^^^^^^^^^^^^^^^^^^^^^
  File "/home/airflow/.local/lib/python3.12/site-packages/airflow/models/taskinstance.py", line 3182, in _execute_task
    return _execute_task(self, context, task_orig)
           ^^^^^^^^^^^^^^^^^^^^^^^^^^^^^^^^^^^^^^^
  File "/home/airflow/.local/lib/python3.12/site-packages/airflow/models/taskinstance.py", line 767, in _execute_task
    result = _execute_callable(context=context, **execute_callable_kwargs)
             ^^^^^^^^^^^^^^^^^^^^^^^^^^^^^^^^^^^^^^^^^^^^^^^^^^^^^^^^^^^^^
  File "/home/airflow/.local/lib/python3.12/site-packages/airflow/models/taskinstance.py", line 733, in _execute_callable
    return ExecutionCallableRunner(
           ^^^^^^^^^^^^^^^^^^^^^^^^
  File "/home/airflow/.local/lib/python3.12/site-packages/airflow/utils/operator_helpers.py", line 252, in run
    return self.func(*args, **kwargs)
           ^^^^^^^^^^^^^^^^^^^^^^^^^^
  File "/home/airflow/.local/lib/python3.12/site-packages/airflow/models/baseoperator.py", line 406, in wrapper
    return func(self, *args, **kwargs)
           ^^^^^^^^^^^^^^^^^^^^^^^^^^^
  File "/home/airflow/.local/lib/python3.12/site-packages/airflow/operators/bash.py", line 249, in execute
    raise AirflowException(
airflow.exceptions.AirflowException: Bash command failed. The command returned a non-zero exit code 1.
[2025-04-22T15:46:39.991+0000] {local_task_job_runner.py:266} INFO - Task exited with return code 1
[2025-04-22T15:46:40.010+0000] {taskinstance.py:3900} INFO - 0 downstream tasks scheduled from follow-on schedule check
[2025-04-22T15:46:40.015+0000] {local_task_job_runner.py:245} INFO - ::endgroup::
