[2025-04-24T00:49:50.537+0000] {local_task_job_runner.py:123} INFO - ::group::Pre task execution logs
[2025-04-24T00:49:50.553+0000] {taskinstance.py:2612} INFO - Dependencies all met for dep_context=non-requeueable deps ti=<TaskInstance: dbt_stock_project.dbt_run manual__2025-04-24T00:49:49.630082+00:00 [queued]>
[2025-04-24T00:49:50.561+0000] {taskinstance.py:2612} INFO - Dependencies all met for dep_context=requeueable deps ti=<TaskInstance: dbt_stock_project.dbt_run manual__2025-04-24T00:49:49.630082+00:00 [queued]>
[2025-04-24T00:49:50.563+0000] {taskinstance.py:2865} INFO - Starting attempt 1 of 1
[2025-04-24T00:49:50.576+0000] {taskinstance.py:2888} INFO - Executing <Task(BashOperator): dbt_run> on 2025-04-24 00:49:49.630082+00:00
[2025-04-24T00:49:50.584+0000] {logging_mixin.py:190} WARNING - /home/***/.local/lib/python3.12/site-packages/***/task/task_runner/standard_task_runner.py:70 DeprecationWarning: This process (pid=8521) is multi-threaded, use of fork() may lead to deadlocks in the child.
[2025-04-24T00:49:50.583+0000] {standard_task_runner.py:104} INFO - Running: ['***', 'tasks', 'run', 'dbt_stock_project', 'dbt_run', 'manual__2025-04-24T00:49:49.630082+00:00', '--job-id', '342', '--raw', '--subdir', 'DAGS_FOLDER/226_lab2_elt.py', '--cfg-path', '/tmp/tmpm27132qt']
[2025-04-24T00:49:50.586+0000] {standard_task_runner.py:72} INFO - Started process 8522 to run task
[2025-04-24T00:49:50.587+0000] {standard_task_runner.py:105} INFO - Job 342: Subtask dbt_run
[2025-04-24T00:49:50.633+0000] {task_command.py:467} INFO - Running <TaskInstance: dbt_stock_project.dbt_run manual__2025-04-24T00:49:49.630082+00:00 [running]> on host d01273b1fd04
[2025-04-24T00:49:50.708+0000] {taskinstance.py:3131} INFO - Exporting env vars: AIRFLOW_CTX_DAG_OWNER='***' AIRFLOW_CTX_DAG_ID='dbt_stock_project' AIRFLOW_CTX_TASK_ID='dbt_run' AIRFLOW_CTX_EXECUTION_DATE='2025-04-24T00:49:49.630082+00:00' AIRFLOW_CTX_TRY_NUMBER='1' AIRFLOW_CTX_DAG_RUN_ID='manual__2025-04-24T00:49:49.630082+00:00'
[2025-04-24T00:49:50.709+0000] {taskinstance.py:731} INFO - ::endgroup::
[2025-04-24T00:49:50.725+0000] {subprocess.py:63} INFO - Tmp dir root location: /tmp
[2025-04-24T00:49:50.727+0000] {subprocess.py:75} INFO - Running command: ['/usr/bin/bash', '-c', '/home/***/.local/bin/dbt run --profiles-dir /home/***/.dbt --project-dir /opt/***/dbt']
[2025-04-24T00:49:50.736+0000] {subprocess.py:86} INFO - Output:
[2025-04-24T00:49:52.568+0000] {subprocess.py:93} INFO - [0m00:49:52  Running with dbt=1.8.7
[2025-04-24T00:49:53.551+0000] {subprocess.py:93} INFO - [0m00:49:53  Registered adapter: snowflake=1.8.1
[2025-04-24T00:49:54.303+0000] {subprocess.py:93} INFO - [0m00:49:54  [[33mWARNING[0m]: Deprecated functionality
[2025-04-24T00:49:54.304+0000] {subprocess.py:93} INFO - The `tests` config has been renamed to `data_tests`. Please see
[2025-04-24T00:49:54.305+0000] {subprocess.py:93} INFO - https://docs.getdbt.com/docs/build/data-tests#new-data_tests-syntax for more
[2025-04-24T00:49:54.306+0000] {subprocess.py:93} INFO - information.
[2025-04-24T00:49:54.723+0000] {subprocess.py:93} INFO - [0m00:49:54  Found 6 models, 22 data tests, 3 sources, 459 macros
[2025-04-24T00:49:54.728+0000] {subprocess.py:93} INFO - [0m00:49:54
[2025-04-24T00:49:55.887+0000] {subprocess.py:93} INFO - [0m00:49:55  Concurrency: 1 threads (target='dev')
[2025-04-24T00:49:55.888+0000] {subprocess.py:93} INFO - [0m00:49:55
[2025-04-24T00:49:55.968+0000] {subprocess.py:93} INFO - [0m00:49:55  1 of 4 START sql table model analytics.stock_indicators ........................ [RUN]
[2025-04-24T00:49:57.118+0000] {subprocess.py:93} INFO - [0m00:49:57  1 of 4 OK created sql table model analytics.stock_indicators ................... [[32mSUCCESS 1[0m in 1.15s]
[2025-04-24T00:49:57.121+0000] {subprocess.py:93} INFO - [0m00:49:57  2 of 4 START sql table model analytics.volume_summary .......................... [RUN]
[2025-04-24T00:49:58.523+0000] {subprocess.py:93} INFO - [0m00:49:58  2 of 4 OK created sql table model analytics.volume_summary ..................... [[32mSUCCESS 1[0m in 1.40s]
[2025-04-24T00:49:58.526+0000] {subprocess.py:93} INFO - [0m00:49:58  3 of 4 START sql table model analytics.moving_averages ......................... [RUN]
[2025-04-24T00:49:58.974+0000] {subprocess.py:93} INFO - [0m00:49:58  3 of 4 ERROR creating sql table model analytics.moving_averages ................ [[31mERROR[0m in 0.45s]
[2025-04-24T00:49:58.978+0000] {subprocess.py:93} INFO - [0m00:49:58  4 of 4 START sql table model analytics.rsi ..................................... [RUN]
[2025-04-24T00:50:00.199+0000] {subprocess.py:93} INFO - [0m00:50:00  4 of 4 OK created sql table model analytics.rsi ................................ [[32mSUCCESS 1[0m in 1.22s]
[2025-04-24T00:50:00.205+0000] {subprocess.py:93} INFO - [0m00:50:00
[2025-04-24T00:50:00.206+0000] {subprocess.py:93} INFO - [0m00:50:00  Finished running 4 table models in 0 hours 0 minutes and 5.48 seconds (5.48s).
[2025-04-24T00:50:00.421+0000] {subprocess.py:93} INFO - [0m00:50:00
[2025-04-24T00:50:00.422+0000] {subprocess.py:93} INFO - [0m00:50:00  [31mCompleted with 1 error and 0 warnings:[0m
[2025-04-24T00:50:00.424+0000] {subprocess.py:93} INFO - [0m00:50:00
[2025-04-24T00:50:00.425+0000] {subprocess.py:93} INFO - [0m00:50:00    Database Error in model moving_averages (models/output/moving_averages.sql)
[2025-04-24T00:50:00.426+0000] {subprocess.py:93} INFO -   001003 (42000): SQL compilation error:
[2025-04-24T00:50:00.427+0000] {subprocess.py:93} INFO -   syntax error line 50 at position 27 unexpected ';'.
[2025-04-24T00:50:00.428+0000] {subprocess.py:93} INFO -   compiled code at target/run/dbt_stock_project/models/output/moving_averages.sql
[2025-04-24T00:50:00.428+0000] {subprocess.py:93} INFO - [0m00:50:00
[2025-04-24T00:50:00.429+0000] {subprocess.py:93} INFO - [0m00:50:00  Done. PASS=3 WARN=0 ERROR=1 SKIP=0 TOTAL=4
[2025-04-24T00:50:01.445+0000] {subprocess.py:97} INFO - Command exited with return code 1
[2025-04-24T00:50:01.457+0000] {taskinstance.py:3310} ERROR - Task failed with exception
Traceback (most recent call last):
  File "/home/airflow/.local/lib/python3.12/site-packages/airflow/models/taskinstance.py", line 767, in _execute_task
    result = _execute_callable(context=context, **execute_callable_kwargs)
             ^^^^^^^^^^^^^^^^^^^^^^^^^^^^^^^^^^^^^^^^^^^^^^^^^^^^^^^^^^^^^
  File "/home/airflow/.local/lib/python3.12/site-packages/airflow/models/taskinstance.py", line 733, in _execute_callable
    return ExecutionCallableRunner(
           ^^^^^^^^^^^^^^^^^^^^^^^^
  File "/home/airflow/.local/lib/python3.12/site-packages/airflow/utils/operator_helpers.py", line 252, in run
    return self.func(*args, **kwargs)
           ^^^^^^^^^^^^^^^^^^^^^^^^^^
  File "/home/airflow/.local/lib/python3.12/site-packages/airflow/models/baseoperator.py", line 406, in wrapper
    return func(self, *args, **kwargs)
           ^^^^^^^^^^^^^^^^^^^^^^^^^^^
  File "/home/airflow/.local/lib/python3.12/site-packages/airflow/operators/bash.py", line 249, in execute
    raise AirflowException(
airflow.exceptions.AirflowException: Bash command failed. The command returned a non-zero exit code 1.
[2025-04-24T00:50:01.462+0000] {taskinstance.py:1225} INFO - Marking task as FAILED. dag_id=dbt_stock_project, task_id=dbt_run, run_id=manual__2025-04-24T00:49:49.630082+00:00, execution_date=20250424T004949, start_date=20250424T004950, end_date=20250424T005001
[2025-04-24T00:50:01.482+0000] {taskinstance.py:340} INFO - ::group::Post task execution logs
[2025-04-24T00:50:01.483+0000] {standard_task_runner.py:124} ERROR - Failed to execute job 342 for task dbt_run (Bash command failed. The command returned a non-zero exit code 1.; 8522)
Traceback (most recent call last):
  File "/home/airflow/.local/lib/python3.12/site-packages/airflow/task/task_runner/standard_task_runner.py", line 117, in _start_by_fork
    ret = args.func(args, dag=self.dag)
          ^^^^^^^^^^^^^^^^^^^^^^^^^^^^^
  File "/home/airflow/.local/lib/python3.12/site-packages/airflow/cli/cli_config.py", line 49, in command
    return func(*args, **kwargs)
           ^^^^^^^^^^^^^^^^^^^^^
  File "/home/airflow/.local/lib/python3.12/site-packages/airflow/utils/cli.py", line 115, in wrapper
    return f(*args, **kwargs)
           ^^^^^^^^^^^^^^^^^^
  File "/home/airflow/.local/lib/python3.12/site-packages/airflow/cli/commands/task_command.py", line 483, in task_run
    task_return_code = _run_task_by_selected_method(args, _dag, ti)
                       ^^^^^^^^^^^^^^^^^^^^^^^^^^^^^^^^^^^^^^^^^^^^
  File "/home/airflow/.local/lib/python3.12/site-packages/airflow/cli/commands/task_command.py", line 256, in _run_task_by_selected_method
    return _run_raw_task(args, ti)
           ^^^^^^^^^^^^^^^^^^^^^^^
  File "/home/airflow/.local/lib/python3.12/site-packages/airflow/cli/commands/task_command.py", line 341, in _run_raw_task
    return ti._run_raw_task(
           ^^^^^^^^^^^^^^^^^
  File "/home/airflow/.local/lib/python3.12/site-packages/airflow/utils/session.py", line 97, in wrapper
    return func(*args, session=session, **kwargs)
           ^^^^^^^^^^^^^^^^^^^^^^^^^^^^^^^^^^^^^^
  File "/home/airflow/.local/lib/python3.12/site-packages/airflow/models/taskinstance.py", line 3004, in _run_raw_task
    return _run_raw_task(
           ^^^^^^^^^^^^^^
  File "/home/airflow/.local/lib/python3.12/site-packages/airflow/models/taskinstance.py", line 273, in _run_raw_task
    TaskInstance._execute_task_with_callbacks(
  File "/home/airflow/.local/lib/python3.12/site-packages/airflow/models/taskinstance.py", line 3158, in _execute_task_with_callbacks
    result = self._execute_task(context, task_orig)
             ^^^^^^^^^^^^^^^^^^^^^^^^^^^^^^^^^^^^^^
  File "/home/airflow/.local/lib/python3.12/site-packages/airflow/models/taskinstance.py", line 3182, in _execute_task
    return _execute_task(self, context, task_orig)
           ^^^^^^^^^^^^^^^^^^^^^^^^^^^^^^^^^^^^^^^
  File "/home/airflow/.local/lib/python3.12/site-packages/airflow/models/taskinstance.py", line 767, in _execute_task
    result = _execute_callable(context=context, **execute_callable_kwargs)
             ^^^^^^^^^^^^^^^^^^^^^^^^^^^^^^^^^^^^^^^^^^^^^^^^^^^^^^^^^^^^^
  File "/home/airflow/.local/lib/python3.12/site-packages/airflow/models/taskinstance.py", line 733, in _execute_callable
    return ExecutionCallableRunner(
           ^^^^^^^^^^^^^^^^^^^^^^^^
  File "/home/airflow/.local/lib/python3.12/site-packages/airflow/utils/operator_helpers.py", line 252, in run
    return self.func(*args, **kwargs)
           ^^^^^^^^^^^^^^^^^^^^^^^^^^
  File "/home/airflow/.local/lib/python3.12/site-packages/airflow/models/baseoperator.py", line 406, in wrapper
    return func(self, *args, **kwargs)
           ^^^^^^^^^^^^^^^^^^^^^^^^^^^
  File "/home/airflow/.local/lib/python3.12/site-packages/airflow/operators/bash.py", line 249, in execute
    raise AirflowException(
airflow.exceptions.AirflowException: Bash command failed. The command returned a non-zero exit code 1.
[2025-04-24T00:50:01.496+0000] {local_task_job_runner.py:266} INFO - Task exited with return code 1
[2025-04-24T00:50:01.517+0000] {taskinstance.py:3900} INFO - 0 downstream tasks scheduled from follow-on schedule check
[2025-04-24T00:50:01.521+0000] {local_task_job_runner.py:245} INFO - ::endgroup::
