[2025-04-24T07:43:53.724+0000] {local_task_job_runner.py:123} INFO - ::group::Pre task execution logs
[2025-04-24T07:43:53.741+0000] {taskinstance.py:2612} INFO - Dependencies all met for dep_context=non-requeueable deps ti=<TaskInstance: dbt_stock_project.dbt_test manual__2025-04-24T07:43:38.803887+00:00 [queued]>
[2025-04-24T07:43:53.749+0000] {taskinstance.py:2612} INFO - Dependencies all met for dep_context=requeueable deps ti=<TaskInstance: dbt_stock_project.dbt_test manual__2025-04-24T07:43:38.803887+00:00 [queued]>
[2025-04-24T07:43:53.752+0000] {taskinstance.py:2865} INFO - Starting attempt 1 of 1
[2025-04-24T07:43:53.766+0000] {taskinstance.py:2888} INFO - Executing <Task(BashOperator): dbt_test> on 2025-04-24 07:43:38.803887+00:00
[2025-04-24T07:43:53.775+0000] {standard_task_runner.py:104} INFO - Running: ['***', 'tasks', 'run', 'dbt_stock_project', 'dbt_test', 'manual__2025-04-24T07:43:38.803887+00:00', '--job-id', '365', '--raw', '--subdir', 'DAGS_FOLDER/226_lab2_elt.py', '--cfg-path', '/tmp/tmp3nj11qve']
[2025-04-24T07:43:53.778+0000] {standard_task_runner.py:105} INFO - Job 365: Subtask dbt_test
[2025-04-24T07:43:53.778+0000] {logging_mixin.py:190} WARNING - /home/***/.local/lib/python3.12/site-packages/***/task/task_runner/standard_task_runner.py:70 DeprecationWarning: This process (pid=3092) is multi-threaded, use of fork() may lead to deadlocks in the child.
[2025-04-24T07:43:53.780+0000] {standard_task_runner.py:72} INFO - Started process 3093 to run task
[2025-04-24T07:43:53.823+0000] {task_command.py:467} INFO - Running <TaskInstance: dbt_stock_project.dbt_test manual__2025-04-24T07:43:38.803887+00:00 [running]> on host e8b5346887eb
[2025-04-24T07:43:53.911+0000] {taskinstance.py:3131} INFO - Exporting env vars: AIRFLOW_CTX_DAG_OWNER='***' AIRFLOW_CTX_DAG_ID='dbt_stock_project' AIRFLOW_CTX_TASK_ID='dbt_test' AIRFLOW_CTX_EXECUTION_DATE='2025-04-24T07:43:38.803887+00:00' AIRFLOW_CTX_TRY_NUMBER='1' AIRFLOW_CTX_DAG_RUN_ID='manual__2025-04-24T07:43:38.803887+00:00'
[2025-04-24T07:43:53.913+0000] {taskinstance.py:731} INFO - ::endgroup::
[2025-04-24T07:43:53.929+0000] {subprocess.py:63} INFO - Tmp dir root location: /tmp
[2025-04-24T07:43:53.932+0000] {subprocess.py:75} INFO - Running command: ['/usr/bin/bash', '-c', '/home/***/.local/bin/dbt test --profiles-dir /home/***/.dbt --project-dir /opt/***/dbt']
[2025-04-24T07:43:53.941+0000] {subprocess.py:86} INFO - Output:
[2025-04-24T07:43:55.967+0000] {subprocess.py:93} INFO - [0m07:43:55  Running with dbt=1.8.7
[2025-04-24T07:43:56.959+0000] {subprocess.py:93} INFO - [0m07:43:56  Registered adapter: snowflake=1.8.1
[2025-04-24T07:43:57.814+0000] {subprocess.py:93} INFO - [0m07:43:57  Found 7 models, 12 data tests, 3 sources, 459 macros
[2025-04-24T07:43:57.819+0000] {subprocess.py:93} INFO - [0m07:43:57
[2025-04-24T07:43:58.738+0000] {subprocess.py:93} INFO - [0m07:43:58  Concurrency: 1 threads (target='dev')
[2025-04-24T07:43:58.739+0000] {subprocess.py:93} INFO - [0m07:43:58
[2025-04-24T07:43:58.753+0000] {subprocess.py:93} INFO - [0m07:43:58  1 of 12 START test not_null_moving_averages_stock_id ........................... [RUN]
[2025-04-24T07:43:59.728+0000] {subprocess.py:93} INFO - [0m07:43:59  1 of 12 PASS not_null_moving_averages_stock_id ................................. [[32mPASS[0m in 0.97s]
[2025-04-24T07:43:59.733+0000] {subprocess.py:93} INFO - [0m07:43:59  2 of 12 START test not_null_rsi_stock_id ....................................... [RUN]
[2025-04-24T07:44:00.511+0000] {subprocess.py:93} INFO - [0m07:44:00  2 of 12 PASS not_null_rsi_stock_id ............................................. [[32mPASS[0m in 0.78s]
[2025-04-24T07:44:00.514+0000] {subprocess.py:93} INFO - [0m07:44:00  3 of 12 START test not_null_stock_stock_id ..................................... [RUN]
[2025-04-24T07:44:01.183+0000] {subprocess.py:93} INFO - [0m07:44:01  3 of 12 PASS not_null_stock_stock_id ........................................... [[32mPASS[0m in 0.67s]
[2025-04-24T07:44:01.187+0000] {subprocess.py:93} INFO - [0m07:44:01  4 of 12 START test not_null_stock_symbol ....................................... [RUN]
[2025-04-24T07:44:01.847+0000] {subprocess.py:93} INFO - [0m07:44:01  4 of 12 PASS not_null_stock_symbol ............................................. [[32mPASS[0m in 0.66s]
[2025-04-24T07:44:01.850+0000] {subprocess.py:93} INFO - [0m07:44:01  5 of 12 START test not_null_stock_trade_date ................................... [RUN]
[2025-04-24T07:44:02.543+0000] {subprocess.py:93} INFO - [0m07:44:02  5 of 12 PASS not_null_stock_trade_date ......................................... [[32mPASS[0m in 0.69s]
[2025-04-24T07:44:02.547+0000] {subprocess.py:93} INFO - [0m07:44:02  6 of 12 START test relationships_moving_averages_stock_id__stock_id__ref_stock_  [RUN]
[2025-04-24T07:44:03.580+0000] {subprocess.py:93} INFO - [0m07:44:03  6 of 12 PASS relationships_moving_averages_stock_id__stock_id__ref_stock_ ...... [[32mPASS[0m in 1.03s]
[2025-04-24T07:44:03.583+0000] {subprocess.py:93} INFO - [0m07:44:03  7 of 12 START test relationships_rsi_stock_id__stock_id__ref_stock_ ............ [RUN]
[2025-04-24T07:44:04.513+0000] {subprocess.py:93} INFO - [0m07:44:04  7 of 12 PASS relationships_rsi_stock_id__stock_id__ref_stock_ .................. [[32mPASS[0m in 0.93s]
[2025-04-24T07:44:04.517+0000] {subprocess.py:93} INFO - [0m07:44:04  8 of 12 START test rsi_test .................................................... [RUN]
[2025-04-24T07:44:05.192+0000] {subprocess.py:93} INFO - [0m07:44:05  8 of 12 FAIL 18 rsi_test ....................................................... [[31mFAIL 18[0m in 0.67s]
[2025-04-24T07:44:05.195+0000] {subprocess.py:93} INFO - [0m07:44:05  9 of 12 START test rsi_test .................................................... [RUN]
[2025-04-24T07:44:05.205+0000] {subprocess.py:93} INFO - [0m07:44:05  9 of 12 ERROR rsi_test ......................................................... [[31mERROR[0m in 0.01s]
[2025-04-24T07:44:05.209+0000] {subprocess.py:93} INFO - [0m07:44:05  10 of 12 START test unique_moving_averages_stock_id ............................ [RUN]
[2025-04-24T07:44:05.997+0000] {subprocess.py:93} INFO - [0m07:44:05  10 of 12 PASS unique_moving_averages_stock_id .................................. [[32mPASS[0m in 0.79s]
[2025-04-24T07:44:06.002+0000] {subprocess.py:93} INFO - [0m07:44:06  11 of 12 START test unique_rsi_stock_id ........................................ [RUN]
[2025-04-24T07:44:06.753+0000] {subprocess.py:93} INFO - [0m07:44:06  11 of 12 PASS unique_rsi_stock_id .............................................. [[32mPASS[0m in 0.75s]
[2025-04-24T07:44:06.756+0000] {subprocess.py:93} INFO - [0m07:44:06  12 of 12 START test unique_stock_stock_id ...................................... [RUN]
[2025-04-24T07:44:07.409+0000] {subprocess.py:93} INFO - [0m07:44:07  12 of 12 PASS unique_stock_stock_id ............................................ [[32mPASS[0m in 0.65s]
[2025-04-24T07:44:07.415+0000] {subprocess.py:93} INFO - [0m07:44:07
[2025-04-24T07:44:07.416+0000] {subprocess.py:93} INFO - [0m07:44:07  Finished running 12 data tests in 0 hours 0 minutes and 9.60 seconds (9.60s).
[2025-04-24T07:44:07.535+0000] {subprocess.py:93} INFO - [0m07:44:07
[2025-04-24T07:44:07.537+0000] {subprocess.py:93} INFO - [0m07:44:07  [31mCompleted with 2 errors and 0 warnings:[0m
[2025-04-24T07:44:07.538+0000] {subprocess.py:93} INFO - [0m07:44:07
[2025-04-24T07:44:07.539+0000] {subprocess.py:93} INFO - [0m07:44:07  [31mFailure in test rsi_test (tests/rsi_test.sql)[0m
[2025-04-24T07:44:07.540+0000] {subprocess.py:93} INFO - [0m07:44:07    Got 18 results, configured to fail if != 0
[2025-04-24T07:44:07.541+0000] {subprocess.py:93} INFO - [0m07:44:07
[2025-04-24T07:44:07.542+0000] {subprocess.py:93} INFO - [0m07:44:07    compiled code at target/compiled/dbt_stock_project/tests/rsi_test.sql
[2025-04-24T07:44:07.543+0000] {subprocess.py:93} INFO - [0m07:44:07
[2025-04-24T07:44:07.544+0000] {subprocess.py:93} INFO - [0m07:44:07    Compilation Error in test rsi_test (models/output/schema.yml)
[2025-04-24T07:44:07.545+0000] {subprocess.py:93} INFO -   'test_custom' is undefined. This can happen when calling a macro that does not exist. Check for typos and/or install package dependencies with "dbt deps".
[2025-04-24T07:44:07.546+0000] {subprocess.py:93} INFO - [0m07:44:07
[2025-04-24T07:44:07.546+0000] {subprocess.py:93} INFO - [0m07:44:07  Done. PASS=10 WARN=0 ERROR=2 SKIP=0 TOTAL=12
[2025-04-24T07:44:08.321+0000] {subprocess.py:97} INFO - Command exited with return code 1
[2025-04-24T07:44:08.332+0000] {taskinstance.py:3310} ERROR - Task failed with exception
Traceback (most recent call last):
  File "/home/airflow/.local/lib/python3.12/site-packages/airflow/models/taskinstance.py", line 767, in _execute_task
    result = _execute_callable(context=context, **execute_callable_kwargs)
             ^^^^^^^^^^^^^^^^^^^^^^^^^^^^^^^^^^^^^^^^^^^^^^^^^^^^^^^^^^^^^
  File "/home/airflow/.local/lib/python3.12/site-packages/airflow/models/taskinstance.py", line 733, in _execute_callable
    return ExecutionCallableRunner(
           ^^^^^^^^^^^^^^^^^^^^^^^^
  File "/home/airflow/.local/lib/python3.12/site-packages/airflow/utils/operator_helpers.py", line 252, in run
    return self.func(*args, **kwargs)
           ^^^^^^^^^^^^^^^^^^^^^^^^^^
  File "/home/airflow/.local/lib/python3.12/site-packages/airflow/models/baseoperator.py", line 406, in wrapper
    return func(self, *args, **kwargs)
           ^^^^^^^^^^^^^^^^^^^^^^^^^^^
  File "/home/airflow/.local/lib/python3.12/site-packages/airflow/operators/bash.py", line 249, in execute
    raise AirflowException(
airflow.exceptions.AirflowException: Bash command failed. The command returned a non-zero exit code 1.
[2025-04-24T07:44:08.336+0000] {taskinstance.py:1225} INFO - Marking task as FAILED. dag_id=dbt_stock_project, task_id=dbt_test, run_id=manual__2025-04-24T07:43:38.803887+00:00, execution_date=20250424T074338, start_date=20250424T074353, end_date=20250424T074408
[2025-04-24T07:44:08.351+0000] {taskinstance.py:340} INFO - ::group::Post task execution logs
[2025-04-24T07:44:08.352+0000] {standard_task_runner.py:124} ERROR - Failed to execute job 365 for task dbt_test (Bash command failed. The command returned a non-zero exit code 1.; 3093)
Traceback (most recent call last):
  File "/home/airflow/.local/lib/python3.12/site-packages/airflow/task/task_runner/standard_task_runner.py", line 117, in _start_by_fork
    ret = args.func(args, dag=self.dag)
          ^^^^^^^^^^^^^^^^^^^^^^^^^^^^^
  File "/home/airflow/.local/lib/python3.12/site-packages/airflow/cli/cli_config.py", line 49, in command
    return func(*args, **kwargs)
           ^^^^^^^^^^^^^^^^^^^^^
  File "/home/airflow/.local/lib/python3.12/site-packages/airflow/utils/cli.py", line 115, in wrapper
    return f(*args, **kwargs)
           ^^^^^^^^^^^^^^^^^^
  File "/home/airflow/.local/lib/python3.12/site-packages/airflow/cli/commands/task_command.py", line 483, in task_run
    task_return_code = _run_task_by_selected_method(args, _dag, ti)
                       ^^^^^^^^^^^^^^^^^^^^^^^^^^^^^^^^^^^^^^^^^^^^
  File "/home/airflow/.local/lib/python3.12/site-packages/airflow/cli/commands/task_command.py", line 256, in _run_task_by_selected_method
    return _run_raw_task(args, ti)
           ^^^^^^^^^^^^^^^^^^^^^^^
  File "/home/airflow/.local/lib/python3.12/site-packages/airflow/cli/commands/task_command.py", line 341, in _run_raw_task
    return ti._run_raw_task(
           ^^^^^^^^^^^^^^^^^
  File "/home/airflow/.local/lib/python3.12/site-packages/airflow/utils/session.py", line 97, in wrapper
    return func(*args, session=session, **kwargs)
           ^^^^^^^^^^^^^^^^^^^^^^^^^^^^^^^^^^^^^^
  File "/home/airflow/.local/lib/python3.12/site-packages/airflow/models/taskinstance.py", line 3004, in _run_raw_task
    return _run_raw_task(
           ^^^^^^^^^^^^^^
  File "/home/airflow/.local/lib/python3.12/site-packages/airflow/models/taskinstance.py", line 273, in _run_raw_task
    TaskInstance._execute_task_with_callbacks(
  File "/home/airflow/.local/lib/python3.12/site-packages/airflow/models/taskinstance.py", line 3158, in _execute_task_with_callbacks
    result = self._execute_task(context, task_orig)
             ^^^^^^^^^^^^^^^^^^^^^^^^^^^^^^^^^^^^^^
  File "/home/airflow/.local/lib/python3.12/site-packages/airflow/models/taskinstance.py", line 3182, in _execute_task
    return _execute_task(self, context, task_orig)
           ^^^^^^^^^^^^^^^^^^^^^^^^^^^^^^^^^^^^^^^
  File "/home/airflow/.local/lib/python3.12/site-packages/airflow/models/taskinstance.py", line 767, in _execute_task
    result = _execute_callable(context=context, **execute_callable_kwargs)
             ^^^^^^^^^^^^^^^^^^^^^^^^^^^^^^^^^^^^^^^^^^^^^^^^^^^^^^^^^^^^^
  File "/home/airflow/.local/lib/python3.12/site-packages/airflow/models/taskinstance.py", line 733, in _execute_callable
    return ExecutionCallableRunner(
           ^^^^^^^^^^^^^^^^^^^^^^^^
  File "/home/airflow/.local/lib/python3.12/site-packages/airflow/utils/operator_helpers.py", line 252, in run
    return self.func(*args, **kwargs)
           ^^^^^^^^^^^^^^^^^^^^^^^^^^
  File "/home/airflow/.local/lib/python3.12/site-packages/airflow/models/baseoperator.py", line 406, in wrapper
    return func(self, *args, **kwargs)
           ^^^^^^^^^^^^^^^^^^^^^^^^^^^
  File "/home/airflow/.local/lib/python3.12/site-packages/airflow/operators/bash.py", line 249, in execute
    raise AirflowException(
airflow.exceptions.AirflowException: Bash command failed. The command returned a non-zero exit code 1.
[2025-04-24T07:44:08.396+0000] {local_task_job_runner.py:266} INFO - Task exited with return code 1
[2025-04-24T07:44:08.415+0000] {taskinstance.py:3900} INFO - 0 downstream tasks scheduled from follow-on schedule check
[2025-04-24T07:44:08.421+0000] {local_task_job_runner.py:245} INFO - ::endgroup::
