[2025-04-24T00:54:29.643+0000] {local_task_job_runner.py:123} INFO - ::group::Pre task execution logs
[2025-04-24T00:54:29.664+0000] {taskinstance.py:2612} INFO - Dependencies all met for dep_context=non-requeueable deps ti=<TaskInstance: dbt_stock_project.dbt_test manual__2025-04-24T00:54:15.022941+00:00 [queued]>
[2025-04-24T00:54:29.676+0000] {taskinstance.py:2612} INFO - Dependencies all met for dep_context=requeueable deps ti=<TaskInstance: dbt_stock_project.dbt_test manual__2025-04-24T00:54:15.022941+00:00 [queued]>
[2025-04-24T00:54:29.678+0000] {taskinstance.py:2865} INFO - Starting attempt 1 of 1
[2025-04-24T00:54:29.695+0000] {taskinstance.py:2888} INFO - Executing <Task(BashOperator): dbt_test> on 2025-04-24 00:54:15.022941+00:00
[2025-04-24T00:54:29.705+0000] {logging_mixin.py:190} WARNING - /home/***/.local/lib/python3.12/site-packages/***/task/task_runner/standard_task_runner.py:70 DeprecationWarning: This process (pid=8940) is multi-threaded, use of fork() may lead to deadlocks in the child.
[2025-04-24T00:54:29.703+0000] {standard_task_runner.py:104} INFO - Running: ['***', 'tasks', 'run', 'dbt_stock_project', 'dbt_test', 'manual__2025-04-24T00:54:15.022941+00:00', '--job-id', '348', '--raw', '--subdir', 'DAGS_FOLDER/226_lab2_elt.py', '--cfg-path', '/tmp/tmpgwu6060j']
[2025-04-24T00:54:29.706+0000] {standard_task_runner.py:72} INFO - Started process 8941 to run task
[2025-04-24T00:54:29.707+0000] {standard_task_runner.py:105} INFO - Job 348: Subtask dbt_test
[2025-04-24T00:54:29.762+0000] {task_command.py:467} INFO - Running <TaskInstance: dbt_stock_project.dbt_test manual__2025-04-24T00:54:15.022941+00:00 [running]> on host d01273b1fd04
[2025-04-24T00:54:29.875+0000] {taskinstance.py:3131} INFO - Exporting env vars: AIRFLOW_CTX_DAG_OWNER='***' AIRFLOW_CTX_DAG_ID='dbt_stock_project' AIRFLOW_CTX_TASK_ID='dbt_test' AIRFLOW_CTX_EXECUTION_DATE='2025-04-24T00:54:15.022941+00:00' AIRFLOW_CTX_TRY_NUMBER='1' AIRFLOW_CTX_DAG_RUN_ID='manual__2025-04-24T00:54:15.022941+00:00'
[2025-04-24T00:54:29.877+0000] {taskinstance.py:731} INFO - ::endgroup::
[2025-04-24T00:54:29.897+0000] {subprocess.py:63} INFO - Tmp dir root location: /tmp
[2025-04-24T00:54:29.899+0000] {subprocess.py:75} INFO - Running command: ['/usr/bin/bash', '-c', '/home/***/.local/bin/dbt test --profiles-dir /home/***/.dbt --project-dir /opt/***/dbt']
[2025-04-24T00:54:29.910+0000] {subprocess.py:86} INFO - Output:
[2025-04-24T00:54:32.053+0000] {subprocess.py:93} INFO - [0m00:54:32  Running with dbt=1.8.7
[2025-04-24T00:54:33.094+0000] {subprocess.py:93} INFO - [0m00:54:33  Registered adapter: snowflake=1.8.1
[2025-04-24T00:54:34.094+0000] {subprocess.py:93} INFO - [0m00:54:34  Found 6 models, 18 data tests, 3 sources, 459 macros
[2025-04-24T00:54:34.098+0000] {subprocess.py:93} INFO - [0m00:54:34
[2025-04-24T00:54:34.711+0000] {subprocess.py:93} INFO - [0m00:54:34  Concurrency: 1 threads (target='dev')
[2025-04-24T00:54:34.712+0000] {subprocess.py:93} INFO - [0m00:54:34
[2025-04-24T00:54:34.724+0000] {subprocess.py:93} INFO - [0m00:54:34  1 of 18 START test not_null_moving_averages_close_price_14d_ma ................. [RUN]
[2025-04-24T00:54:35.372+0000] {subprocess.py:93} INFO - [0m00:54:35  1 of 18 PASS not_null_moving_averages_close_price_14d_ma ....................... [[32mPASS[0m in 0.65s]
[2025-04-24T00:54:35.376+0000] {subprocess.py:93} INFO - [0m00:54:35  2 of 18 START test not_null_moving_averages_close_price_30d_ma ................. [RUN]
[2025-04-24T00:54:36.095+0000] {subprocess.py:93} INFO - [0m00:54:36  2 of 18 PASS not_null_moving_averages_close_price_30d_ma ....................... [[32mPASS[0m in 0.72s]
[2025-04-24T00:54:36.100+0000] {subprocess.py:93} INFO - [0m00:54:36  3 of 18 START test not_null_moving_averages_close_price_7d_ma .................. [RUN]
[2025-04-24T00:54:36.661+0000] {subprocess.py:93} INFO - [0m00:54:36  3 of 18 PASS not_null_moving_averages_close_price_7d_ma ........................ [[32mPASS[0m in 0.56s]
[2025-04-24T00:54:36.664+0000] {subprocess.py:93} INFO - [0m00:54:36  4 of 18 START test not_null_moving_averages_symbol ............................. [RUN]
[2025-04-24T00:54:37.125+0000] {subprocess.py:93} INFO - [0m00:54:37  4 of 18 PASS not_null_moving_averages_symbol ................................... [[32mPASS[0m in 0.46s]
[2025-04-24T00:54:37.130+0000] {subprocess.py:93} INFO - [0m00:54:37  5 of 18 START test not_null_moving_averages_trade_date ......................... [RUN]
[2025-04-24T00:54:37.763+0000] {subprocess.py:93} INFO - [0m00:54:37  5 of 18 PASS not_null_moving_averages_trade_date ............................... [[32mPASS[0m in 0.63s]
[2025-04-24T00:54:37.767+0000] {subprocess.py:93} INFO - [0m00:54:37  6 of 18 START test not_null_rsi_rsi_14d ........................................ [RUN]
[2025-04-24T00:54:38.322+0000] {subprocess.py:93} INFO - [0m00:54:38  6 of 18 PASS not_null_rsi_rsi_14d .............................................. [[32mPASS[0m in 0.55s]
[2025-04-24T00:54:38.328+0000] {subprocess.py:93} INFO - [0m00:54:38  7 of 18 START test not_null_rsi_symbol ......................................... [RUN]
[2025-04-24T00:54:38.911+0000] {subprocess.py:93} INFO - [0m00:54:38  7 of 18 PASS not_null_rsi_symbol ............................................... [[32mPASS[0m in 0.58s]
[2025-04-24T00:54:38.915+0000] {subprocess.py:93} INFO - [0m00:54:38  8 of 18 START test not_null_rsi_trade_date ..................................... [RUN]
[2025-04-24T00:54:39.412+0000] {subprocess.py:93} INFO - [0m00:54:39  8 of 18 PASS not_null_rsi_trade_date ........................................... [[32mPASS[0m in 0.50s]
[2025-04-24T00:54:39.417+0000] {subprocess.py:93} INFO - [0m00:54:39  9 of 18 START test not_null_stock_indicators_rsi_14d ........................... [RUN]
[2025-04-24T00:54:39.959+0000] {subprocess.py:93} INFO - [0m00:54:39  9 of 18 ERROR not_null_stock_indicators_rsi_14d ................................ [[31mERROR[0m in 0.54s]
[2025-04-24T00:54:39.963+0000] {subprocess.py:93} INFO - [0m00:54:39  10 of 18 START test not_null_stock_indicators_symbol ........................... [RUN]
[2025-04-24T00:54:40.537+0000] {subprocess.py:93} INFO - [0m00:54:40  10 of 18 PASS not_null_stock_indicators_symbol ................................. [[32mPASS[0m in 0.57s]
[2025-04-24T00:54:40.540+0000] {subprocess.py:93} INFO - [0m00:54:40  11 of 18 START test not_null_stock_indicators_trade_date ....................... [RUN]
[2025-04-24T00:54:41.206+0000] {subprocess.py:93} INFO - [0m00:54:41  11 of 18 PASS not_null_stock_indicators_trade_date ............................. [[32mPASS[0m in 0.66s]
[2025-04-24T00:54:41.209+0000] {subprocess.py:93} INFO - [0m00:54:41  12 of 18 START test not_null_volume_summary_symbol ............................. [RUN]
[2025-04-24T00:54:41.737+0000] {subprocess.py:93} INFO - [0m00:54:41  12 of 18 PASS not_null_volume_summary_symbol ................................... [[32mPASS[0m in 0.53s]
[2025-04-24T00:54:41.740+0000] {subprocess.py:93} INFO - [0m00:54:41  13 of 18 START test not_null_volume_summary_total_volume ....................... [RUN]
[2025-04-24T00:54:42.194+0000] {subprocess.py:93} INFO - [0m00:54:42  13 of 18 ERROR not_null_volume_summary_total_volume ............................ [[31mERROR[0m in 0.45s]
[2025-04-24T00:54:42.196+0000] {subprocess.py:93} INFO - [0m00:54:42  14 of 18 START test not_null_volume_summary_trade_date ......................... [RUN]
[2025-04-24T00:54:42.726+0000] {subprocess.py:93} INFO - [0m00:54:42  14 of 18 PASS not_null_volume_summary_trade_date ............................... [[32mPASS[0m in 0.53s]
[2025-04-24T00:54:42.731+0000] {subprocess.py:93} INFO - [0m00:54:42  15 of 18 START test range_rsi_rsi_14d__100__0 .................................. [RUN]
[2025-04-24T00:54:42.756+0000] {subprocess.py:93} INFO - [0m00:54:42  15 of 18 ERROR range_rsi_rsi_14d__100__0 ....................................... [[31mERROR[0m in 0.02s]
[2025-04-24T00:54:42.762+0000] {subprocess.py:93} INFO - [0m00:54:42  16 of 18 START test relationships_moving_averages_symbol__symbol__source_raw_stock_  [RUN]
[2025-04-24T00:54:43.481+0000] {subprocess.py:93} INFO - [0m00:54:43  16 of 18 PASS relationships_moving_averages_symbol__symbol__source_raw_stock_ .. [[32mPASS[0m in 0.72s]
[2025-04-24T00:54:43.485+0000] {subprocess.py:93} INFO - [0m00:54:43  17 of 18 START test relationships_rsi_symbol__symbol__source_raw_stock_ ........ [RUN]
[2025-04-24T00:54:44.004+0000] {subprocess.py:93} INFO - [0m00:54:44  17 of 18 PASS relationships_rsi_symbol__symbol__source_raw_stock_ .............. [[32mPASS[0m in 0.52s]
[2025-04-24T00:54:44.007+0000] {subprocess.py:93} INFO - [0m00:54:44  18 of 18 START test relationships_stock_indicators_symbol__symbol__source_raw_stock_  [RUN]
[2025-04-24T00:54:44.760+0000] {subprocess.py:93} INFO - [0m00:54:44  18 of 18 PASS relationships_stock_indicators_symbol__symbol__source_raw_stock_ . [[32mPASS[0m in 0.75s]
[2025-04-24T00:54:44.765+0000] {subprocess.py:93} INFO - [0m00:54:44
[2025-04-24T00:54:44.766+0000] {subprocess.py:93} INFO - [0m00:54:44  Finished running 18 data tests in 0 hours 0 minutes and 10.67 seconds (10.67s).
[2025-04-24T00:54:44.879+0000] {subprocess.py:93} INFO - [0m00:54:44
[2025-04-24T00:54:44.881+0000] {subprocess.py:93} INFO - [0m00:54:44  [31mCompleted with 3 errors and 0 warnings:[0m
[2025-04-24T00:54:44.881+0000] {subprocess.py:93} INFO - [0m00:54:44
[2025-04-24T00:54:44.883+0000] {subprocess.py:93} INFO - [0m00:54:44    Database Error in test not_null_stock_indicators_rsi_14d (models/output/schema.yml)
[2025-04-24T00:54:44.883+0000] {subprocess.py:93} INFO -   000904 (42000): SQL compilation error: error line 12 at position 7
[2025-04-24T00:54:44.884+0000] {subprocess.py:93} INFO -   invalid identifier 'RSI_14D'
[2025-04-24T00:54:44.885+0000] {subprocess.py:93} INFO -   compiled code at target/run/dbt_stock_project/models/output/schema.yml/not_null_stock_indicators_rsi_14d.sql
[2025-04-24T00:54:44.886+0000] {subprocess.py:93} INFO - [0m00:54:44
[2025-04-24T00:54:44.886+0000] {subprocess.py:93} INFO - [0m00:54:44    Database Error in test not_null_volume_summary_total_volume (models/output/schema.yml)
[2025-04-24T00:54:44.887+0000] {subprocess.py:93} INFO -   000904 (42000): SQL compilation error: error line 12 at position 7
[2025-04-24T00:54:44.888+0000] {subprocess.py:93} INFO -   invalid identifier 'TOTAL_VOLUME'
[2025-04-24T00:54:44.888+0000] {subprocess.py:93} INFO -   compiled code at target/run/dbt_stock_project/models/output/schema.yml/not_null_volume_summary_total_volume.sql
[2025-04-24T00:54:44.889+0000] {subprocess.py:93} INFO - [0m00:54:44
[2025-04-24T00:54:44.890+0000] {subprocess.py:93} INFO - [0m00:54:44    Compilation Error in test range_rsi_rsi_14d__100__0 (models/output/schema.yml)
[2025-04-24T00:54:44.890+0000] {subprocess.py:93} INFO -   'test_range' is undefined. This can happen when calling a macro that does not exist. Check for typos and/or install package dependencies with "dbt deps".
[2025-04-24T00:54:44.891+0000] {subprocess.py:93} INFO - [0m00:54:44
[2025-04-24T00:54:44.891+0000] {subprocess.py:93} INFO - [0m00:54:44  Done. PASS=15 WARN=0 ERROR=3 SKIP=0 TOTAL=18
[2025-04-24T00:54:45.663+0000] {subprocess.py:97} INFO - Command exited with return code 1
[2025-04-24T00:54:45.674+0000] {taskinstance.py:3310} ERROR - Task failed with exception
Traceback (most recent call last):
  File "/home/airflow/.local/lib/python3.12/site-packages/airflow/models/taskinstance.py", line 767, in _execute_task
    result = _execute_callable(context=context, **execute_callable_kwargs)
             ^^^^^^^^^^^^^^^^^^^^^^^^^^^^^^^^^^^^^^^^^^^^^^^^^^^^^^^^^^^^^
  File "/home/airflow/.local/lib/python3.12/site-packages/airflow/models/taskinstance.py", line 733, in _execute_callable
    return ExecutionCallableRunner(
           ^^^^^^^^^^^^^^^^^^^^^^^^
  File "/home/airflow/.local/lib/python3.12/site-packages/airflow/utils/operator_helpers.py", line 252, in run
    return self.func(*args, **kwargs)
           ^^^^^^^^^^^^^^^^^^^^^^^^^^
  File "/home/airflow/.local/lib/python3.12/site-packages/airflow/models/baseoperator.py", line 406, in wrapper
    return func(self, *args, **kwargs)
           ^^^^^^^^^^^^^^^^^^^^^^^^^^^
  File "/home/airflow/.local/lib/python3.12/site-packages/airflow/operators/bash.py", line 249, in execute
    raise AirflowException(
airflow.exceptions.AirflowException: Bash command failed. The command returned a non-zero exit code 1.
[2025-04-24T00:54:45.678+0000] {taskinstance.py:1225} INFO - Marking task as FAILED. dag_id=dbt_stock_project, task_id=dbt_test, run_id=manual__2025-04-24T00:54:15.022941+00:00, execution_date=20250424T005415, start_date=20250424T005429, end_date=20250424T005445
[2025-04-24T00:54:45.693+0000] {taskinstance.py:340} INFO - ::group::Post task execution logs
[2025-04-24T00:54:45.694+0000] {standard_task_runner.py:124} ERROR - Failed to execute job 348 for task dbt_test (Bash command failed. The command returned a non-zero exit code 1.; 8941)
Traceback (most recent call last):
  File "/home/airflow/.local/lib/python3.12/site-packages/airflow/task/task_runner/standard_task_runner.py", line 117, in _start_by_fork
    ret = args.func(args, dag=self.dag)
          ^^^^^^^^^^^^^^^^^^^^^^^^^^^^^
  File "/home/airflow/.local/lib/python3.12/site-packages/airflow/cli/cli_config.py", line 49, in command
    return func(*args, **kwargs)
           ^^^^^^^^^^^^^^^^^^^^^
  File "/home/airflow/.local/lib/python3.12/site-packages/airflow/utils/cli.py", line 115, in wrapper
    return f(*args, **kwargs)
           ^^^^^^^^^^^^^^^^^^
  File "/home/airflow/.local/lib/python3.12/site-packages/airflow/cli/commands/task_command.py", line 483, in task_run
    task_return_code = _run_task_by_selected_method(args, _dag, ti)
                       ^^^^^^^^^^^^^^^^^^^^^^^^^^^^^^^^^^^^^^^^^^^^
  File "/home/airflow/.local/lib/python3.12/site-packages/airflow/cli/commands/task_command.py", line 256, in _run_task_by_selected_method
    return _run_raw_task(args, ti)
           ^^^^^^^^^^^^^^^^^^^^^^^
  File "/home/airflow/.local/lib/python3.12/site-packages/airflow/cli/commands/task_command.py", line 341, in _run_raw_task
    return ti._run_raw_task(
           ^^^^^^^^^^^^^^^^^
  File "/home/airflow/.local/lib/python3.12/site-packages/airflow/utils/session.py", line 97, in wrapper
    return func(*args, session=session, **kwargs)
           ^^^^^^^^^^^^^^^^^^^^^^^^^^^^^^^^^^^^^^
  File "/home/airflow/.local/lib/python3.12/site-packages/airflow/models/taskinstance.py", line 3004, in _run_raw_task
    return _run_raw_task(
           ^^^^^^^^^^^^^^
  File "/home/airflow/.local/lib/python3.12/site-packages/airflow/models/taskinstance.py", line 273, in _run_raw_task
    TaskInstance._execute_task_with_callbacks(
  File "/home/airflow/.local/lib/python3.12/site-packages/airflow/models/taskinstance.py", line 3158, in _execute_task_with_callbacks
    result = self._execute_task(context, task_orig)
             ^^^^^^^^^^^^^^^^^^^^^^^^^^^^^^^^^^^^^^
  File "/home/airflow/.local/lib/python3.12/site-packages/airflow/models/taskinstance.py", line 3182, in _execute_task
    return _execute_task(self, context, task_orig)
           ^^^^^^^^^^^^^^^^^^^^^^^^^^^^^^^^^^^^^^^
  File "/home/airflow/.local/lib/python3.12/site-packages/airflow/models/taskinstance.py", line 767, in _execute_task
    result = _execute_callable(context=context, **execute_callable_kwargs)
             ^^^^^^^^^^^^^^^^^^^^^^^^^^^^^^^^^^^^^^^^^^^^^^^^^^^^^^^^^^^^^
  File "/home/airflow/.local/lib/python3.12/site-packages/airflow/models/taskinstance.py", line 733, in _execute_callable
    return ExecutionCallableRunner(
           ^^^^^^^^^^^^^^^^^^^^^^^^
  File "/home/airflow/.local/lib/python3.12/site-packages/airflow/utils/operator_helpers.py", line 252, in run
    return self.func(*args, **kwargs)
           ^^^^^^^^^^^^^^^^^^^^^^^^^^
  File "/home/airflow/.local/lib/python3.12/site-packages/airflow/models/baseoperator.py", line 406, in wrapper
    return func(self, *args, **kwargs)
           ^^^^^^^^^^^^^^^^^^^^^^^^^^^
  File "/home/airflow/.local/lib/python3.12/site-packages/airflow/operators/bash.py", line 249, in execute
    raise AirflowException(
airflow.exceptions.AirflowException: Bash command failed. The command returned a non-zero exit code 1.
[2025-04-24T00:54:45.728+0000] {local_task_job_runner.py:266} INFO - Task exited with return code 1
[2025-04-24T00:54:45.763+0000] {taskinstance.py:3900} INFO - 0 downstream tasks scheduled from follow-on schedule check
[2025-04-24T00:54:45.770+0000] {local_task_job_runner.py:245} INFO - ::endgroup::
