[2025-04-24T00:23:13.977+0000] {local_task_job_runner.py:123} INFO - ::group::Pre task execution logs
[2025-04-24T00:23:13.994+0000] {taskinstance.py:2612} INFO - Dependencies all met for dep_context=non-requeueable deps ti=<TaskInstance: dbt_stock_project.dbt_run manual__2025-04-24T00:23:13.065590+00:00 [queued]>
[2025-04-24T00:23:14.002+0000] {taskinstance.py:2612} INFO - Dependencies all met for dep_context=requeueable deps ti=<TaskInstance: dbt_stock_project.dbt_run manual__2025-04-24T00:23:13.065590+00:00 [queued]>
[2025-04-24T00:23:14.004+0000] {taskinstance.py:2865} INFO - Starting attempt 1 of 1
[2025-04-24T00:23:14.019+0000] {taskinstance.py:2888} INFO - Executing <Task(BashOperator): dbt_run> on 2025-04-24 00:23:13.065590+00:00
[2025-04-24T00:23:14.028+0000] {logging_mixin.py:190} WARNING - /home/***/.local/lib/python3.12/site-packages/***/task/task_runner/standard_task_runner.py:70 DeprecationWarning: This process (pid=7055) is multi-threaded, use of fork() may lead to deadlocks in the child.
[2025-04-24T00:23:14.026+0000] {standard_task_runner.py:104} INFO - Running: ['***', 'tasks', 'run', 'dbt_stock_project', 'dbt_run', 'manual__2025-04-24T00:23:13.065590+00:00', '--job-id', '332', '--raw', '--subdir', 'DAGS_FOLDER/226_lab2_elt.py', '--cfg-path', '/tmp/tmpk2wr262f']
[2025-04-24T00:23:14.029+0000] {standard_task_runner.py:72} INFO - Started process 7056 to run task
[2025-04-24T00:23:14.030+0000] {standard_task_runner.py:105} INFO - Job 332: Subtask dbt_run
[2025-04-24T00:23:14.084+0000] {task_command.py:467} INFO - Running <TaskInstance: dbt_stock_project.dbt_run manual__2025-04-24T00:23:13.065590+00:00 [running]> on host d01273b1fd04
[2025-04-24T00:23:14.165+0000] {taskinstance.py:3131} INFO - Exporting env vars: AIRFLOW_CTX_DAG_OWNER='***' AIRFLOW_CTX_DAG_ID='dbt_stock_project' AIRFLOW_CTX_TASK_ID='dbt_run' AIRFLOW_CTX_EXECUTION_DATE='2025-04-24T00:23:13.065590+00:00' AIRFLOW_CTX_TRY_NUMBER='1' AIRFLOW_CTX_DAG_RUN_ID='manual__2025-04-24T00:23:13.065590+00:00'
[2025-04-24T00:23:14.167+0000] {taskinstance.py:731} INFO - ::endgroup::
[2025-04-24T00:23:14.182+0000] {subprocess.py:63} INFO - Tmp dir root location: /tmp
[2025-04-24T00:23:14.185+0000] {subprocess.py:75} INFO - Running command: ['/usr/bin/bash', '-c', '/home/***/.local/bin/dbt run --profiles-dir /home/***/.dbt --project-dir /opt/***/dbt']
[2025-04-24T00:23:14.193+0000] {subprocess.py:86} INFO - Output:
[2025-04-24T00:23:16.035+0000] {subprocess.py:93} INFO - [0m00:23:16  Running with dbt=1.8.7
[2025-04-24T00:23:16.961+0000] {subprocess.py:93} INFO - [0m00:23:16  Registered adapter: snowflake=1.8.1
[2025-04-24T00:23:17.722+0000] {subprocess.py:93} INFO - [0m00:23:17  [[33mWARNING[0m]: Deprecated functionality
[2025-04-24T00:23:17.723+0000] {subprocess.py:93} INFO - The `tests` config has been renamed to `data_tests`. Please see
[2025-04-24T00:23:17.724+0000] {subprocess.py:93} INFO - https://docs.getdbt.com/docs/build/data-tests#new-data_tests-syntax for more
[2025-04-24T00:23:17.724+0000] {subprocess.py:93} INFO - information.
[2025-04-24T00:23:18.067+0000] {subprocess.py:93} INFO - [0m00:23:18  Encountered an error:
[2025-04-24T00:23:18.068+0000] {subprocess.py:93} INFO - Found a cycle: model.dbt_stock_project.rsi
[2025-04-24T00:23:18.069+0000] {subprocess.py:93} INFO - [0m00:23:18  Traceback (most recent call last):
[2025-04-24T00:23:18.070+0000] {subprocess.py:93} INFO -   File "/home/***/.local/lib/python3.12/site-packages/dbt/cli/requires.py", line 138, in wrapper
[2025-04-24T00:23:18.071+0000] {subprocess.py:93} INFO -     result, success = func(*args, **kwargs)
[2025-04-24T00:23:18.072+0000] {subprocess.py:93} INFO -                       ^^^^^^^^^^^^^^^^^^^^^
[2025-04-24T00:23:18.073+0000] {subprocess.py:93} INFO -   File "/home/***/.local/lib/python3.12/site-packages/dbt/cli/requires.py", line 101, in wrapper
[2025-04-24T00:23:18.074+0000] {subprocess.py:93} INFO -     return func(*args, **kwargs)
[2025-04-24T00:23:18.075+0000] {subprocess.py:93} INFO -            ^^^^^^^^^^^^^^^^^^^^^
[2025-04-24T00:23:18.076+0000] {subprocess.py:93} INFO -   File "/home/***/.local/lib/python3.12/site-packages/dbt/cli/requires.py", line 218, in wrapper
[2025-04-24T00:23:18.077+0000] {subprocess.py:93} INFO -     return func(*args, **kwargs)
[2025-04-24T00:23:18.078+0000] {subprocess.py:93} INFO -            ^^^^^^^^^^^^^^^^^^^^^
[2025-04-24T00:23:18.079+0000] {subprocess.py:93} INFO -   File "/home/***/.local/lib/python3.12/site-packages/dbt/cli/requires.py", line 247, in wrapper
[2025-04-24T00:23:18.080+0000] {subprocess.py:93} INFO -     return func(*args, **kwargs)
[2025-04-24T00:23:18.081+0000] {subprocess.py:93} INFO -            ^^^^^^^^^^^^^^^^^^^^^
[2025-04-24T00:23:18.082+0000] {subprocess.py:93} INFO -   File "/home/***/.local/lib/python3.12/site-packages/dbt/cli/requires.py", line 294, in wrapper
[2025-04-24T00:23:18.083+0000] {subprocess.py:93} INFO -     return func(*args, **kwargs)
[2025-04-24T00:23:18.084+0000] {subprocess.py:93} INFO -            ^^^^^^^^^^^^^^^^^^^^^
[2025-04-24T00:23:18.084+0000] {subprocess.py:93} INFO -   File "/home/***/.local/lib/python3.12/site-packages/dbt/cli/requires.py", line 332, in wrapper
[2025-04-24T00:23:18.085+0000] {subprocess.py:93} INFO -     return func(*args, **kwargs)
[2025-04-24T00:23:18.086+0000] {subprocess.py:93} INFO -            ^^^^^^^^^^^^^^^^^^^^^
[2025-04-24T00:23:18.087+0000] {subprocess.py:93} INFO -   File "/home/***/.local/lib/python3.12/site-packages/dbt/cli/main.py", line 569, in run
[2025-04-24T00:23:18.088+0000] {subprocess.py:93} INFO -     results = task.run()
[2025-04-24T00:23:18.088+0000] {subprocess.py:93} INFO -               ^^^^^^^^^^
[2025-04-24T00:23:18.089+0000] {subprocess.py:93} INFO -   File "/home/***/.local/lib/python3.12/site-packages/dbt/task/runnable.py", line 506, in run
[2025-04-24T00:23:18.090+0000] {subprocess.py:93} INFO -     self._runtime_initialize()
[2025-04-24T00:23:18.090+0000] {subprocess.py:93} INFO -   File "/home/***/.local/lib/python3.12/site-packages/dbt/task/compile.py", line 125, in _runtime_initialize
[2025-04-24T00:23:18.091+0000] {subprocess.py:93} INFO -     super()._runtime_initialize()
[2025-04-24T00:23:18.092+0000] {subprocess.py:93} INFO -   File "/home/***/.local/lib/python3.12/site-packages/dbt/task/runnable.py", line 147, in _runtime_initialize
[2025-04-24T00:23:18.092+0000] {subprocess.py:93} INFO -     self.compile_manifest()
[2025-04-24T00:23:18.093+0000] {subprocess.py:93} INFO -   File "/home/***/.local/lib/python3.12/site-packages/dbt/task/base.py", line 145, in compile_manifest
[2025-04-24T00:23:18.094+0000] {subprocess.py:93} INFO -     self.graph = self.compiler.compile(self.manifest)
[2025-04-24T00:23:18.095+0000] {subprocess.py:93} INFO -                  ^^^^^^^^^^^^^^^^^^^^^^^^^^^^^^^^^^^^
[2025-04-24T00:23:18.095+0000] {subprocess.py:93} INFO -   File "/home/***/.local/lib/python3.12/site-packages/dbt/compilation.py", line 449, in compile
[2025-04-24T00:23:18.096+0000] {subprocess.py:93} INFO -     linker.link_graph(manifest)
[2025-04-24T00:23:18.096+0000] {subprocess.py:93} INFO -   File "/home/***/.local/lib/python3.12/site-packages/dbt/compilation.py", line 192, in link_graph
[2025-04-24T00:23:18.097+0000] {subprocess.py:93} INFO -     raise RuntimeError("Found a cycle: {}".format(cycle))
[2025-04-24T00:23:18.098+0000] {subprocess.py:93} INFO - RuntimeError: Found a cycle: model.dbt_stock_project.rsi
[2025-04-24T00:23:18.099+0000] {subprocess.py:93} INFO - 
[2025-04-24T00:23:18.837+0000] {subprocess.py:97} INFO - Command exited with return code 2
[2025-04-24T00:23:18.849+0000] {taskinstance.py:3310} ERROR - Task failed with exception
Traceback (most recent call last):
  File "/home/airflow/.local/lib/python3.12/site-packages/airflow/models/taskinstance.py", line 767, in _execute_task
    result = _execute_callable(context=context, **execute_callable_kwargs)
             ^^^^^^^^^^^^^^^^^^^^^^^^^^^^^^^^^^^^^^^^^^^^^^^^^^^^^^^^^^^^^
  File "/home/airflow/.local/lib/python3.12/site-packages/airflow/models/taskinstance.py", line 733, in _execute_callable
    return ExecutionCallableRunner(
           ^^^^^^^^^^^^^^^^^^^^^^^^
  File "/home/airflow/.local/lib/python3.12/site-packages/airflow/utils/operator_helpers.py", line 252, in run
    return self.func(*args, **kwargs)
           ^^^^^^^^^^^^^^^^^^^^^^^^^^
  File "/home/airflow/.local/lib/python3.12/site-packages/airflow/models/baseoperator.py", line 406, in wrapper
    return func(self, *args, **kwargs)
           ^^^^^^^^^^^^^^^^^^^^^^^^^^^
  File "/home/airflow/.local/lib/python3.12/site-packages/airflow/operators/bash.py", line 249, in execute
    raise AirflowException(
airflow.exceptions.AirflowException: Bash command failed. The command returned a non-zero exit code 2.
[2025-04-24T00:23:18.855+0000] {taskinstance.py:1225} INFO - Marking task as FAILED. dag_id=dbt_stock_project, task_id=dbt_run, run_id=manual__2025-04-24T00:23:13.065590+00:00, execution_date=20250424T002313, start_date=20250424T002313, end_date=20250424T002318
[2025-04-24T00:23:18.870+0000] {taskinstance.py:340} INFO - ::group::Post task execution logs
[2025-04-24T00:23:18.872+0000] {standard_task_runner.py:124} ERROR - Failed to execute job 332 for task dbt_run (Bash command failed. The command returned a non-zero exit code 2.; 7056)
Traceback (most recent call last):
  File "/home/airflow/.local/lib/python3.12/site-packages/airflow/task/task_runner/standard_task_runner.py", line 117, in _start_by_fork
    ret = args.func(args, dag=self.dag)
          ^^^^^^^^^^^^^^^^^^^^^^^^^^^^^
  File "/home/airflow/.local/lib/python3.12/site-packages/airflow/cli/cli_config.py", line 49, in command
    return func(*args, **kwargs)
           ^^^^^^^^^^^^^^^^^^^^^
  File "/home/airflow/.local/lib/python3.12/site-packages/airflow/utils/cli.py", line 115, in wrapper
    return f(*args, **kwargs)
           ^^^^^^^^^^^^^^^^^^
  File "/home/airflow/.local/lib/python3.12/site-packages/airflow/cli/commands/task_command.py", line 483, in task_run
    task_return_code = _run_task_by_selected_method(args, _dag, ti)
                       ^^^^^^^^^^^^^^^^^^^^^^^^^^^^^^^^^^^^^^^^^^^^
  File "/home/airflow/.local/lib/python3.12/site-packages/airflow/cli/commands/task_command.py", line 256, in _run_task_by_selected_method
    return _run_raw_task(args, ti)
           ^^^^^^^^^^^^^^^^^^^^^^^
  File "/home/airflow/.local/lib/python3.12/site-packages/airflow/cli/commands/task_command.py", line 341, in _run_raw_task
    return ti._run_raw_task(
           ^^^^^^^^^^^^^^^^^
  File "/home/airflow/.local/lib/python3.12/site-packages/airflow/utils/session.py", line 97, in wrapper
    return func(*args, session=session, **kwargs)
           ^^^^^^^^^^^^^^^^^^^^^^^^^^^^^^^^^^^^^^
  File "/home/airflow/.local/lib/python3.12/site-packages/airflow/models/taskinstance.py", line 3004, in _run_raw_task
    return _run_raw_task(
           ^^^^^^^^^^^^^^
  File "/home/airflow/.local/lib/python3.12/site-packages/airflow/models/taskinstance.py", line 273, in _run_raw_task
    TaskInstance._execute_task_with_callbacks(
  File "/home/airflow/.local/lib/python3.12/site-packages/airflow/models/taskinstance.py", line 3158, in _execute_task_with_callbacks
    result = self._execute_task(context, task_orig)
             ^^^^^^^^^^^^^^^^^^^^^^^^^^^^^^^^^^^^^^
  File "/home/airflow/.local/lib/python3.12/site-packages/airflow/models/taskinstance.py", line 3182, in _execute_task
    return _execute_task(self, context, task_orig)
           ^^^^^^^^^^^^^^^^^^^^^^^^^^^^^^^^^^^^^^^
  File "/home/airflow/.local/lib/python3.12/site-packages/airflow/models/taskinstance.py", line 767, in _execute_task
    result = _execute_callable(context=context, **execute_callable_kwargs)
             ^^^^^^^^^^^^^^^^^^^^^^^^^^^^^^^^^^^^^^^^^^^^^^^^^^^^^^^^^^^^^
  File "/home/airflow/.local/lib/python3.12/site-packages/airflow/models/taskinstance.py", line 733, in _execute_callable
    return ExecutionCallableRunner(
           ^^^^^^^^^^^^^^^^^^^^^^^^
  File "/home/airflow/.local/lib/python3.12/site-packages/airflow/utils/operator_helpers.py", line 252, in run
    return self.func(*args, **kwargs)
           ^^^^^^^^^^^^^^^^^^^^^^^^^^
  File "/home/airflow/.local/lib/python3.12/site-packages/airflow/models/baseoperator.py", line 406, in wrapper
    return func(self, *args, **kwargs)
           ^^^^^^^^^^^^^^^^^^^^^^^^^^^
  File "/home/airflow/.local/lib/python3.12/site-packages/airflow/operators/bash.py", line 249, in execute
    raise AirflowException(
airflow.exceptions.AirflowException: Bash command failed. The command returned a non-zero exit code 2.
[2025-04-24T00:23:18.911+0000] {local_task_job_runner.py:266} INFO - Task exited with return code 1
[2025-04-24T00:23:18.933+0000] {taskinstance.py:3900} INFO - 0 downstream tasks scheduled from follow-on schedule check
[2025-04-24T00:23:18.940+0000] {local_task_job_runner.py:245} INFO - ::endgroup::
