[2025-04-23T23:38:47.522+0000] {local_task_job_runner.py:123} INFO - ::group::Pre task execution logs
[2025-04-23T23:38:47.538+0000] {taskinstance.py:2612} INFO - Dependencies all met for dep_context=non-requeueable deps ti=<TaskInstance: dbt_stock_project.dbt_run manual__2025-04-23T23:38:46.612693+00:00 [queued]>
[2025-04-23T23:38:47.547+0000] {taskinstance.py:2612} INFO - Dependencies all met for dep_context=requeueable deps ti=<TaskInstance: dbt_stock_project.dbt_run manual__2025-04-23T23:38:46.612693+00:00 [queued]>
[2025-04-23T23:38:47.549+0000] {taskinstance.py:2865} INFO - Starting attempt 1 of 1
[2025-04-23T23:38:47.563+0000] {taskinstance.py:2888} INFO - Executing <Task(BashOperator): dbt_run> on 2025-04-23 23:38:46.612693+00:00
[2025-04-23T23:38:47.571+0000] {standard_task_runner.py:104} INFO - Running: ['***', 'tasks', 'run', 'dbt_stock_project', 'dbt_run', 'manual__2025-04-23T23:38:46.612693+00:00', '--job-id', '312', '--raw', '--subdir', 'DAGS_FOLDER/226_lab2_elt.py', '--cfg-path', '/tmp/tmpar5l3psy']
[2025-04-23T23:38:47.575+0000] {standard_task_runner.py:105} INFO - Job 312: Subtask dbt_run
[2025-04-23T23:38:47.576+0000] {logging_mixin.py:190} WARNING - /home/***/.local/lib/python3.12/site-packages/***/task/task_runner/standard_task_runner.py:70 DeprecationWarning: This process (pid=4633) is multi-threaded, use of fork() may lead to deadlocks in the child.
[2025-04-23T23:38:47.577+0000] {standard_task_runner.py:72} INFO - Started process 4634 to run task
[2025-04-23T23:38:47.625+0000] {task_command.py:467} INFO - Running <TaskInstance: dbt_stock_project.dbt_run manual__2025-04-23T23:38:46.612693+00:00 [running]> on host d01273b1fd04
[2025-04-23T23:38:47.703+0000] {taskinstance.py:3131} INFO - Exporting env vars: AIRFLOW_CTX_DAG_OWNER='***' AIRFLOW_CTX_DAG_ID='dbt_stock_project' AIRFLOW_CTX_TASK_ID='dbt_run' AIRFLOW_CTX_EXECUTION_DATE='2025-04-23T23:38:46.612693+00:00' AIRFLOW_CTX_TRY_NUMBER='1' AIRFLOW_CTX_DAG_RUN_ID='manual__2025-04-23T23:38:46.612693+00:00'
[2025-04-23T23:38:47.704+0000] {taskinstance.py:731} INFO - ::endgroup::
[2025-04-23T23:38:47.730+0000] {subprocess.py:63} INFO - Tmp dir root location: /tmp
[2025-04-23T23:38:47.732+0000] {subprocess.py:75} INFO - Running command: ['/usr/bin/bash', '-c', '/home/***/.local/bin/dbt run --profiles-dir /home/***/.dbt --project-dir /opt/***/dbt']
[2025-04-23T23:38:47.741+0000] {subprocess.py:86} INFO - Output:
[2025-04-23T23:38:50.682+0000] {subprocess.py:93} INFO - [0m23:38:50  Running with dbt=1.8.7
[2025-04-23T23:38:52.444+0000] {subprocess.py:93} INFO - [0m23:38:52  Registered adapter: snowflake=1.8.1
[2025-04-23T23:38:53.110+0000] {subprocess.py:93} INFO - [0m23:38:53  [[33mWARNING[0m]: Deprecated functionality
[2025-04-23T23:38:53.111+0000] {subprocess.py:93} INFO - The `tests` config has been renamed to `data_tests`. Please see
[2025-04-23T23:38:53.112+0000] {subprocess.py:93} INFO - https://docs.getdbt.com/docs/build/data-tests#new-data_tests-syntax for more
[2025-04-23T23:38:53.113+0000] {subprocess.py:93} INFO - information.
[2025-04-23T23:38:53.542+0000] {subprocess.py:93} INFO - [0m23:38:53  Found 6 models, 27 data tests, 3 sources, 459 macros
[2025-04-23T23:38:53.546+0000] {subprocess.py:93} INFO - [0m23:38:53
[2025-04-23T23:38:54.762+0000] {subprocess.py:93} INFO - [0m23:38:54  Concurrency: 1 threads (target='dev')
[2025-04-23T23:38:54.763+0000] {subprocess.py:93} INFO - [0m23:38:54
[2025-04-23T23:38:54.829+0000] {subprocess.py:93} INFO - [0m23:38:54  1 of 4 START sql table model analytics.stock_indicators ........................ [RUN]
[2025-04-23T23:38:56.436+0000] {subprocess.py:93} INFO - [0m23:38:56  1 of 4 OK created sql table model analytics.stock_indicators ................... [[32mSUCCESS 1[0m in 1.60s]
[2025-04-23T23:38:56.439+0000] {subprocess.py:93} INFO - [0m23:38:56  2 of 4 START sql table model analytics.volume_summary .......................... [RUN]
[2025-04-23T23:38:57.582+0000] {subprocess.py:93} INFO - [0m23:38:57  2 of 4 OK created sql table model analytics.volume_summary ..................... [[32mSUCCESS 1[0m in 1.14s]
[2025-04-23T23:38:57.585+0000] {subprocess.py:93} INFO - [0m23:38:57  3 of 4 START sql table model analytics.moving_averages ......................... [RUN]
[2025-04-23T23:38:58.132+0000] {subprocess.py:93} INFO - [0m23:38:58  3 of 4 ERROR creating sql table model analytics.moving_averages ................ [[31mERROR[0m in 0.55s]
[2025-04-23T23:38:58.135+0000] {subprocess.py:93} INFO - [0m23:38:58  4 of 4 START sql table model analytics.rsi ..................................... [RUN]
[2025-04-23T23:38:58.703+0000] {subprocess.py:93} INFO - [0m23:38:58  4 of 4 ERROR creating sql table model analytics.rsi ............................ [[31mERROR[0m in 0.57s]
[2025-04-23T23:38:58.709+0000] {subprocess.py:93} INFO - [0m23:38:58
[2025-04-23T23:38:58.710+0000] {subprocess.py:93} INFO - [0m23:38:58  Finished running 4 table models in 0 hours 0 minutes and 5.16 seconds (5.16s).
[2025-04-23T23:38:58.811+0000] {subprocess.py:93} INFO - [0m23:38:58
[2025-04-23T23:38:58.812+0000] {subprocess.py:93} INFO - [0m23:38:58  [31mCompleted with 2 errors and 0 warnings:[0m
[2025-04-23T23:38:58.813+0000] {subprocess.py:93} INFO - [0m23:38:58
[2025-04-23T23:38:58.814+0000] {subprocess.py:93} INFO - [0m23:38:58    Database Error in model moving_averages (models/output/moving_averages.sql)
[2025-04-23T23:38:58.815+0000] {subprocess.py:93} INFO -   001003 (42000): SQL compilation error:
[2025-04-23T23:38:58.816+0000] {subprocess.py:93} INFO -   syntax error line 50 at position 27 unexpected ';'.
[2025-04-23T23:38:58.817+0000] {subprocess.py:93} INFO -   compiled code at target/run/dbt_stock_project/models/output/moving_averages.sql
[2025-04-23T23:38:58.818+0000] {subprocess.py:93} INFO - [0m23:38:58
[2025-04-23T23:38:58.819+0000] {subprocess.py:93} INFO - [0m23:38:58    Database Error in model rsi (models/output/rsi.sql)
[2025-04-23T23:38:58.820+0000] {subprocess.py:93} INFO -   001003 (42000): SQL compilation error:
[2025-04-23T23:38:58.821+0000] {subprocess.py:93} INFO -   syntax error line 62 at position 27 unexpected ';'.
[2025-04-23T23:38:58.822+0000] {subprocess.py:93} INFO -   compiled code at target/run/dbt_stock_project/models/output/rsi.sql
[2025-04-23T23:38:58.823+0000] {subprocess.py:93} INFO - [0m23:38:58
[2025-04-23T23:38:58.824+0000] {subprocess.py:93} INFO - [0m23:38:58  Done. PASS=2 WARN=0 ERROR=2 SKIP=0 TOTAL=4
[2025-04-23T23:38:59.747+0000] {subprocess.py:97} INFO - Command exited with return code 1
[2025-04-23T23:38:59.757+0000] {taskinstance.py:3310} ERROR - Task failed with exception
Traceback (most recent call last):
  File "/home/airflow/.local/lib/python3.12/site-packages/airflow/models/taskinstance.py", line 767, in _execute_task
    result = _execute_callable(context=context, **execute_callable_kwargs)
             ^^^^^^^^^^^^^^^^^^^^^^^^^^^^^^^^^^^^^^^^^^^^^^^^^^^^^^^^^^^^^
  File "/home/airflow/.local/lib/python3.12/site-packages/airflow/models/taskinstance.py", line 733, in _execute_callable
    return ExecutionCallableRunner(
           ^^^^^^^^^^^^^^^^^^^^^^^^
  File "/home/airflow/.local/lib/python3.12/site-packages/airflow/utils/operator_helpers.py", line 252, in run
    return self.func(*args, **kwargs)
           ^^^^^^^^^^^^^^^^^^^^^^^^^^
  File "/home/airflow/.local/lib/python3.12/site-packages/airflow/models/baseoperator.py", line 406, in wrapper
    return func(self, *args, **kwargs)
           ^^^^^^^^^^^^^^^^^^^^^^^^^^^
  File "/home/airflow/.local/lib/python3.12/site-packages/airflow/operators/bash.py", line 249, in execute
    raise AirflowException(
airflow.exceptions.AirflowException: Bash command failed. The command returned a non-zero exit code 1.
[2025-04-23T23:38:59.765+0000] {taskinstance.py:1225} INFO - Marking task as FAILED. dag_id=dbt_stock_project, task_id=dbt_run, run_id=manual__2025-04-23T23:38:46.612693+00:00, execution_date=20250423T233846, start_date=20250423T233847, end_date=20250423T233859
[2025-04-23T23:38:59.779+0000] {taskinstance.py:340} INFO - ::group::Post task execution logs
[2025-04-23T23:38:59.780+0000] {standard_task_runner.py:124} ERROR - Failed to execute job 312 for task dbt_run (Bash command failed. The command returned a non-zero exit code 1.; 4634)
Traceback (most recent call last):
  File "/home/airflow/.local/lib/python3.12/site-packages/airflow/task/task_runner/standard_task_runner.py", line 117, in _start_by_fork
    ret = args.func(args, dag=self.dag)
          ^^^^^^^^^^^^^^^^^^^^^^^^^^^^^
  File "/home/airflow/.local/lib/python3.12/site-packages/airflow/cli/cli_config.py", line 49, in command
    return func(*args, **kwargs)
           ^^^^^^^^^^^^^^^^^^^^^
  File "/home/airflow/.local/lib/python3.12/site-packages/airflow/utils/cli.py", line 115, in wrapper
    return f(*args, **kwargs)
           ^^^^^^^^^^^^^^^^^^
  File "/home/airflow/.local/lib/python3.12/site-packages/airflow/cli/commands/task_command.py", line 483, in task_run
    task_return_code = _run_task_by_selected_method(args, _dag, ti)
                       ^^^^^^^^^^^^^^^^^^^^^^^^^^^^^^^^^^^^^^^^^^^^
  File "/home/airflow/.local/lib/python3.12/site-packages/airflow/cli/commands/task_command.py", line 256, in _run_task_by_selected_method
    return _run_raw_task(args, ti)
           ^^^^^^^^^^^^^^^^^^^^^^^
  File "/home/airflow/.local/lib/python3.12/site-packages/airflow/cli/commands/task_command.py", line 341, in _run_raw_task
    return ti._run_raw_task(
           ^^^^^^^^^^^^^^^^^
  File "/home/airflow/.local/lib/python3.12/site-packages/airflow/utils/session.py", line 97, in wrapper
    return func(*args, session=session, **kwargs)
           ^^^^^^^^^^^^^^^^^^^^^^^^^^^^^^^^^^^^^^
  File "/home/airflow/.local/lib/python3.12/site-packages/airflow/models/taskinstance.py", line 3004, in _run_raw_task
    return _run_raw_task(
           ^^^^^^^^^^^^^^
  File "/home/airflow/.local/lib/python3.12/site-packages/airflow/models/taskinstance.py", line 273, in _run_raw_task
    TaskInstance._execute_task_with_callbacks(
  File "/home/airflow/.local/lib/python3.12/site-packages/airflow/models/taskinstance.py", line 3158, in _execute_task_with_callbacks
    result = self._execute_task(context, task_orig)
             ^^^^^^^^^^^^^^^^^^^^^^^^^^^^^^^^^^^^^^
  File "/home/airflow/.local/lib/python3.12/site-packages/airflow/models/taskinstance.py", line 3182, in _execute_task
    return _execute_task(self, context, task_orig)
           ^^^^^^^^^^^^^^^^^^^^^^^^^^^^^^^^^^^^^^^
  File "/home/airflow/.local/lib/python3.12/site-packages/airflow/models/taskinstance.py", line 767, in _execute_task
    result = _execute_callable(context=context, **execute_callable_kwargs)
             ^^^^^^^^^^^^^^^^^^^^^^^^^^^^^^^^^^^^^^^^^^^^^^^^^^^^^^^^^^^^^
  File "/home/airflow/.local/lib/python3.12/site-packages/airflow/models/taskinstance.py", line 733, in _execute_callable
    return ExecutionCallableRunner(
           ^^^^^^^^^^^^^^^^^^^^^^^^
  File "/home/airflow/.local/lib/python3.12/site-packages/airflow/utils/operator_helpers.py", line 252, in run
    return self.func(*args, **kwargs)
           ^^^^^^^^^^^^^^^^^^^^^^^^^^
  File "/home/airflow/.local/lib/python3.12/site-packages/airflow/models/baseoperator.py", line 406, in wrapper
    return func(self, *args, **kwargs)
           ^^^^^^^^^^^^^^^^^^^^^^^^^^^
  File "/home/airflow/.local/lib/python3.12/site-packages/airflow/operators/bash.py", line 249, in execute
    raise AirflowException(
airflow.exceptions.AirflowException: Bash command failed. The command returned a non-zero exit code 1.
[2025-04-23T23:38:59.821+0000] {local_task_job_runner.py:266} INFO - Task exited with return code 1
[2025-04-23T23:38:59.839+0000] {taskinstance.py:3900} INFO - 0 downstream tasks scheduled from follow-on schedule check
[2025-04-23T23:38:59.844+0000] {local_task_job_runner.py:245} INFO - ::endgroup::
