[2025-04-24T00:02:44.861+0000] {local_task_job_runner.py:123} INFO - ::group::Pre task execution logs
[2025-04-24T00:02:44.880+0000] {taskinstance.py:2612} INFO - Dependencies all met for dep_context=non-requeueable deps ti=<TaskInstance: dbt_stock_project.dbt_run manual__2025-04-24T00:02:44.040691+00:00 [queued]>
[2025-04-24T00:02:44.889+0000] {taskinstance.py:2612} INFO - Dependencies all met for dep_context=requeueable deps ti=<TaskInstance: dbt_stock_project.dbt_run manual__2025-04-24T00:02:44.040691+00:00 [queued]>
[2025-04-24T00:02:44.891+0000] {taskinstance.py:2865} INFO - Starting attempt 1 of 1
[2025-04-24T00:02:44.905+0000] {taskinstance.py:2888} INFO - Executing <Task(BashOperator): dbt_run> on 2025-04-24 00:02:44.040691+00:00
[2025-04-24T00:02:44.913+0000] {standard_task_runner.py:104} INFO - Running: ['***', 'tasks', 'run', 'dbt_stock_project', 'dbt_run', 'manual__2025-04-24T00:02:44.040691+00:00', '--job-id', '323', '--raw', '--subdir', 'DAGS_FOLDER/226_lab2_elt.py', '--cfg-path', '/tmp/tmp4b9umuoj']
[2025-04-24T00:02:44.918+0000] {logging_mixin.py:190} WARNING - /home/***/.local/lib/python3.12/site-packages/***/task/task_runner/standard_task_runner.py:70 DeprecationWarning: This process (pid=5871) is multi-threaded, use of fork() may lead to deadlocks in the child.
[2025-04-24T00:02:44.919+0000] {standard_task_runner.py:105} INFO - Job 323: Subtask dbt_run
[2025-04-24T00:02:44.920+0000] {standard_task_runner.py:72} INFO - Started process 5872 to run task
[2025-04-24T00:02:44.982+0000] {task_command.py:467} INFO - Running <TaskInstance: dbt_stock_project.dbt_run manual__2025-04-24T00:02:44.040691+00:00 [running]> on host d01273b1fd04
[2025-04-24T00:02:45.075+0000] {taskinstance.py:3131} INFO - Exporting env vars: AIRFLOW_CTX_DAG_OWNER='***' AIRFLOW_CTX_DAG_ID='dbt_stock_project' AIRFLOW_CTX_TASK_ID='dbt_run' AIRFLOW_CTX_EXECUTION_DATE='2025-04-24T00:02:44.040691+00:00' AIRFLOW_CTX_TRY_NUMBER='1' AIRFLOW_CTX_DAG_RUN_ID='manual__2025-04-24T00:02:44.040691+00:00'
[2025-04-24T00:02:45.076+0000] {taskinstance.py:731} INFO - ::endgroup::
[2025-04-24T00:02:45.094+0000] {subprocess.py:63} INFO - Tmp dir root location: /tmp
[2025-04-24T00:02:45.098+0000] {subprocess.py:75} INFO - Running command: ['/usr/bin/bash', '-c', '/home/***/.local/bin/dbt run --profiles-dir /home/***/.dbt --project-dir /opt/***/dbt']
[2025-04-24T00:02:45.107+0000] {subprocess.py:86} INFO - Output:
[2025-04-24T00:02:47.164+0000] {subprocess.py:93} INFO - [0m00:02:47  Running with dbt=1.8.7
[2025-04-24T00:02:48.231+0000] {subprocess.py:93} INFO - [0m00:02:48  Registered adapter: snowflake=1.8.1
[2025-04-24T00:02:49.008+0000] {subprocess.py:93} INFO - [0m00:02:49  [[33mWARNING[0m]: Deprecated functionality
[2025-04-24T00:02:49.009+0000] {subprocess.py:93} INFO - The `tests` config has been renamed to `data_tests`. Please see
[2025-04-24T00:02:49.010+0000] {subprocess.py:93} INFO - https://docs.getdbt.com/docs/build/data-tests#new-data_tests-syntax for more
[2025-04-24T00:02:49.011+0000] {subprocess.py:93} INFO - information.
[2025-04-24T00:02:49.393+0000] {subprocess.py:93} INFO - [0m00:02:49  Found 6 models, 18 data tests, 3 sources, 459 macros
[2025-04-24T00:02:49.397+0000] {subprocess.py:93} INFO - [0m00:02:49
[2025-04-24T00:02:50.421+0000] {subprocess.py:93} INFO - [0m00:02:50  Concurrency: 1 threads (target='dev')
[2025-04-24T00:02:50.421+0000] {subprocess.py:93} INFO - [0m00:02:50
[2025-04-24T00:02:50.433+0000] {subprocess.py:93} INFO - [0m00:02:50  1 of 4 START sql table model analytics.moving_averages ......................... [RUN]
[2025-04-24T00:02:50.920+0000] {subprocess.py:93} INFO - [0m00:02:50  1 of 4 ERROR creating sql table model analytics.moving_averages ................ [[31mERROR[0m in 0.48s]
[2025-04-24T00:02:50.963+0000] {subprocess.py:93} INFO - [0m00:02:50  2 of 4 START sql table model analytics.stock_indicators ........................ [RUN]
[2025-04-24T00:02:52.049+0000] {subprocess.py:93} INFO - [0m00:02:52  2 of 4 OK created sql table model analytics.stock_indicators ................... [[32mSUCCESS 1[0m in 1.08s]
[2025-04-24T00:02:52.052+0000] {subprocess.py:93} INFO - [0m00:02:52  3 of 4 START sql table model analytics.volume_summary .......................... [RUN]
[2025-04-24T00:02:53.387+0000] {subprocess.py:93} INFO - [0m00:02:53  3 of 4 OK created sql table model analytics.volume_summary ..................... [[32mSUCCESS 1[0m in 1.33s]
[2025-04-24T00:02:53.391+0000] {subprocess.py:93} INFO - [0m00:02:53  4 of 4 START sql table model analytics.rsi ..................................... [RUN]
[2025-04-24T00:02:53.879+0000] {subprocess.py:93} INFO - [0m00:02:53  4 of 4 ERROR creating sql table model analytics.rsi ............................ [[31mERROR[0m in 0.49s]
[2025-04-24T00:02:53.884+0000] {subprocess.py:93} INFO - [0m00:02:53
[2025-04-24T00:02:53.885+0000] {subprocess.py:93} INFO - [0m00:02:53  Finished running 4 table models in 0 hours 0 minutes and 4.49 seconds (4.49s).
[2025-04-24T00:02:54.067+0000] {subprocess.py:93} INFO - [0m00:02:54
[2025-04-24T00:02:54.069+0000] {subprocess.py:93} INFO - [0m00:02:54  [31mCompleted with 2 errors and 0 warnings:[0m
[2025-04-24T00:02:54.070+0000] {subprocess.py:93} INFO - [0m00:02:54
[2025-04-24T00:02:54.071+0000] {subprocess.py:93} INFO - [0m00:02:54    Database Error in model moving_averages (models/output/moving_averages.sql)
[2025-04-24T00:02:54.072+0000] {subprocess.py:93} INFO -   001003 (42000): SQL compilation error:
[2025-04-24T00:02:54.073+0000] {subprocess.py:93} INFO -   syntax error line 31 at position 27 unexpected ';'.
[2025-04-24T00:02:54.073+0000] {subprocess.py:93} INFO -   compiled code at target/run/dbt_stock_project/models/output/moving_averages.sql
[2025-04-24T00:02:54.074+0000] {subprocess.py:93} INFO - [0m00:02:54
[2025-04-24T00:02:54.075+0000] {subprocess.py:93} INFO - [0m00:02:54    Database Error in model rsi (models/output/rsi.sql)
[2025-04-24T00:02:54.076+0000] {subprocess.py:93} INFO -   001003 (42000): SQL compilation error:
[2025-04-24T00:02:54.077+0000] {subprocess.py:93} INFO -   syntax error line 48 at position 27 unexpected ';'.
[2025-04-24T00:02:54.078+0000] {subprocess.py:93} INFO -   compiled code at target/run/dbt_stock_project/models/output/rsi.sql
[2025-04-24T00:02:54.079+0000] {subprocess.py:93} INFO - [0m00:02:54
[2025-04-24T00:02:54.080+0000] {subprocess.py:93} INFO - [0m00:02:54  Done. PASS=2 WARN=0 ERROR=2 SKIP=0 TOTAL=4
[2025-04-24T00:02:54.955+0000] {subprocess.py:97} INFO - Command exited with return code 1
[2025-04-24T00:02:54.967+0000] {taskinstance.py:3310} ERROR - Task failed with exception
Traceback (most recent call last):
  File "/home/airflow/.local/lib/python3.12/site-packages/airflow/models/taskinstance.py", line 767, in _execute_task
    result = _execute_callable(context=context, **execute_callable_kwargs)
             ^^^^^^^^^^^^^^^^^^^^^^^^^^^^^^^^^^^^^^^^^^^^^^^^^^^^^^^^^^^^^
  File "/home/airflow/.local/lib/python3.12/site-packages/airflow/models/taskinstance.py", line 733, in _execute_callable
    return ExecutionCallableRunner(
           ^^^^^^^^^^^^^^^^^^^^^^^^
  File "/home/airflow/.local/lib/python3.12/site-packages/airflow/utils/operator_helpers.py", line 252, in run
    return self.func(*args, **kwargs)
           ^^^^^^^^^^^^^^^^^^^^^^^^^^
  File "/home/airflow/.local/lib/python3.12/site-packages/airflow/models/baseoperator.py", line 406, in wrapper
    return func(self, *args, **kwargs)
           ^^^^^^^^^^^^^^^^^^^^^^^^^^^
  File "/home/airflow/.local/lib/python3.12/site-packages/airflow/operators/bash.py", line 249, in execute
    raise AirflowException(
airflow.exceptions.AirflowException: Bash command failed. The command returned a non-zero exit code 1.
[2025-04-24T00:02:54.972+0000] {taskinstance.py:1225} INFO - Marking task as FAILED. dag_id=dbt_stock_project, task_id=dbt_run, run_id=manual__2025-04-24T00:02:44.040691+00:00, execution_date=20250424T000244, start_date=20250424T000244, end_date=20250424T000254
[2025-04-24T00:02:54.988+0000] {taskinstance.py:340} INFO - ::group::Post task execution logs
[2025-04-24T00:02:54.989+0000] {standard_task_runner.py:124} ERROR - Failed to execute job 323 for task dbt_run (Bash command failed. The command returned a non-zero exit code 1.; 5872)
Traceback (most recent call last):
  File "/home/airflow/.local/lib/python3.12/site-packages/airflow/task/task_runner/standard_task_runner.py", line 117, in _start_by_fork
    ret = args.func(args, dag=self.dag)
          ^^^^^^^^^^^^^^^^^^^^^^^^^^^^^
  File "/home/airflow/.local/lib/python3.12/site-packages/airflow/cli/cli_config.py", line 49, in command
    return func(*args, **kwargs)
           ^^^^^^^^^^^^^^^^^^^^^
  File "/home/airflow/.local/lib/python3.12/site-packages/airflow/utils/cli.py", line 115, in wrapper
    return f(*args, **kwargs)
           ^^^^^^^^^^^^^^^^^^
  File "/home/airflow/.local/lib/python3.12/site-packages/airflow/cli/commands/task_command.py", line 483, in task_run
    task_return_code = _run_task_by_selected_method(args, _dag, ti)
                       ^^^^^^^^^^^^^^^^^^^^^^^^^^^^^^^^^^^^^^^^^^^^
  File "/home/airflow/.local/lib/python3.12/site-packages/airflow/cli/commands/task_command.py", line 256, in _run_task_by_selected_method
    return _run_raw_task(args, ti)
           ^^^^^^^^^^^^^^^^^^^^^^^
  File "/home/airflow/.local/lib/python3.12/site-packages/airflow/cli/commands/task_command.py", line 341, in _run_raw_task
    return ti._run_raw_task(
           ^^^^^^^^^^^^^^^^^
  File "/home/airflow/.local/lib/python3.12/site-packages/airflow/utils/session.py", line 97, in wrapper
    return func(*args, session=session, **kwargs)
           ^^^^^^^^^^^^^^^^^^^^^^^^^^^^^^^^^^^^^^
  File "/home/airflow/.local/lib/python3.12/site-packages/airflow/models/taskinstance.py", line 3004, in _run_raw_task
    return _run_raw_task(
           ^^^^^^^^^^^^^^
  File "/home/airflow/.local/lib/python3.12/site-packages/airflow/models/taskinstance.py", line 273, in _run_raw_task
    TaskInstance._execute_task_with_callbacks(
  File "/home/airflow/.local/lib/python3.12/site-packages/airflow/models/taskinstance.py", line 3158, in _execute_task_with_callbacks
    result = self._execute_task(context, task_orig)
             ^^^^^^^^^^^^^^^^^^^^^^^^^^^^^^^^^^^^^^
  File "/home/airflow/.local/lib/python3.12/site-packages/airflow/models/taskinstance.py", line 3182, in _execute_task
    return _execute_task(self, context, task_orig)
           ^^^^^^^^^^^^^^^^^^^^^^^^^^^^^^^^^^^^^^^
  File "/home/airflow/.local/lib/python3.12/site-packages/airflow/models/taskinstance.py", line 767, in _execute_task
    result = _execute_callable(context=context, **execute_callable_kwargs)
             ^^^^^^^^^^^^^^^^^^^^^^^^^^^^^^^^^^^^^^^^^^^^^^^^^^^^^^^^^^^^^
  File "/home/airflow/.local/lib/python3.12/site-packages/airflow/models/taskinstance.py", line 733, in _execute_callable
    return ExecutionCallableRunner(
           ^^^^^^^^^^^^^^^^^^^^^^^^
  File "/home/airflow/.local/lib/python3.12/site-packages/airflow/utils/operator_helpers.py", line 252, in run
    return self.func(*args, **kwargs)
           ^^^^^^^^^^^^^^^^^^^^^^^^^^
  File "/home/airflow/.local/lib/python3.12/site-packages/airflow/models/baseoperator.py", line 406, in wrapper
    return func(self, *args, **kwargs)
           ^^^^^^^^^^^^^^^^^^^^^^^^^^^
  File "/home/airflow/.local/lib/python3.12/site-packages/airflow/operators/bash.py", line 249, in execute
    raise AirflowException(
airflow.exceptions.AirflowException: Bash command failed. The command returned a non-zero exit code 1.
[2025-04-24T00:02:55.002+0000] {local_task_job_runner.py:266} INFO - Task exited with return code 1
[2025-04-24T00:02:55.023+0000] {taskinstance.py:3900} INFO - 0 downstream tasks scheduled from follow-on schedule check
[2025-04-24T00:02:55.028+0000] {local_task_job_runner.py:245} INFO - ::endgroup::
