[2025-04-24T08:11:58.945+0000] {local_task_job_runner.py:123} INFO - ::group::Pre task execution logs
[2025-04-24T08:11:58.966+0000] {taskinstance.py:2612} INFO - Dependencies all met for dep_context=non-requeueable deps ti=<TaskInstance: dbt_stock_project.dbt_snapshot manual__2025-04-24T08:11:27.923024+00:00 [queued]>
[2025-04-24T08:11:58.976+0000] {taskinstance.py:2612} INFO - Dependencies all met for dep_context=requeueable deps ti=<TaskInstance: dbt_stock_project.dbt_snapshot manual__2025-04-24T08:11:27.923024+00:00 [queued]>
[2025-04-24T08:11:58.978+0000] {taskinstance.py:2865} INFO - Starting attempt 1 of 1
[2025-04-24T08:11:58.994+0000] {taskinstance.py:2888} INFO - Executing <Task(BashOperator): dbt_snapshot> on 2025-04-24 08:11:27.923024+00:00
[2025-04-24T08:11:59.005+0000] {logging_mixin.py:190} WARNING - /home/***/.local/lib/python3.12/site-packages/***/task/task_runner/standard_task_runner.py:70 DeprecationWarning: This process (pid=4693) is multi-threaded, use of fork() may lead to deadlocks in the child.
[2025-04-24T08:11:59.003+0000] {standard_task_runner.py:104} INFO - Running: ['***', 'tasks', 'run', 'dbt_stock_project', 'dbt_snapshot', 'manual__2025-04-24T08:11:27.923024+00:00', '--job-id', '382', '--raw', '--subdir', 'DAGS_FOLDER/226_lab2_elt.py', '--cfg-path', '/tmp/tmpdfzokb3e']
[2025-04-24T08:11:59.006+0000] {standard_task_runner.py:72} INFO - Started process 4699 to run task
[2025-04-24T08:11:59.007+0000] {standard_task_runner.py:105} INFO - Job 382: Subtask dbt_snapshot
[2025-04-24T08:11:59.059+0000] {task_command.py:467} INFO - Running <TaskInstance: dbt_stock_project.dbt_snapshot manual__2025-04-24T08:11:27.923024+00:00 [running]> on host e8b5346887eb
[2025-04-24T08:11:59.154+0000] {taskinstance.py:3131} INFO - Exporting env vars: AIRFLOW_CTX_DAG_OWNER='***' AIRFLOW_CTX_DAG_ID='dbt_stock_project' AIRFLOW_CTX_TASK_ID='dbt_snapshot' AIRFLOW_CTX_EXECUTION_DATE='2025-04-24T08:11:27.923024+00:00' AIRFLOW_CTX_TRY_NUMBER='1' AIRFLOW_CTX_DAG_RUN_ID='manual__2025-04-24T08:11:27.923024+00:00'
[2025-04-24T08:11:59.156+0000] {taskinstance.py:731} INFO - ::endgroup::
[2025-04-24T08:11:59.172+0000] {subprocess.py:63} INFO - Tmp dir root location: /tmp
[2025-04-24T08:11:59.175+0000] {subprocess.py:75} INFO - Running command: ['/usr/bin/bash', '-c', '/home/***/.local/bin/dbt snapshot --profiles-dir /home/***/.dbt --project-dir /opt/***/dbt']
[2025-04-24T08:11:59.184+0000] {subprocess.py:86} INFO - Output:
[2025-04-24T08:12:01.082+0000] {subprocess.py:93} INFO - [0m08:12:01  Running with dbt=1.8.7
[2025-04-24T08:12:02.258+0000] {subprocess.py:93} INFO - [0m08:12:02  Registered adapter: snowflake=1.8.1
[2025-04-24T08:12:03.270+0000] {subprocess.py:93} INFO - [0m08:12:03  Found 7 models, 10 data tests, 4 snapshots, 3 sources, 459 macros
[2025-04-24T08:12:03.274+0000] {subprocess.py:93} INFO - [0m08:12:03
[2025-04-24T08:12:06.192+0000] {subprocess.py:93} INFO - [0m08:12:06  Concurrency: 1 threads (target='dev')
[2025-04-24T08:12:06.193+0000] {subprocess.py:93} INFO - [0m08:12:06
[2025-04-24T08:12:06.203+0000] {subprocess.py:93} INFO - [0m08:12:06  1 of 4 START snapshot snapshots.snapshot_moving_averages ....................... [RUN]
[2025-04-24T08:12:08.118+0000] {subprocess.py:93} INFO - [0m08:12:08  1 of 4 OK snapshotted snapshots.snapshot_moving_averages ....................... [[32mSUCCESS 1[0m in 1.91s]
[2025-04-24T08:12:08.121+0000] {subprocess.py:93} INFO - [0m08:12:08  2 of 4 START snapshot snapshots.snapshot_rsi ................................... [RUN]
[2025-04-24T08:12:09.595+0000] {subprocess.py:93} INFO - [0m08:12:09  2 of 4 OK snapshotted snapshots.snapshot_rsi ................................... [[32mSUCCESS 1[0m in 1.47s]
[2025-04-24T08:12:09.599+0000] {subprocess.py:93} INFO - [0m08:12:09  3 of 4 START snapshot snapshots.snapshot_stock_indicators ...................... [RUN]
[2025-04-24T08:12:10.254+0000] {subprocess.py:93} INFO - [0m08:12:10  3 of 4 ERROR snapshotting snapshots.snapshot_stock_indicators .................. [[31mERROR[0m in 0.65s]
[2025-04-24T08:12:10.258+0000] {subprocess.py:93} INFO - [0m08:12:10  4 of 4 START snapshot snapshots.snapshot_volume_summary ........................ [RUN]
[2025-04-24T08:12:10.869+0000] {subprocess.py:93} INFO - [0m08:12:10  4 of 4 ERROR snapshotting snapshots.snapshot_volume_summary .................... [[31mERROR[0m in 0.61s]
[2025-04-24T08:12:10.876+0000] {subprocess.py:93} INFO - [0m08:12:10
[2025-04-24T08:12:10.877+0000] {subprocess.py:93} INFO - [0m08:12:10  Finished running 4 snapshots in 0 hours 0 minutes and 7.60 seconds (7.60s).
[2025-04-24T08:12:10.982+0000] {subprocess.py:93} INFO - [0m08:12:10
[2025-04-24T08:12:10.983+0000] {subprocess.py:93} INFO - [0m08:12:10  [31mCompleted with 2 errors and 0 warnings:[0m
[2025-04-24T08:12:10.984+0000] {subprocess.py:93} INFO - [0m08:12:10
[2025-04-24T08:12:10.985+0000] {subprocess.py:93} INFO - [0m08:12:10    Database Error in snapshot snapshot_stock_indicators (snapshots/snapshot_stock_indicators.sql)
[2025-04-24T08:12:10.986+0000] {subprocess.py:93} INFO -   000904 (42000): SQL compilation error: error line 24 at position 6
[2025-04-24T08:12:10.987+0000] {subprocess.py:93} INFO -   invalid identifier 'RSI_14D'
[2025-04-24T08:12:10.987+0000] {subprocess.py:93} INFO - [0m08:12:10
[2025-04-24T08:12:10.988+0000] {subprocess.py:93} INFO - [0m08:12:10    Database Error in snapshot snapshot_volume_summary (snapshots/snapshot_volume _summary.sql)
[2025-04-24T08:12:10.989+0000] {subprocess.py:93} INFO -   000904 (42000): SQL compilation error: error line 24 at position 4
[2025-04-24T08:12:10.989+0000] {subprocess.py:93} INFO -   invalid identifier 'TOTAL_VOLUME'
[2025-04-24T08:12:10.990+0000] {subprocess.py:93} INFO - [0m08:12:10
[2025-04-24T08:12:10.990+0000] {subprocess.py:93} INFO - [0m08:12:10  Done. PASS=2 WARN=0 ERROR=2 SKIP=0 TOTAL=4
[2025-04-24T08:12:11.907+0000] {subprocess.py:97} INFO - Command exited with return code 1
[2025-04-24T08:12:11.919+0000] {taskinstance.py:3310} ERROR - Task failed with exception
Traceback (most recent call last):
  File "/home/airflow/.local/lib/python3.12/site-packages/airflow/models/taskinstance.py", line 767, in _execute_task
    result = _execute_callable(context=context, **execute_callable_kwargs)
             ^^^^^^^^^^^^^^^^^^^^^^^^^^^^^^^^^^^^^^^^^^^^^^^^^^^^^^^^^^^^^
  File "/home/airflow/.local/lib/python3.12/site-packages/airflow/models/taskinstance.py", line 733, in _execute_callable
    return ExecutionCallableRunner(
           ^^^^^^^^^^^^^^^^^^^^^^^^
  File "/home/airflow/.local/lib/python3.12/site-packages/airflow/utils/operator_helpers.py", line 252, in run
    return self.func(*args, **kwargs)
           ^^^^^^^^^^^^^^^^^^^^^^^^^^
  File "/home/airflow/.local/lib/python3.12/site-packages/airflow/models/baseoperator.py", line 406, in wrapper
    return func(self, *args, **kwargs)
           ^^^^^^^^^^^^^^^^^^^^^^^^^^^
  File "/home/airflow/.local/lib/python3.12/site-packages/airflow/operators/bash.py", line 249, in execute
    raise AirflowException(
airflow.exceptions.AirflowException: Bash command failed. The command returned a non-zero exit code 1.
[2025-04-24T08:12:11.924+0000] {taskinstance.py:1225} INFO - Marking task as FAILED. dag_id=dbt_stock_project, task_id=dbt_snapshot, run_id=manual__2025-04-24T08:11:27.923024+00:00, execution_date=20250424T081127, start_date=20250424T081158, end_date=20250424T081211
[2025-04-24T08:12:11.938+0000] {taskinstance.py:340} INFO - ::group::Post task execution logs
[2025-04-24T08:12:11.939+0000] {standard_task_runner.py:124} ERROR - Failed to execute job 382 for task dbt_snapshot (Bash command failed. The command returned a non-zero exit code 1.; 4699)
Traceback (most recent call last):
  File "/home/airflow/.local/lib/python3.12/site-packages/airflow/task/task_runner/standard_task_runner.py", line 117, in _start_by_fork
    ret = args.func(args, dag=self.dag)
          ^^^^^^^^^^^^^^^^^^^^^^^^^^^^^
  File "/home/airflow/.local/lib/python3.12/site-packages/airflow/cli/cli_config.py", line 49, in command
    return func(*args, **kwargs)
           ^^^^^^^^^^^^^^^^^^^^^
  File "/home/airflow/.local/lib/python3.12/site-packages/airflow/utils/cli.py", line 115, in wrapper
    return f(*args, **kwargs)
           ^^^^^^^^^^^^^^^^^^
  File "/home/airflow/.local/lib/python3.12/site-packages/airflow/cli/commands/task_command.py", line 483, in task_run
    task_return_code = _run_task_by_selected_method(args, _dag, ti)
                       ^^^^^^^^^^^^^^^^^^^^^^^^^^^^^^^^^^^^^^^^^^^^
  File "/home/airflow/.local/lib/python3.12/site-packages/airflow/cli/commands/task_command.py", line 256, in _run_task_by_selected_method
    return _run_raw_task(args, ti)
           ^^^^^^^^^^^^^^^^^^^^^^^
  File "/home/airflow/.local/lib/python3.12/site-packages/airflow/cli/commands/task_command.py", line 341, in _run_raw_task
    return ti._run_raw_task(
           ^^^^^^^^^^^^^^^^^
  File "/home/airflow/.local/lib/python3.12/site-packages/airflow/utils/session.py", line 97, in wrapper
    return func(*args, session=session, **kwargs)
           ^^^^^^^^^^^^^^^^^^^^^^^^^^^^^^^^^^^^^^
  File "/home/airflow/.local/lib/python3.12/site-packages/airflow/models/taskinstance.py", line 3004, in _run_raw_task
    return _run_raw_task(
           ^^^^^^^^^^^^^^
  File "/home/airflow/.local/lib/python3.12/site-packages/airflow/models/taskinstance.py", line 273, in _run_raw_task
    TaskInstance._execute_task_with_callbacks(
  File "/home/airflow/.local/lib/python3.12/site-packages/airflow/models/taskinstance.py", line 3158, in _execute_task_with_callbacks
    result = self._execute_task(context, task_orig)
             ^^^^^^^^^^^^^^^^^^^^^^^^^^^^^^^^^^^^^^
  File "/home/airflow/.local/lib/python3.12/site-packages/airflow/models/taskinstance.py", line 3182, in _execute_task
    return _execute_task(self, context, task_orig)
           ^^^^^^^^^^^^^^^^^^^^^^^^^^^^^^^^^^^^^^^
  File "/home/airflow/.local/lib/python3.12/site-packages/airflow/models/taskinstance.py", line 767, in _execute_task
    result = _execute_callable(context=context, **execute_callable_kwargs)
             ^^^^^^^^^^^^^^^^^^^^^^^^^^^^^^^^^^^^^^^^^^^^^^^^^^^^^^^^^^^^^
  File "/home/airflow/.local/lib/python3.12/site-packages/airflow/models/taskinstance.py", line 733, in _execute_callable
    return ExecutionCallableRunner(
           ^^^^^^^^^^^^^^^^^^^^^^^^
  File "/home/airflow/.local/lib/python3.12/site-packages/airflow/utils/operator_helpers.py", line 252, in run
    return self.func(*args, **kwargs)
           ^^^^^^^^^^^^^^^^^^^^^^^^^^
  File "/home/airflow/.local/lib/python3.12/site-packages/airflow/models/baseoperator.py", line 406, in wrapper
    return func(self, *args, **kwargs)
           ^^^^^^^^^^^^^^^^^^^^^^^^^^^
  File "/home/airflow/.local/lib/python3.12/site-packages/airflow/operators/bash.py", line 249, in execute
    raise AirflowException(
airflow.exceptions.AirflowException: Bash command failed. The command returned a non-zero exit code 1.
[2025-04-24T08:12:11.965+0000] {local_task_job_runner.py:266} INFO - Task exited with return code 1
[2025-04-24T08:12:11.981+0000] {taskinstance.py:3900} INFO - 0 downstream tasks scheduled from follow-on schedule check
[2025-04-24T08:12:11.985+0000] {local_task_job_runner.py:245} INFO - ::endgroup::
