[2025-04-24T09:54:15.623+0000] {local_task_job_runner.py:123} INFO - ::group::Pre task execution logs
[2025-04-24T09:54:15.641+0000] {taskinstance.py:2612} INFO - Dependencies all met for dep_context=non-requeueable deps ti=<TaskInstance: dbt_stock_project.dbt_snapshot manual__2025-04-24T08:47:39.548491+00:00 [queued]>
[2025-04-24T09:54:15.650+0000] {taskinstance.py:2612} INFO - Dependencies all met for dep_context=requeueable deps ti=<TaskInstance: dbt_stock_project.dbt_snapshot manual__2025-04-24T08:47:39.548491+00:00 [queued]>
[2025-04-24T09:54:15.653+0000] {taskinstance.py:2865} INFO - Starting attempt 7 of 7
[2025-04-24T09:54:15.667+0000] {taskinstance.py:2888} INFO - Executing <Task(BashOperator): dbt_snapshot> on 2025-04-24 08:47:39.548491+00:00
[2025-04-24T09:54:15.675+0000] {standard_task_runner.py:104} INFO - Running: ['***', 'tasks', 'run', 'dbt_stock_project', 'dbt_snapshot', 'manual__2025-04-24T08:47:39.548491+00:00', '--job-id', '393', '--raw', '--subdir', 'DAGS_FOLDER/226_lab2_elt.py', '--cfg-path', '/tmp/tmprfktchn8']
[2025-04-24T09:54:15.677+0000] {logging_mixin.py:190} WARNING - /home/***/.local/lib/python3.12/site-packages/***/task/task_runner/standard_task_runner.py:70 DeprecationWarning: This process (pid=9206) is multi-threaded, use of fork() may lead to deadlocks in the child.
[2025-04-24T09:54:15.679+0000] {standard_task_runner.py:105} INFO - Job 393: Subtask dbt_snapshot
[2025-04-24T09:54:15.680+0000] {standard_task_runner.py:72} INFO - Started process 9207 to run task
[2025-04-24T09:54:15.732+0000] {task_command.py:467} INFO - Running <TaskInstance: dbt_stock_project.dbt_snapshot manual__2025-04-24T08:47:39.548491+00:00 [running]> on host e8b5346887eb
[2025-04-24T09:54:15.812+0000] {taskinstance.py:3131} INFO - Exporting env vars: AIRFLOW_CTX_DAG_OWNER='***' AIRFLOW_CTX_DAG_ID='dbt_stock_project' AIRFLOW_CTX_TASK_ID='dbt_snapshot' AIRFLOW_CTX_EXECUTION_DATE='2025-04-24T08:47:39.548491+00:00' AIRFLOW_CTX_TRY_NUMBER='7' AIRFLOW_CTX_DAG_RUN_ID='manual__2025-04-24T08:47:39.548491+00:00'
[2025-04-24T09:54:15.814+0000] {taskinstance.py:731} INFO - ::endgroup::
[2025-04-24T09:54:15.828+0000] {subprocess.py:63} INFO - Tmp dir root location: /tmp
[2025-04-24T09:54:15.832+0000] {subprocess.py:75} INFO - Running command: ['/usr/bin/bash', '-c', '/home/***/.local/bin/dbt snapshot --profiles-dir /home/***/.dbt --project-dir /opt/***/dbt']
[2025-04-24T09:54:15.841+0000] {subprocess.py:86} INFO - Output:
[2025-04-24T09:54:17.653+0000] {subprocess.py:93} INFO - [0m09:54:17  Running with dbt=1.8.7
[2025-04-24T09:54:18.663+0000] {subprocess.py:93} INFO - [0m09:54:18  Registered adapter: snowflake=1.8.1
[2025-04-24T09:54:19.739+0000] {subprocess.py:93} INFO - [0m09:54:19  Found 5 models, 10 data tests, 4 snapshots, 3 sources, 459 macros
[2025-04-24T09:54:19.742+0000] {subprocess.py:93} INFO - [0m09:54:19
[2025-04-24T09:54:21.843+0000] {subprocess.py:93} INFO - [0m09:54:21  Concurrency: 1 threads (target='dev')
[2025-04-24T09:54:21.844+0000] {subprocess.py:93} INFO - [0m09:54:21
[2025-04-24T09:54:21.855+0000] {subprocess.py:93} INFO - [0m09:54:21  1 of 4 START snapshot snapshots.snapshot_moving_averages ....................... [RUN]
[2025-04-24T09:54:23.347+0000] {subprocess.py:93} INFO - [0m09:54:23  1 of 4 ERROR snapshotting snapshots.snapshot_moving_averages ................... [[31mERROR[0m in 1.49s]
[2025-04-24T09:54:23.352+0000] {subprocess.py:93} INFO - [0m09:54:23  2 of 4 START snapshot snapshots.snapshot_rsi ................................... [RUN]
[2025-04-24T09:54:24.423+0000] {subprocess.py:93} INFO - [0m09:54:24  2 of 4 ERROR snapshotting snapshots.snapshot_rsi ............................... [[31mERROR[0m in 1.07s]
[2025-04-24T09:54:24.426+0000] {subprocess.py:93} INFO - [0m09:54:24  3 of 4 START snapshot snapshots.snapshot_stock_indicators ...................... [RUN]
[2025-04-24T09:54:25.261+0000] {subprocess.py:93} INFO - [0m09:54:25  3 of 4 ERROR snapshotting snapshots.snapshot_stock_indicators .................. [[31mERROR[0m in 0.83s]
[2025-04-24T09:54:25.264+0000] {subprocess.py:93} INFO - [0m09:54:25  4 of 4 START snapshot snapshots.snapshot_volume_summary ........................ [RUN]
[2025-04-24T09:54:25.907+0000] {subprocess.py:93} INFO - [0m09:54:25  4 of 4 ERROR snapshotting snapshots.snapshot_volume_summary .................... [[31mERROR[0m in 0.64s]
[2025-04-24T09:54:25.912+0000] {subprocess.py:93} INFO - [0m09:54:25
[2025-04-24T09:54:25.913+0000] {subprocess.py:93} INFO - [0m09:54:25  Finished running 4 snapshots in 0 hours 0 minutes and 6.17 seconds (6.17s).
[2025-04-24T09:54:26.008+0000] {subprocess.py:93} INFO - [0m09:54:26
[2025-04-24T09:54:26.009+0000] {subprocess.py:93} INFO - [0m09:54:26  [31mCompleted with 4 errors and 0 warnings:[0m
[2025-04-24T09:54:26.010+0000] {subprocess.py:93} INFO - [0m09:54:26
[2025-04-24T09:54:26.011+0000] {subprocess.py:93} INFO - [0m09:54:26    Database Error in snapshot snapshot_moving_averages (snapshots/snapshot_moving_average.sql)
[2025-04-24T09:54:26.012+0000] {subprocess.py:93} INFO -   000904 (42000): SQL compilation error: error line 30 at position 8
[2025-04-24T09:54:26.012+0000] {subprocess.py:93} INFO -   invalid identifier 'STOCK_ID'
[2025-04-24T09:54:26.013+0000] {subprocess.py:93} INFO - [0m09:54:26
[2025-04-24T09:54:26.014+0000] {subprocess.py:93} INFO - [0m09:54:26    Database Error in snapshot snapshot_rsi (snapshots/snapshot_rsi.sql)
[2025-04-24T09:54:26.015+0000] {subprocess.py:93} INFO -   000904 (42000): SQL compilation error: error line 37 at position 8
[2025-04-24T09:54:26.015+0000] {subprocess.py:93} INFO -   invalid identifier 'STOCK_ID'
[2025-04-24T09:54:26.016+0000] {subprocess.py:93} INFO - [0m09:54:26
[2025-04-24T09:54:26.017+0000] {subprocess.py:93} INFO - [0m09:54:26    Database Error in snapshot snapshot_stock_indicators (snapshots/snapshot_stock_indicators.sql)
[2025-04-24T09:54:26.018+0000] {subprocess.py:93} INFO -   000904 (42000): SQL compilation error: error line 29 at position 8
[2025-04-24T09:54:26.018+0000] {subprocess.py:93} INFO -   invalid identifier 'RSI_14D'
[2025-04-24T09:54:26.019+0000] {subprocess.py:93} INFO - [0m09:54:26
[2025-04-24T09:54:26.019+0000] {subprocess.py:93} INFO - [0m09:54:26    Database Error in snapshot snapshot_volume_summary (snapshots/snapshot_volume _summary.sql)
[2025-04-24T09:54:26.020+0000] {subprocess.py:93} INFO -   000904 (42000): SQL compilation error: error line 10 at position 4
[2025-04-24T09:54:26.021+0000] {subprocess.py:93} INFO -   invalid identifier 'TOTAL_VOLUME'
[2025-04-24T09:54:26.021+0000] {subprocess.py:93} INFO - [0m09:54:26
[2025-04-24T09:54:26.022+0000] {subprocess.py:93} INFO - [0m09:54:26  Done. PASS=0 WARN=0 ERROR=4 SKIP=0 TOTAL=4
[2025-04-24T09:54:26.912+0000] {subprocess.py:97} INFO - Command exited with return code 1
[2025-04-24T09:54:26.924+0000] {taskinstance.py:3310} ERROR - Task failed with exception
Traceback (most recent call last):
  File "/home/airflow/.local/lib/python3.12/site-packages/airflow/models/taskinstance.py", line 767, in _execute_task
    result = _execute_callable(context=context, **execute_callable_kwargs)
             ^^^^^^^^^^^^^^^^^^^^^^^^^^^^^^^^^^^^^^^^^^^^^^^^^^^^^^^^^^^^^
  File "/home/airflow/.local/lib/python3.12/site-packages/airflow/models/taskinstance.py", line 733, in _execute_callable
    return ExecutionCallableRunner(
           ^^^^^^^^^^^^^^^^^^^^^^^^
  File "/home/airflow/.local/lib/python3.12/site-packages/airflow/utils/operator_helpers.py", line 252, in run
    return self.func(*args, **kwargs)
           ^^^^^^^^^^^^^^^^^^^^^^^^^^
  File "/home/airflow/.local/lib/python3.12/site-packages/airflow/models/baseoperator.py", line 406, in wrapper
    return func(self, *args, **kwargs)
           ^^^^^^^^^^^^^^^^^^^^^^^^^^^
  File "/home/airflow/.local/lib/python3.12/site-packages/airflow/operators/bash.py", line 249, in execute
    raise AirflowException(
airflow.exceptions.AirflowException: Bash command failed. The command returned a non-zero exit code 1.
[2025-04-24T09:54:26.929+0000] {taskinstance.py:1225} INFO - Marking task as FAILED. dag_id=dbt_stock_project, task_id=dbt_snapshot, run_id=manual__2025-04-24T08:47:39.548491+00:00, execution_date=20250424T084739, start_date=20250424T095415, end_date=20250424T095426
[2025-04-24T09:54:26.944+0000] {taskinstance.py:340} INFO - ::group::Post task execution logs
[2025-04-24T09:54:26.946+0000] {standard_task_runner.py:124} ERROR - Failed to execute job 393 for task dbt_snapshot (Bash command failed. The command returned a non-zero exit code 1.; 9207)
Traceback (most recent call last):
  File "/home/airflow/.local/lib/python3.12/site-packages/airflow/task/task_runner/standard_task_runner.py", line 117, in _start_by_fork
    ret = args.func(args, dag=self.dag)
          ^^^^^^^^^^^^^^^^^^^^^^^^^^^^^
  File "/home/airflow/.local/lib/python3.12/site-packages/airflow/cli/cli_config.py", line 49, in command
    return func(*args, **kwargs)
           ^^^^^^^^^^^^^^^^^^^^^
  File "/home/airflow/.local/lib/python3.12/site-packages/airflow/utils/cli.py", line 115, in wrapper
    return f(*args, **kwargs)
           ^^^^^^^^^^^^^^^^^^
  File "/home/airflow/.local/lib/python3.12/site-packages/airflow/cli/commands/task_command.py", line 483, in task_run
    task_return_code = _run_task_by_selected_method(args, _dag, ti)
                       ^^^^^^^^^^^^^^^^^^^^^^^^^^^^^^^^^^^^^^^^^^^^
  File "/home/airflow/.local/lib/python3.12/site-packages/airflow/cli/commands/task_command.py", line 256, in _run_task_by_selected_method
    return _run_raw_task(args, ti)
           ^^^^^^^^^^^^^^^^^^^^^^^
  File "/home/airflow/.local/lib/python3.12/site-packages/airflow/cli/commands/task_command.py", line 341, in _run_raw_task
    return ti._run_raw_task(
           ^^^^^^^^^^^^^^^^^
  File "/home/airflow/.local/lib/python3.12/site-packages/airflow/utils/session.py", line 97, in wrapper
    return func(*args, session=session, **kwargs)
           ^^^^^^^^^^^^^^^^^^^^^^^^^^^^^^^^^^^^^^
  File "/home/airflow/.local/lib/python3.12/site-packages/airflow/models/taskinstance.py", line 3004, in _run_raw_task
    return _run_raw_task(
           ^^^^^^^^^^^^^^
  File "/home/airflow/.local/lib/python3.12/site-packages/airflow/models/taskinstance.py", line 273, in _run_raw_task
    TaskInstance._execute_task_with_callbacks(
  File "/home/airflow/.local/lib/python3.12/site-packages/airflow/models/taskinstance.py", line 3158, in _execute_task_with_callbacks
    result = self._execute_task(context, task_orig)
             ^^^^^^^^^^^^^^^^^^^^^^^^^^^^^^^^^^^^^^
  File "/home/airflow/.local/lib/python3.12/site-packages/airflow/models/taskinstance.py", line 3182, in _execute_task
    return _execute_task(self, context, task_orig)
           ^^^^^^^^^^^^^^^^^^^^^^^^^^^^^^^^^^^^^^^
  File "/home/airflow/.local/lib/python3.12/site-packages/airflow/models/taskinstance.py", line 767, in _execute_task
    result = _execute_callable(context=context, **execute_callable_kwargs)
             ^^^^^^^^^^^^^^^^^^^^^^^^^^^^^^^^^^^^^^^^^^^^^^^^^^^^^^^^^^^^^
  File "/home/airflow/.local/lib/python3.12/site-packages/airflow/models/taskinstance.py", line 733, in _execute_callable
    return ExecutionCallableRunner(
           ^^^^^^^^^^^^^^^^^^^^^^^^
  File "/home/airflow/.local/lib/python3.12/site-packages/airflow/utils/operator_helpers.py", line 252, in run
    return self.func(*args, **kwargs)
           ^^^^^^^^^^^^^^^^^^^^^^^^^^
  File "/home/airflow/.local/lib/python3.12/site-packages/airflow/models/baseoperator.py", line 406, in wrapper
    return func(self, *args, **kwargs)
           ^^^^^^^^^^^^^^^^^^^^^^^^^^^
  File "/home/airflow/.local/lib/python3.12/site-packages/airflow/operators/bash.py", line 249, in execute
    raise AirflowException(
airflow.exceptions.AirflowException: Bash command failed. The command returned a non-zero exit code 1.
[2025-04-24T09:54:26.964+0000] {local_task_job_runner.py:266} INFO - Task exited with return code 1
[2025-04-24T09:54:26.982+0000] {taskinstance.py:3900} INFO - 0 downstream tasks scheduled from follow-on schedule check
[2025-04-24T09:54:26.985+0000] {local_task_job_runner.py:245} INFO - ::endgroup::
