[2025-04-24T09:47:53.189+0000] {local_task_job_runner.py:123} INFO - ::group::Pre task execution logs
[2025-04-24T09:47:53.208+0000] {taskinstance.py:2612} INFO - Dependencies all met for dep_context=non-requeueable deps ti=<TaskInstance: dbt_stock_project.dbt_snapshot manual__2025-04-24T08:47:39.548491+00:00 [queued]>
[2025-04-24T09:47:53.217+0000] {taskinstance.py:2612} INFO - Dependencies all met for dep_context=requeueable deps ti=<TaskInstance: dbt_stock_project.dbt_snapshot manual__2025-04-24T08:47:39.548491+00:00 [queued]>
[2025-04-24T09:47:53.220+0000] {taskinstance.py:2865} INFO - Starting attempt 5 of 5
[2025-04-24T09:47:53.234+0000] {taskinstance.py:2888} INFO - Executing <Task(BashOperator): dbt_snapshot> on 2025-04-24 08:47:39.548491+00:00
[2025-04-24T09:47:53.244+0000] {logging_mixin.py:190} WARNING - /home/***/.local/lib/python3.12/site-packages/***/task/task_runner/standard_task_runner.py:70 DeprecationWarning: This process (pid=8904) is multi-threaded, use of fork() may lead to deadlocks in the child.
[2025-04-24T09:47:53.243+0000] {standard_task_runner.py:104} INFO - Running: ['***', 'tasks', 'run', 'dbt_stock_project', 'dbt_snapshot', 'manual__2025-04-24T08:47:39.548491+00:00', '--job-id', '391', '--raw', '--subdir', 'DAGS_FOLDER/226_lab2_elt.py', '--cfg-path', '/tmp/tmppp7doflf']
[2025-04-24T09:47:53.246+0000] {standard_task_runner.py:72} INFO - Started process 8905 to run task
[2025-04-24T09:47:53.247+0000] {standard_task_runner.py:105} INFO - Job 391: Subtask dbt_snapshot
[2025-04-24T09:47:53.304+0000] {task_command.py:467} INFO - Running <TaskInstance: dbt_stock_project.dbt_snapshot manual__2025-04-24T08:47:39.548491+00:00 [running]> on host e8b5346887eb
[2025-04-24T09:47:53.387+0000] {taskinstance.py:3131} INFO - Exporting env vars: AIRFLOW_CTX_DAG_OWNER='***' AIRFLOW_CTX_DAG_ID='dbt_stock_project' AIRFLOW_CTX_TASK_ID='dbt_snapshot' AIRFLOW_CTX_EXECUTION_DATE='2025-04-24T08:47:39.548491+00:00' AIRFLOW_CTX_TRY_NUMBER='5' AIRFLOW_CTX_DAG_RUN_ID='manual__2025-04-24T08:47:39.548491+00:00'
[2025-04-24T09:47:53.388+0000] {taskinstance.py:731} INFO - ::endgroup::
[2025-04-24T09:47:53.404+0000] {subprocess.py:63} INFO - Tmp dir root location: /tmp
[2025-04-24T09:47:53.408+0000] {subprocess.py:75} INFO - Running command: ['/usr/bin/bash', '-c', '/home/***/.local/bin/dbt snapshot --profiles-dir /home/***/.dbt --project-dir /opt/***/dbt']
[2025-04-24T09:47:53.418+0000] {subprocess.py:86} INFO - Output:
[2025-04-24T09:47:55.307+0000] {subprocess.py:93} INFO - [0m09:47:55  Running with dbt=1.8.7
[2025-04-24T09:47:56.257+0000] {subprocess.py:93} INFO - [0m09:47:56  Registered adapter: snowflake=1.8.1
[2025-04-24T09:47:57.312+0000] {subprocess.py:93} INFO - [0m09:47:57  Found 5 models, 10 data tests, 4 snapshots, 3 sources, 459 macros
[2025-04-24T09:47:57.316+0000] {subprocess.py:93} INFO - [0m09:47:57
[2025-04-24T09:47:59.500+0000] {subprocess.py:93} INFO - [0m09:47:59  Concurrency: 1 threads (target='dev')
[2025-04-24T09:47:59.502+0000] {subprocess.py:93} INFO - [0m09:47:59
[2025-04-24T09:47:59.515+0000] {subprocess.py:93} INFO - [0m09:47:59  1 of 4 START snapshot snapshots.snapshot_moving_averages ....................... [RUN]
[2025-04-24T09:48:00.588+0000] {subprocess.py:93} INFO - [0m09:48:00  1 of 4 ERROR snapshotting snapshots.snapshot_moving_averages ................... [[31mERROR[0m in 1.07s]
[2025-04-24T09:48:00.593+0000] {subprocess.py:93} INFO - [0m09:48:00  2 of 4 START snapshot snapshots.snapshot_rsi ................................... [RUN]
[2025-04-24T09:48:01.725+0000] {subprocess.py:93} INFO - [0m09:48:01  2 of 4 ERROR snapshotting snapshots.snapshot_rsi ............................... [[31mERROR[0m in 1.13s]
[2025-04-24T09:48:01.730+0000] {subprocess.py:93} INFO - [0m09:48:01  3 of 4 START snapshot snapshots.snapshot_stock_indicators ...................... [RUN]
[2025-04-24T09:48:02.294+0000] {subprocess.py:93} INFO - [0m09:48:02  3 of 4 ERROR snapshotting snapshots.snapshot_stock_indicators .................. [[31mERROR[0m in 0.56s]
[2025-04-24T09:48:02.298+0000] {subprocess.py:93} INFO - [0m09:48:02  4 of 4 START snapshot snapshots.snapshot_volume_summary ........................ [RUN]
[2025-04-24T09:48:03.300+0000] {subprocess.py:93} INFO - [0m09:48:03  4 of 4 ERROR snapshotting snapshots.snapshot_volume_summary .................... [[31mERROR[0m in 1.00s]
[2025-04-24T09:48:03.306+0000] {subprocess.py:93} INFO - [0m09:48:03
[2025-04-24T09:48:03.307+0000] {subprocess.py:93} INFO - [0m09:48:03  Finished running 4 snapshots in 0 hours 0 minutes and 5.99 seconds (5.99s).
[2025-04-24T09:48:03.420+0000] {subprocess.py:93} INFO - [0m09:48:03
[2025-04-24T09:48:03.421+0000] {subprocess.py:93} INFO - [0m09:48:03  [31mCompleted with 4 errors and 0 warnings:[0m
[2025-04-24T09:48:03.422+0000] {subprocess.py:93} INFO - [0m09:48:03
[2025-04-24T09:48:03.423+0000] {subprocess.py:93} INFO - [0m09:48:03    Database Error in snapshot snapshot_moving_averages (snapshots/snapshot_moving_average.sql)
[2025-04-24T09:48:03.424+0000] {subprocess.py:93} INFO -   000904 (42000): SQL compilation error: error line 27 at position 8
[2025-04-24T09:48:03.425+0000] {subprocess.py:93} INFO -   invalid identifier 'STOCK_ID'
[2025-04-24T09:48:03.426+0000] {subprocess.py:93} INFO - [0m09:48:03
[2025-04-24T09:48:03.427+0000] {subprocess.py:93} INFO - [0m09:48:03    Database Error in snapshot snapshot_rsi (snapshots/snapshot_rsi.sql)
[2025-04-24T09:48:03.428+0000] {subprocess.py:93} INFO -   000904 (42000): SQL compilation error: error line 37 at position 8
[2025-04-24T09:48:03.429+0000] {subprocess.py:93} INFO -   invalid identifier 'STOCK_ID'
[2025-04-24T09:48:03.430+0000] {subprocess.py:93} INFO - [0m09:48:03
[2025-04-24T09:48:03.431+0000] {subprocess.py:93} INFO - [0m09:48:03    Database Error in snapshot snapshot_stock_indicators (snapshots/snapshot_stock_indicators.sql)
[2025-04-24T09:48:03.431+0000] {subprocess.py:93} INFO -   000904 (42000): SQL compilation error: error line 29 at position 8
[2025-04-24T09:48:03.432+0000] {subprocess.py:93} INFO -   invalid identifier 'RSI_14D'
[2025-04-24T09:48:03.433+0000] {subprocess.py:93} INFO - [0m09:48:03
[2025-04-24T09:48:03.433+0000] {subprocess.py:93} INFO - [0m09:48:03    Database Error in snapshot snapshot_volume_summary (snapshots/snapshot_volume _summary.sql)
[2025-04-24T09:48:03.434+0000] {subprocess.py:93} INFO -   000904 (42000): SQL compilation error: error line 10 at position 4
[2025-04-24T09:48:03.436+0000] {subprocess.py:93} INFO -   invalid identifier 'TOTAL_VOLUME'
[2025-04-24T09:48:03.437+0000] {subprocess.py:93} INFO - [0m09:48:03
[2025-04-24T09:48:03.437+0000] {subprocess.py:93} INFO - [0m09:48:03  Done. PASS=0 WARN=0 ERROR=4 SKIP=0 TOTAL=4
[2025-04-24T09:48:04.321+0000] {subprocess.py:97} INFO - Command exited with return code 1
[2025-04-24T09:48:04.331+0000] {taskinstance.py:3310} ERROR - Task failed with exception
Traceback (most recent call last):
  File "/home/airflow/.local/lib/python3.12/site-packages/airflow/models/taskinstance.py", line 767, in _execute_task
    result = _execute_callable(context=context, **execute_callable_kwargs)
             ^^^^^^^^^^^^^^^^^^^^^^^^^^^^^^^^^^^^^^^^^^^^^^^^^^^^^^^^^^^^^
  File "/home/airflow/.local/lib/python3.12/site-packages/airflow/models/taskinstance.py", line 733, in _execute_callable
    return ExecutionCallableRunner(
           ^^^^^^^^^^^^^^^^^^^^^^^^
  File "/home/airflow/.local/lib/python3.12/site-packages/airflow/utils/operator_helpers.py", line 252, in run
    return self.func(*args, **kwargs)
           ^^^^^^^^^^^^^^^^^^^^^^^^^^
  File "/home/airflow/.local/lib/python3.12/site-packages/airflow/models/baseoperator.py", line 406, in wrapper
    return func(self, *args, **kwargs)
           ^^^^^^^^^^^^^^^^^^^^^^^^^^^
  File "/home/airflow/.local/lib/python3.12/site-packages/airflow/operators/bash.py", line 249, in execute
    raise AirflowException(
airflow.exceptions.AirflowException: Bash command failed. The command returned a non-zero exit code 1.
[2025-04-24T09:48:04.337+0000] {taskinstance.py:1225} INFO - Marking task as FAILED. dag_id=dbt_stock_project, task_id=dbt_snapshot, run_id=manual__2025-04-24T08:47:39.548491+00:00, execution_date=20250424T084739, start_date=20250424T094753, end_date=20250424T094804
[2025-04-24T09:48:04.353+0000] {taskinstance.py:340} INFO - ::group::Post task execution logs
[2025-04-24T09:48:04.354+0000] {standard_task_runner.py:124} ERROR - Failed to execute job 391 for task dbt_snapshot (Bash command failed. The command returned a non-zero exit code 1.; 8905)
Traceback (most recent call last):
  File "/home/airflow/.local/lib/python3.12/site-packages/airflow/task/task_runner/standard_task_runner.py", line 117, in _start_by_fork
    ret = args.func(args, dag=self.dag)
          ^^^^^^^^^^^^^^^^^^^^^^^^^^^^^
  File "/home/airflow/.local/lib/python3.12/site-packages/airflow/cli/cli_config.py", line 49, in command
    return func(*args, **kwargs)
           ^^^^^^^^^^^^^^^^^^^^^
  File "/home/airflow/.local/lib/python3.12/site-packages/airflow/utils/cli.py", line 115, in wrapper
    return f(*args, **kwargs)
           ^^^^^^^^^^^^^^^^^^
  File "/home/airflow/.local/lib/python3.12/site-packages/airflow/cli/commands/task_command.py", line 483, in task_run
    task_return_code = _run_task_by_selected_method(args, _dag, ti)
                       ^^^^^^^^^^^^^^^^^^^^^^^^^^^^^^^^^^^^^^^^^^^^
  File "/home/airflow/.local/lib/python3.12/site-packages/airflow/cli/commands/task_command.py", line 256, in _run_task_by_selected_method
    return _run_raw_task(args, ti)
           ^^^^^^^^^^^^^^^^^^^^^^^
  File "/home/airflow/.local/lib/python3.12/site-packages/airflow/cli/commands/task_command.py", line 341, in _run_raw_task
    return ti._run_raw_task(
           ^^^^^^^^^^^^^^^^^
  File "/home/airflow/.local/lib/python3.12/site-packages/airflow/utils/session.py", line 97, in wrapper
    return func(*args, session=session, **kwargs)
           ^^^^^^^^^^^^^^^^^^^^^^^^^^^^^^^^^^^^^^
  File "/home/airflow/.local/lib/python3.12/site-packages/airflow/models/taskinstance.py", line 3004, in _run_raw_task
    return _run_raw_task(
           ^^^^^^^^^^^^^^
  File "/home/airflow/.local/lib/python3.12/site-packages/airflow/models/taskinstance.py", line 273, in _run_raw_task
    TaskInstance._execute_task_with_callbacks(
  File "/home/airflow/.local/lib/python3.12/site-packages/airflow/models/taskinstance.py", line 3158, in _execute_task_with_callbacks
    result = self._execute_task(context, task_orig)
             ^^^^^^^^^^^^^^^^^^^^^^^^^^^^^^^^^^^^^^
  File "/home/airflow/.local/lib/python3.12/site-packages/airflow/models/taskinstance.py", line 3182, in _execute_task
    return _execute_task(self, context, task_orig)
           ^^^^^^^^^^^^^^^^^^^^^^^^^^^^^^^^^^^^^^^
  File "/home/airflow/.local/lib/python3.12/site-packages/airflow/models/taskinstance.py", line 767, in _execute_task
    result = _execute_callable(context=context, **execute_callable_kwargs)
             ^^^^^^^^^^^^^^^^^^^^^^^^^^^^^^^^^^^^^^^^^^^^^^^^^^^^^^^^^^^^^
  File "/home/airflow/.local/lib/python3.12/site-packages/airflow/models/taskinstance.py", line 733, in _execute_callable
    return ExecutionCallableRunner(
           ^^^^^^^^^^^^^^^^^^^^^^^^
  File "/home/airflow/.local/lib/python3.12/site-packages/airflow/utils/operator_helpers.py", line 252, in run
    return self.func(*args, **kwargs)
           ^^^^^^^^^^^^^^^^^^^^^^^^^^
  File "/home/airflow/.local/lib/python3.12/site-packages/airflow/models/baseoperator.py", line 406, in wrapper
    return func(self, *args, **kwargs)
           ^^^^^^^^^^^^^^^^^^^^^^^^^^^
  File "/home/airflow/.local/lib/python3.12/site-packages/airflow/operators/bash.py", line 249, in execute
    raise AirflowException(
airflow.exceptions.AirflowException: Bash command failed. The command returned a non-zero exit code 1.
[2025-04-24T09:48:04.364+0000] {local_task_job_runner.py:266} INFO - Task exited with return code 1
[2025-04-24T09:48:04.377+0000] {taskinstance.py:3900} INFO - 0 downstream tasks scheduled from follow-on schedule check
[2025-04-24T09:48:04.382+0000] {local_task_job_runner.py:245} INFO - ::endgroup::
