[2025-04-24T08:48:09.142+0000] {local_task_job_runner.py:123} INFO - ::group::Pre task execution logs
[2025-04-24T08:48:09.162+0000] {taskinstance.py:2612} INFO - Dependencies all met for dep_context=non-requeueable deps ti=<TaskInstance: dbt_stock_project.dbt_snapshot manual__2025-04-24T08:47:39.548491+00:00 [queued]>
[2025-04-24T08:48:09.173+0000] {taskinstance.py:2612} INFO - Dependencies all met for dep_context=requeueable deps ti=<TaskInstance: dbt_stock_project.dbt_snapshot manual__2025-04-24T08:47:39.548491+00:00 [queued]>
[2025-04-24T08:48:09.176+0000] {taskinstance.py:2865} INFO - Starting attempt 1 of 1
[2025-04-24T08:48:09.192+0000] {taskinstance.py:2888} INFO - Executing <Task(BashOperator): dbt_snapshot> on 2025-04-24 08:47:39.548491+00:00
[2025-04-24T08:48:09.203+0000] {logging_mixin.py:190} WARNING - /home/***/.local/lib/python3.12/site-packages/***/task/task_runner/standard_task_runner.py:70 DeprecationWarning: This process (pid=6332) is multi-threaded, use of fork() may lead to deadlocks in the child.
[2025-04-24T08:48:09.202+0000] {standard_task_runner.py:104} INFO - Running: ['***', 'tasks', 'run', 'dbt_stock_project', 'dbt_snapshot', 'manual__2025-04-24T08:47:39.548491+00:00', '--job-id', '387', '--raw', '--subdir', 'DAGS_FOLDER/226_lab2_elt.py', '--cfg-path', '/tmp/tmp21uct3a8']
[2025-04-24T08:48:09.205+0000] {standard_task_runner.py:72} INFO - Started process 6333 to run task
[2025-04-24T08:48:09.206+0000] {standard_task_runner.py:105} INFO - Job 387: Subtask dbt_snapshot
[2025-04-24T08:48:09.261+0000] {task_command.py:467} INFO - Running <TaskInstance: dbt_stock_project.dbt_snapshot manual__2025-04-24T08:47:39.548491+00:00 [running]> on host e8b5346887eb
[2025-04-24T08:48:09.343+0000] {taskinstance.py:3131} INFO - Exporting env vars: AIRFLOW_CTX_DAG_OWNER='***' AIRFLOW_CTX_DAG_ID='dbt_stock_project' AIRFLOW_CTX_TASK_ID='dbt_snapshot' AIRFLOW_CTX_EXECUTION_DATE='2025-04-24T08:47:39.548491+00:00' AIRFLOW_CTX_TRY_NUMBER='1' AIRFLOW_CTX_DAG_RUN_ID='manual__2025-04-24T08:47:39.548491+00:00'
[2025-04-24T08:48:09.345+0000] {taskinstance.py:731} INFO - ::endgroup::
[2025-04-24T08:48:09.358+0000] {subprocess.py:63} INFO - Tmp dir root location: /tmp
[2025-04-24T08:48:09.361+0000] {subprocess.py:75} INFO - Running command: ['/usr/bin/bash', '-c', '/home/***/.local/bin/dbt snapshot --profiles-dir /home/***/.dbt --project-dir /opt/***/dbt']
[2025-04-24T08:48:09.370+0000] {subprocess.py:86} INFO - Output:
[2025-04-24T08:48:11.244+0000] {subprocess.py:93} INFO - [0m08:48:11  Running with dbt=1.8.7
[2025-04-24T08:48:12.330+0000] {subprocess.py:93} INFO - [0m08:48:12  Registered adapter: snowflake=1.8.1
[2025-04-24T08:48:13.239+0000] {subprocess.py:93} INFO - [0m08:48:13  Found 5 models, 10 data tests, 4 snapshots, 3 sources, 459 macros
[2025-04-24T08:48:13.243+0000] {subprocess.py:93} INFO - [0m08:48:13
[2025-04-24T08:48:15.415+0000] {subprocess.py:93} INFO - [0m08:48:15  Concurrency: 1 threads (target='dev')
[2025-04-24T08:48:15.415+0000] {subprocess.py:93} INFO - [0m08:48:15
[2025-04-24T08:48:15.426+0000] {subprocess.py:93} INFO - [0m08:48:15  1 of 4 START snapshot snapshots.snapshot_moving_averages ....................... [RUN]
[2025-04-24T09:13:45.134+0000] {subprocess.py:93} INFO - [0m09:13:45  1 of 4 ERROR snapshotting snapshots.snapshot_moving_averages ................... [[31mERROR[0m in 1529.70s]
[2025-04-24T09:13:45.138+0000] {subprocess.py:93} INFO - [0m09:13:45  2 of 4 START snapshot snapshots.snapshot_rsi ................................... [RUN]
[2025-04-24T09:27:31.417+0000] {subprocess.py:93} INFO - [0m09:27:31  2 of 4 ERROR snapshotting snapshots.snapshot_rsi ............................... [[31mERROR[0m in 826.27s]
[2025-04-24T09:27:31.422+0000] {subprocess.py:93} INFO - [0m09:27:31  3 of 4 START snapshot snapshots.snapshot_stock_indicators ...................... [RUN]
[2025-04-24T09:27:32.137+0000] {subprocess.py:93} INFO - [0m09:27:32  3 of 4 ERROR snapshotting snapshots.snapshot_stock_indicators .................. [[31mERROR[0m in 0.71s]
[2025-04-24T09:27:32.141+0000] {subprocess.py:93} INFO - [0m09:27:32  4 of 4 START snapshot snapshots.snapshot_volume_summary ........................ [RUN]
[2025-04-24T09:27:33.936+0000] {subprocess.py:93} INFO - [0m09:27:33  4 of 4 OK snapshotted snapshots.snapshot_volume_summary ........................ [[32mSUCCESS 1[0m in 1.79s]
[2025-04-24T09:27:33.948+0000] {subprocess.py:93} INFO - [0m09:27:33
[2025-04-24T09:27:33.949+0000] {subprocess.py:93} INFO - [0m09:27:33  Finished running 4 snapshots in 0 hours 39 minutes and 20.70 seconds (2360.70s).
[2025-04-24T09:27:34.084+0000] {subprocess.py:93} INFO - [0m09:27:34
[2025-04-24T09:27:34.085+0000] {subprocess.py:93} INFO - [0m09:27:34  [31mCompleted with 3 errors and 0 warnings:[0m
[2025-04-24T09:27:34.087+0000] {subprocess.py:93} INFO - [0m09:27:34
[2025-04-24T09:27:34.088+0000] {subprocess.py:93} INFO - [0m09:27:34    Database Error in snapshot snapshot_moving_averages (snapshots/snapshot_moving_average.sql)
[2025-04-24T09:27:34.089+0000] {subprocess.py:93} INFO -   100090 (42P18): Duplicate row detected during DML action
[2025-04-24T09:27:34.090+0000] {subprocess.py:93} INFO -   Row Values: [redacted]
[2025-04-24T09:27:34.091+0000] {subprocess.py:93} INFO -   compiled code at target/run/dbt_stock_project/snapshots/snapshot_moving_average.sql
[2025-04-24T09:27:34.093+0000] {subprocess.py:93} INFO - [0m09:27:34
[2025-04-24T09:27:34.094+0000] {subprocess.py:93} INFO - [0m09:27:34    Database Error in snapshot snapshot_rsi (snapshots/snapshot_rsi.sql)
[2025-04-24T09:27:34.095+0000] {subprocess.py:93} INFO -   100090 (42P18): Duplicate row detected during DML action
[2025-04-24T09:27:34.096+0000] {subprocess.py:93} INFO -   Row Values: [redacted]
[2025-04-24T09:27:34.097+0000] {subprocess.py:93} INFO -   compiled code at target/run/dbt_stock_project/snapshots/snapshot_rsi.sql
[2025-04-24T09:27:34.098+0000] {subprocess.py:93} INFO - [0m09:27:34
[2025-04-24T09:27:34.099+0000] {subprocess.py:93} INFO - [0m09:27:34    Database Error in snapshot snapshot_stock_indicators (snapshots/snapshot_stock_indicators.sql)
[2025-04-24T09:27:34.101+0000] {subprocess.py:93} INFO -   000904 (42000): SQL compilation error: error line 24 at position 2
[2025-04-24T09:27:34.101+0000] {subprocess.py:93} INFO -   invalid identifier 'RSI_14D'
[2025-04-24T09:27:34.102+0000] {subprocess.py:93} INFO - [0m09:27:34
[2025-04-24T09:27:34.104+0000] {subprocess.py:93} INFO - [0m09:27:34  Done. PASS=1 WARN=0 ERROR=3 SKIP=0 TOTAL=4
[2025-04-24T09:27:35.317+0000] {subprocess.py:97} INFO - Command exited with return code 1
[2025-04-24T09:27:35.366+0000] {taskinstance.py:3310} ERROR - Task failed with exception
Traceback (most recent call last):
  File "/home/airflow/.local/lib/python3.12/site-packages/airflow/models/taskinstance.py", line 767, in _execute_task
    result = _execute_callable(context=context, **execute_callable_kwargs)
             ^^^^^^^^^^^^^^^^^^^^^^^^^^^^^^^^^^^^^^^^^^^^^^^^^^^^^^^^^^^^^
  File "/home/airflow/.local/lib/python3.12/site-packages/airflow/models/taskinstance.py", line 733, in _execute_callable
    return ExecutionCallableRunner(
           ^^^^^^^^^^^^^^^^^^^^^^^^
  File "/home/airflow/.local/lib/python3.12/site-packages/airflow/utils/operator_helpers.py", line 252, in run
    return self.func(*args, **kwargs)
           ^^^^^^^^^^^^^^^^^^^^^^^^^^
  File "/home/airflow/.local/lib/python3.12/site-packages/airflow/models/baseoperator.py", line 406, in wrapper
    return func(self, *args, **kwargs)
           ^^^^^^^^^^^^^^^^^^^^^^^^^^^
  File "/home/airflow/.local/lib/python3.12/site-packages/airflow/operators/bash.py", line 249, in execute
    raise AirflowException(
airflow.exceptions.AirflowException: Bash command failed. The command returned a non-zero exit code 1.
[2025-04-24T09:27:35.381+0000] {taskinstance.py:1225} INFO - Marking task as FAILED. dag_id=dbt_stock_project, task_id=dbt_snapshot, run_id=manual__2025-04-24T08:47:39.548491+00:00, execution_date=20250424T084739, start_date=20250424T084809, end_date=20250424T092735
[2025-04-24T09:27:35.412+0000] {taskinstance.py:340} INFO - ::group::Post task execution logs
[2025-04-24T09:27:35.415+0000] {standard_task_runner.py:124} ERROR - Failed to execute job 387 for task dbt_snapshot (Bash command failed. The command returned a non-zero exit code 1.; 6333)
Traceback (most recent call last):
  File "/home/airflow/.local/lib/python3.12/site-packages/airflow/task/task_runner/standard_task_runner.py", line 117, in _start_by_fork
    ret = args.func(args, dag=self.dag)
          ^^^^^^^^^^^^^^^^^^^^^^^^^^^^^
  File "/home/airflow/.local/lib/python3.12/site-packages/airflow/cli/cli_config.py", line 49, in command
    return func(*args, **kwargs)
           ^^^^^^^^^^^^^^^^^^^^^
  File "/home/airflow/.local/lib/python3.12/site-packages/airflow/utils/cli.py", line 115, in wrapper
    return f(*args, **kwargs)
           ^^^^^^^^^^^^^^^^^^
  File "/home/airflow/.local/lib/python3.12/site-packages/airflow/cli/commands/task_command.py", line 483, in task_run
    task_return_code = _run_task_by_selected_method(args, _dag, ti)
                       ^^^^^^^^^^^^^^^^^^^^^^^^^^^^^^^^^^^^^^^^^^^^
  File "/home/airflow/.local/lib/python3.12/site-packages/airflow/cli/commands/task_command.py", line 256, in _run_task_by_selected_method
    return _run_raw_task(args, ti)
           ^^^^^^^^^^^^^^^^^^^^^^^
  File "/home/airflow/.local/lib/python3.12/site-packages/airflow/cli/commands/task_command.py", line 341, in _run_raw_task
    return ti._run_raw_task(
           ^^^^^^^^^^^^^^^^^
  File "/home/airflow/.local/lib/python3.12/site-packages/airflow/utils/session.py", line 97, in wrapper
    return func(*args, session=session, **kwargs)
           ^^^^^^^^^^^^^^^^^^^^^^^^^^^^^^^^^^^^^^
  File "/home/airflow/.local/lib/python3.12/site-packages/airflow/models/taskinstance.py", line 3004, in _run_raw_task
    return _run_raw_task(
           ^^^^^^^^^^^^^^
  File "/home/airflow/.local/lib/python3.12/site-packages/airflow/models/taskinstance.py", line 273, in _run_raw_task
    TaskInstance._execute_task_with_callbacks(
  File "/home/airflow/.local/lib/python3.12/site-packages/airflow/models/taskinstance.py", line 3158, in _execute_task_with_callbacks
    result = self._execute_task(context, task_orig)
             ^^^^^^^^^^^^^^^^^^^^^^^^^^^^^^^^^^^^^^
  File "/home/airflow/.local/lib/python3.12/site-packages/airflow/models/taskinstance.py", line 3182, in _execute_task
    return _execute_task(self, context, task_orig)
           ^^^^^^^^^^^^^^^^^^^^^^^^^^^^^^^^^^^^^^^
  File "/home/airflow/.local/lib/python3.12/site-packages/airflow/models/taskinstance.py", line 767, in _execute_task
    result = _execute_callable(context=context, **execute_callable_kwargs)
             ^^^^^^^^^^^^^^^^^^^^^^^^^^^^^^^^^^^^^^^^^^^^^^^^^^^^^^^^^^^^^
  File "/home/airflow/.local/lib/python3.12/site-packages/airflow/models/taskinstance.py", line 733, in _execute_callable
    return ExecutionCallableRunner(
           ^^^^^^^^^^^^^^^^^^^^^^^^
  File "/home/airflow/.local/lib/python3.12/site-packages/airflow/utils/operator_helpers.py", line 252, in run
    return self.func(*args, **kwargs)
           ^^^^^^^^^^^^^^^^^^^^^^^^^^
  File "/home/airflow/.local/lib/python3.12/site-packages/airflow/models/baseoperator.py", line 406, in wrapper
    return func(self, *args, **kwargs)
           ^^^^^^^^^^^^^^^^^^^^^^^^^^^
  File "/home/airflow/.local/lib/python3.12/site-packages/airflow/operators/bash.py", line 249, in execute
    raise AirflowException(
airflow.exceptions.AirflowException: Bash command failed. The command returned a non-zero exit code 1.
[2025-04-24T09:27:35.465+0000] {local_task_job_runner.py:266} INFO - Task exited with return code 1
[2025-04-24T09:27:35.497+0000] {taskinstance.py:3900} INFO - 0 downstream tasks scheduled from follow-on schedule check
[2025-04-24T09:27:35.501+0000] {local_task_job_runner.py:245} INFO - ::endgroup::
