[2025-04-24T09:38:34.990+0000] {local_task_job_runner.py:123} INFO - ::group::Pre task execution logs
[2025-04-24T09:38:35.010+0000] {taskinstance.py:2612} INFO - Dependencies all met for dep_context=non-requeueable deps ti=<TaskInstance: dbt_stock_project.dbt_snapshot manual__2025-04-24T08:47:39.548491+00:00 [queued]>
[2025-04-24T09:38:35.022+0000] {taskinstance.py:2612} INFO - Dependencies all met for dep_context=requeueable deps ti=<TaskInstance: dbt_stock_project.dbt_snapshot manual__2025-04-24T08:47:39.548491+00:00 [queued]>
[2025-04-24T09:38:35.024+0000] {taskinstance.py:2865} INFO - Starting attempt 2 of 2
[2025-04-24T09:38:35.039+0000] {taskinstance.py:2888} INFO - Executing <Task(BashOperator): dbt_snapshot> on 2025-04-24 08:47:39.548491+00:00
[2025-04-24T09:38:35.048+0000] {standard_task_runner.py:104} INFO - Running: ['***', 'tasks', 'run', 'dbt_stock_project', 'dbt_snapshot', 'manual__2025-04-24T08:47:39.548491+00:00', '--job-id', '388', '--raw', '--subdir', 'DAGS_FOLDER/226_lab2_elt.py', '--cfg-path', '/tmp/tmpid6bbdjt']
[2025-04-24T09:38:35.051+0000] {logging_mixin.py:190} WARNING - /home/***/.local/lib/python3.12/site-packages/***/task/task_runner/standard_task_runner.py:70 DeprecationWarning: This process (pid=8436) is multi-threaded, use of fork() may lead to deadlocks in the child.
[2025-04-24T09:38:35.052+0000] {standard_task_runner.py:105} INFO - Job 388: Subtask dbt_snapshot
[2025-04-24T09:38:35.052+0000] {standard_task_runner.py:72} INFO - Started process 8437 to run task
[2025-04-24T09:38:35.104+0000] {task_command.py:467} INFO - Running <TaskInstance: dbt_stock_project.dbt_snapshot manual__2025-04-24T08:47:39.548491+00:00 [running]> on host e8b5346887eb
[2025-04-24T09:38:35.197+0000] {taskinstance.py:3131} INFO - Exporting env vars: AIRFLOW_CTX_DAG_OWNER='***' AIRFLOW_CTX_DAG_ID='dbt_stock_project' AIRFLOW_CTX_TASK_ID='dbt_snapshot' AIRFLOW_CTX_EXECUTION_DATE='2025-04-24T08:47:39.548491+00:00' AIRFLOW_CTX_TRY_NUMBER='2' AIRFLOW_CTX_DAG_RUN_ID='manual__2025-04-24T08:47:39.548491+00:00'
[2025-04-24T09:38:35.198+0000] {taskinstance.py:731} INFO - ::endgroup::
[2025-04-24T09:38:35.230+0000] {subprocess.py:63} INFO - Tmp dir root location: /tmp
[2025-04-24T09:38:35.232+0000] {subprocess.py:75} INFO - Running command: ['/usr/bin/bash', '-c', '/home/***/.local/bin/dbt snapshot --profiles-dir /home/***/.dbt --project-dir /opt/***/dbt']
[2025-04-24T09:38:35.242+0000] {subprocess.py:86} INFO - Output:
[2025-04-24T09:38:38.151+0000] {subprocess.py:93} INFO - [0m09:38:38  Running with dbt=1.8.7
[2025-04-24T09:38:39.830+0000] {subprocess.py:93} INFO - [0m09:38:39  Registered adapter: snowflake=1.8.1
[2025-04-24T09:38:41.035+0000] {subprocess.py:93} INFO - [0m09:38:41  Found 5 models, 10 data tests, 4 snapshots, 3 sources, 459 macros
[2025-04-24T09:38:41.039+0000] {subprocess.py:93} INFO - [0m09:38:41
[2025-04-24T09:38:43.255+0000] {subprocess.py:93} INFO - [0m09:38:43  Concurrency: 1 threads (target='dev')
[2025-04-24T09:38:43.256+0000] {subprocess.py:93} INFO - [0m09:38:43
[2025-04-24T09:38:43.267+0000] {subprocess.py:93} INFO - [0m09:38:43  1 of 4 START snapshot snapshots.snapshot_moving_averages ....................... [RUN]
[2025-04-24T09:38:43.901+0000] {subprocess.py:93} INFO - [0m09:38:43  1 of 4 ERROR snapshotting snapshots.snapshot_moving_averages ................... [[31mERROR[0m in 0.63s]
[2025-04-24T09:38:43.905+0000] {subprocess.py:93} INFO - [0m09:38:43  2 of 4 START snapshot snapshots.snapshot_rsi ................................... [RUN]
[2025-04-24T09:38:45.656+0000] {subprocess.py:93} INFO - [0m09:38:45  2 of 4 ERROR snapshotting snapshots.snapshot_rsi ............................... [[31mERROR[0m in 1.75s]
[2025-04-24T09:38:45.659+0000] {subprocess.py:93} INFO - [0m09:38:45  3 of 4 START snapshot snapshots.snapshot_stock_indicators ...................... [RUN]
[2025-04-24T09:38:46.346+0000] {subprocess.py:93} INFO - [0m09:38:46  3 of 4 ERROR snapshotting snapshots.snapshot_stock_indicators .................. [[31mERROR[0m in 0.68s]
[2025-04-24T09:38:46.349+0000] {subprocess.py:93} INFO - [0m09:38:46  4 of 4 START snapshot snapshots.snapshot_volume_summary ........................ [RUN]
[2025-04-24T09:38:46.945+0000] {subprocess.py:93} INFO - [0m09:38:46  4 of 4 ERROR snapshotting snapshots.snapshot_volume_summary .................... [[31mERROR[0m in 0.59s]
[2025-04-24T09:38:46.952+0000] {subprocess.py:93} INFO - [0m09:38:46
[2025-04-24T09:38:46.953+0000] {subprocess.py:93} INFO - [0m09:38:46  Finished running 4 snapshots in 0 hours 0 minutes and 5.91 seconds (5.91s).
[2025-04-24T09:38:47.059+0000] {subprocess.py:93} INFO - [0m09:38:47
[2025-04-24T09:38:47.059+0000] {subprocess.py:93} INFO - [0m09:38:47  [31mCompleted with 4 errors and 0 warnings:[0m
[2025-04-24T09:38:47.060+0000] {subprocess.py:93} INFO - [0m09:38:47
[2025-04-24T09:38:47.061+0000] {subprocess.py:93} INFO - [0m09:38:47    Database Error in snapshot snapshot_moving_averages (snapshots/snapshot_moving_average.sql)
[2025-04-24T09:38:47.061+0000] {subprocess.py:93} INFO -   000904 (42000): SQL compilation error: error line 10 at position 4
[2025-04-24T09:38:47.062+0000] {subprocess.py:93} INFO -   invalid identifier 'MOVING_AVG_7'
[2025-04-24T09:38:47.064+0000] {subprocess.py:93} INFO - [0m09:38:47
[2025-04-24T09:38:47.065+0000] {subprocess.py:93} INFO - [0m09:38:47    Database Error in snapshot snapshot_rsi (snapshots/snapshot_rsi.sql)
[2025-04-24T09:38:47.066+0000] {subprocess.py:93} INFO -   000904 (42000): SQL compilation error: error line 37 at position 8
[2025-04-24T09:38:47.067+0000] {subprocess.py:93} INFO -   invalid identifier 'STOCK_ID'
[2025-04-24T09:38:47.067+0000] {subprocess.py:93} INFO - [0m09:38:47
[2025-04-24T09:38:47.068+0000] {subprocess.py:93} INFO - [0m09:38:47    Database Error in snapshot snapshot_stock_indicators (snapshots/snapshot_stock_indicators.sql)
[2025-04-24T09:38:47.069+0000] {subprocess.py:93} INFO -   000904 (42000): SQL compilation error: error line 29 at position 8
[2025-04-24T09:38:47.069+0000] {subprocess.py:93} INFO -   invalid identifier 'RSI_14D'
[2025-04-24T09:38:47.070+0000] {subprocess.py:93} INFO - [0m09:38:47
[2025-04-24T09:38:47.071+0000] {subprocess.py:93} INFO - [0m09:38:47    Database Error in snapshot snapshot_volume_summary (snapshots/snapshot_volume _summary.sql)
[2025-04-24T09:38:47.072+0000] {subprocess.py:93} INFO -   000904 (42000): SQL compilation error: error line 10 at position 4
[2025-04-24T09:38:47.072+0000] {subprocess.py:93} INFO -   invalid identifier 'TOTAL_VOLUME'
[2025-04-24T09:38:47.073+0000] {subprocess.py:93} INFO - [0m09:38:47
[2025-04-24T09:38:47.074+0000] {subprocess.py:93} INFO - [0m09:38:47  Done. PASS=0 WARN=0 ERROR=4 SKIP=0 TOTAL=4
[2025-04-24T09:38:48.074+0000] {subprocess.py:97} INFO - Command exited with return code 1
[2025-04-24T09:38:48.085+0000] {taskinstance.py:3310} ERROR - Task failed with exception
Traceback (most recent call last):
  File "/home/airflow/.local/lib/python3.12/site-packages/airflow/models/taskinstance.py", line 767, in _execute_task
    result = _execute_callable(context=context, **execute_callable_kwargs)
             ^^^^^^^^^^^^^^^^^^^^^^^^^^^^^^^^^^^^^^^^^^^^^^^^^^^^^^^^^^^^^
  File "/home/airflow/.local/lib/python3.12/site-packages/airflow/models/taskinstance.py", line 733, in _execute_callable
    return ExecutionCallableRunner(
           ^^^^^^^^^^^^^^^^^^^^^^^^
  File "/home/airflow/.local/lib/python3.12/site-packages/airflow/utils/operator_helpers.py", line 252, in run
    return self.func(*args, **kwargs)
           ^^^^^^^^^^^^^^^^^^^^^^^^^^
  File "/home/airflow/.local/lib/python3.12/site-packages/airflow/models/baseoperator.py", line 406, in wrapper
    return func(self, *args, **kwargs)
           ^^^^^^^^^^^^^^^^^^^^^^^^^^^
  File "/home/airflow/.local/lib/python3.12/site-packages/airflow/operators/bash.py", line 249, in execute
    raise AirflowException(
airflow.exceptions.AirflowException: Bash command failed. The command returned a non-zero exit code 1.
[2025-04-24T09:38:48.093+0000] {taskinstance.py:1225} INFO - Marking task as FAILED. dag_id=dbt_stock_project, task_id=dbt_snapshot, run_id=manual__2025-04-24T08:47:39.548491+00:00, execution_date=20250424T084739, start_date=20250424T093835, end_date=20250424T093848
[2025-04-24T09:38:48.106+0000] {taskinstance.py:340} INFO - ::group::Post task execution logs
[2025-04-24T09:38:48.107+0000] {standard_task_runner.py:124} ERROR - Failed to execute job 388 for task dbt_snapshot (Bash command failed. The command returned a non-zero exit code 1.; 8437)
Traceback (most recent call last):
  File "/home/airflow/.local/lib/python3.12/site-packages/airflow/task/task_runner/standard_task_runner.py", line 117, in _start_by_fork
    ret = args.func(args, dag=self.dag)
          ^^^^^^^^^^^^^^^^^^^^^^^^^^^^^
  File "/home/airflow/.local/lib/python3.12/site-packages/airflow/cli/cli_config.py", line 49, in command
    return func(*args, **kwargs)
           ^^^^^^^^^^^^^^^^^^^^^
  File "/home/airflow/.local/lib/python3.12/site-packages/airflow/utils/cli.py", line 115, in wrapper
    return f(*args, **kwargs)
           ^^^^^^^^^^^^^^^^^^
  File "/home/airflow/.local/lib/python3.12/site-packages/airflow/cli/commands/task_command.py", line 483, in task_run
    task_return_code = _run_task_by_selected_method(args, _dag, ti)
                       ^^^^^^^^^^^^^^^^^^^^^^^^^^^^^^^^^^^^^^^^^^^^
  File "/home/airflow/.local/lib/python3.12/site-packages/airflow/cli/commands/task_command.py", line 256, in _run_task_by_selected_method
    return _run_raw_task(args, ti)
           ^^^^^^^^^^^^^^^^^^^^^^^
  File "/home/airflow/.local/lib/python3.12/site-packages/airflow/cli/commands/task_command.py", line 341, in _run_raw_task
    return ti._run_raw_task(
           ^^^^^^^^^^^^^^^^^
  File "/home/airflow/.local/lib/python3.12/site-packages/airflow/utils/session.py", line 97, in wrapper
    return func(*args, session=session, **kwargs)
           ^^^^^^^^^^^^^^^^^^^^^^^^^^^^^^^^^^^^^^
  File "/home/airflow/.local/lib/python3.12/site-packages/airflow/models/taskinstance.py", line 3004, in _run_raw_task
    return _run_raw_task(
           ^^^^^^^^^^^^^^
  File "/home/airflow/.local/lib/python3.12/site-packages/airflow/models/taskinstance.py", line 273, in _run_raw_task
    TaskInstance._execute_task_with_callbacks(
  File "/home/airflow/.local/lib/python3.12/site-packages/airflow/models/taskinstance.py", line 3158, in _execute_task_with_callbacks
    result = self._execute_task(context, task_orig)
             ^^^^^^^^^^^^^^^^^^^^^^^^^^^^^^^^^^^^^^
  File "/home/airflow/.local/lib/python3.12/site-packages/airflow/models/taskinstance.py", line 3182, in _execute_task
    return _execute_task(self, context, task_orig)
           ^^^^^^^^^^^^^^^^^^^^^^^^^^^^^^^^^^^^^^^
  File "/home/airflow/.local/lib/python3.12/site-packages/airflow/models/taskinstance.py", line 767, in _execute_task
    result = _execute_callable(context=context, **execute_callable_kwargs)
             ^^^^^^^^^^^^^^^^^^^^^^^^^^^^^^^^^^^^^^^^^^^^^^^^^^^^^^^^^^^^^
  File "/home/airflow/.local/lib/python3.12/site-packages/airflow/models/taskinstance.py", line 733, in _execute_callable
    return ExecutionCallableRunner(
           ^^^^^^^^^^^^^^^^^^^^^^^^
  File "/home/airflow/.local/lib/python3.12/site-packages/airflow/utils/operator_helpers.py", line 252, in run
    return self.func(*args, **kwargs)
           ^^^^^^^^^^^^^^^^^^^^^^^^^^
  File "/home/airflow/.local/lib/python3.12/site-packages/airflow/models/baseoperator.py", line 406, in wrapper
    return func(self, *args, **kwargs)
           ^^^^^^^^^^^^^^^^^^^^^^^^^^^
  File "/home/airflow/.local/lib/python3.12/site-packages/airflow/operators/bash.py", line 249, in execute
    raise AirflowException(
airflow.exceptions.AirflowException: Bash command failed. The command returned a non-zero exit code 1.
[2025-04-24T09:38:48.132+0000] {local_task_job_runner.py:266} INFO - Task exited with return code 1
[2025-04-24T09:38:48.146+0000] {taskinstance.py:3900} INFO - 0 downstream tasks scheduled from follow-on schedule check
[2025-04-24T09:38:48.149+0000] {local_task_job_runner.py:245} INFO - ::endgroup::
